Workbook

Sheet Indice
A1: Tablas del atlas descriptivo (V10). Generado por src/v10/tablas_excel.py; no editar a mano.
A2: Azul: datos de entrada (fuente y fecha en la cabecera). Negro: cálculos de cada hoja. Verde: vínculos a otras pestañas.
A4: Hoja | B4: Contenido | C4: Filas (vínculo)
A5: IPVA_nuevo_existente | B5: INE, IPVA (59004, 59005) · 2015-2024 · capa C4 | C5: =COUNTA('IPVA_nuevo_existente'!A5:A100000)
A6: Provincias | B6: MIVAU (valor tasado, SERPAVI); INE (censo anual, ADRH); V5-A4 · 2023-2025 · capa C4 | C6: =COUNTA('Provincias'!A5:A100000)
A7: CV_municipios | B7: INE censo anual; MIVAU SERPAVI; INE VUT; Catastro · 2019-2026 · capa C4 | C7: =COUNTA('CV_municipios'!A5:A100000)
A8: Valencia_barrios | B8: INE (censo anual, ADRH, VUT, Censo 2021); MIVAU SERPAVI; Ajuntament de València · 2019-2026 · capa C4 (recuentos de población por barrio repartidos por área) | C8: =COUNTA('Valencia_barrios'!A5:A100000)
A9: Quien_ECV | B9: INE ECV (microdatos), cálculo propio · ECV 2025 · capa C1 o C4 según fila (columna capa) | C9: =COUNTA('Quien_ECV'!A5:A100000)
A11: Brecha IPVA España, último año (vínculo) | C11: =SUMIFS('IPVA_nuevo_existente'!H5:H268,'IPVA_nuevo_existente'!A5:A268,"nacional",'IPVA_nuevo_existente'!D5:D268,MAX('IPVA_nuevo_existente'!D5:D268))

Sheet IPVA_nuevo_existente
A1: IPVA_nuevo_existente: datos de entrada en azul; cálculos de esta hoja en negro
A2: Fuente: INE, IPVA (59004, 59005). Fecha del dato: 2015-2024. Capa: C4.
A4: nivel | B4: territorio_codigo | C4: nombre | D4: periodo | E4: nuevo | F4: existente | G4: total | H4: brecha_nuevo_menos_existente
A5: nacional | B5: 00 | C5: España | D5: 2021 | E5: 114.871 | F5: 112.229 | G5: 112.694 | H5: =IF(AND(ISNUMBER(E5),ISNUMBER(F5)),E5-F5,"")
A6: nacional | B6: 00 | C6: España | D6: 2022 | E6: 120.958 | F6: 114.639 | G6: 115.684 | H6: =IF(AND(ISNUMBER(E6),ISNUMBER(F6)),E6-F6,"")
A7: nacional | B7: 00 | C7: España | D7: 2023 | E7: 125.959 | F7: 117.361 | G7: 118.727 | H7: =IF(AND(ISNUMBER(E7),ISNUMBER(F7)),E7-F7,"")
A8: nacional | B8: 00 | C8: España | D8: 2024 | E8: 137.041 | F8: 120.637 | G8: 122.92 | H8: =IF(AND(ISNUMBER(E8),ISNUMBER(F8)),E8-F8,"")
A9: ccaa | B9: 01 | C9: Andalucía | D9: 2021 | E9: 114.939 | F9: 111.729 | G9: 112.471 | H9: =IF(AND(ISNUMBER(E9),ISNUMBER(F9)),E9-F9,"")
A10: ccaa | B10: 01 | C10: Andalucía | D10: 2022 | E10: 120.976 | F10: 114.043 | G10: 115.57 | H10: =IF(AND(ISNUMBER(E10),ISNUMBER(F10)),E10-F10,"")
A11: ccaa | B11: 01 | C11: Andalucía | D11: 2023 | E11: 125.4 | F11: 116.656 | G11: 118.53 | H11: =IF(AND(ISNUMBER(E11),ISNUMBER(F11)),E11-F11,"")
A12: ccaa | B12: 01 | C12: Andalucía | D12: 2024 | E12: 136.009 | F12: 120.001 | G12: 123.029 | H12: =IF(AND(ISNUMBER(E12),ISNUMBER(F12)),E12-F12,"")
A13: ccaa | B13: 02 | C13: Aragón | D13: 2021 | E13: 114.284 | F13: 110.127 | G13: 110.742 | H13: =IF(AND(ISNUMBER(E13),ISNUMBER(F13)),E13-F13,"")
A14: ccaa | B14: 02 | C14: Aragón | D14: 2022 | E14: 120.309 | F14: 112.432 | G14: 113.566 | H14: =IF(AND(ISNUMBER(E14),ISNUMBER(F14)),E14-F14,"")
A15: ccaa | B15: 02 | C15: Aragón | D15: 2023 | E15: 124.339 | F15: 114.863 | G15: 116.212 | H15: =IF(AND(ISNUMBER(E15),ISNUMBER(F15)),E15-F15,"")
A16: ccaa | B16: 02 | C16: Aragón | D16: 2024 | E16: 134.141 | F16: 117.745 | G16: 119.907 | H16: =IF(AND(ISNUMBER(E16),ISNUMBER(F16)),E16-F16,"")
... A268: provincia | B268: 52 | C268: Melilla | D268: 2024 | E268: 114.402 | F268: 107.633 | G268: 108.771 | H268: =IF(AND(ISNUMBER(E268),ISNUMBER(F268)),E268-F268,"")

Sheet Provincias
A1: Provincias: datos de entrada en azul; cálculos de esta hoja en negro
A2: Fuente: MIVAU (valor tasado, SERPAVI); INE (censo anual, ADRH); V5-A4. Fecha del dato: 2023-2025. Capa: C4.
A4: cod_provincia | B4: nombre | C4: pob_2025 | D4: valor_tasado_2024 | E4: alquiler_m2_2024 | F4: renta_neta_persona_2023 | G4: deficit_2021_2025_mediana | H4: alquiler_80m2_pct_renta | I4: deficit_por_1000_hab
A5: 01 | B5: Araba/Álava | C5: 341961 | D5: 2133.075 | E5: 8.83 | F5: 17764.64 | G5: 4448.43 | H5: =IF(AND(ISNUMBER(E5),ISNUMBER(F5)),100*E5*80*12/F5,"") | I5: =IF(AND(ISNUMBER(G5),ISNUMBER(C5)),1000*G5/C5,"")
A6: 02 | B6: Albacete | C6: 390751 | D6: 1011.05 | E6: 5.3657 | F6: 13073.191 | G6: 4641.783 | H6: =IF(AND(ISNUMBER(E6),ISNUMBER(F6)),100*E6*80*12/F6,"") | I6: =IF(AND(ISNUMBER(G6),ISNUMBER(C6)),1000*G6/C6,"")
A7: 03 | B7: Alicante/Alacant | C7: 2033566 | D7: 1596.35 | E7: 6.2044 | F7: 12321.959 | G7: 57280.015 | H7: =IF(AND(ISNUMBER(E7),ISNUMBER(F7)),100*E7*80*12/F7,"") | I7: =IF(AND(ISNUMBER(G7),ISNUMBER(C7)),1000*G7/C7,"")
A8: 04 | B8: Almería | C8: 770554 | D8: 1243.65 | E8: 5.9378 | F8: 11546.096 | G8: 19643.408 | H8: =IF(AND(ISNUMBER(E8),ISNUMBER(F8)),100*E8*80*12/F8,"") | I8: =IF(AND(ISNUMBER(G8),ISNUMBER(C8)),1000*G8/C8,"")
A9: 05 | B9: Ávila | C9: 160738 | D9: 939.375 | E9: 5.2809 | F9: 13631.146 | G9: 1726.868 | H9: =IF(AND(ISNUMBER(E9),ISNUMBER(F9)),100*E9*80*12/F9,"") | I9: =IF(AND(ISNUMBER(G9),ISNUMBER(C9)),1000*G9/C9,"")
A10: 06 | B10: Badajoz | C10: 665155 | D10: 924.775 | E10: 5.1537 | F10: 12082.228 | G10: 7223.87 | H10: =IF(AND(ISNUMBER(E10),ISNUMBER(F10)),100*E10*80*12/F10,"") | I10: =IF(AND(ISNUMBER(G10),ISNUMBER(C10)),1000*G10/C10,"")
A11: 07 | B11: Balears, Illes | C11: 1249844 | D11: 3167.025 | E11: 9.6154 | F11: 16171.064 | G11: 15972.308 | H11: =IF(AND(ISNUMBER(E11),ISNUMBER(F11)),100*E11*80*12/F11,"") | I11: =IF(AND(ISNUMBER(G11),ISNUMBER(C11)),1000*G11/C11,"")
A12: 08 | B12: Barcelona | C12: 5959941 | D12: 2692.8 | E12: 10.9842 | F12: 17072.439 | G12: 89835.615 | H12: =IF(AND(ISNUMBER(E12),ISNUMBER(F12)),100*E12*80*12/F12,"") | I12: =IF(AND(ISNUMBER(G12),ISNUMBER(C12)),1000*G12/C12,"")
A13: 09 | B13: Burgos | C13: 362663 | D13: 1197.875 | E13: 6.7073 | F13: 15991.082 | G13: 4389.597 | H13: =IF(AND(ISNUMBER(E13),ISNUMBER(F13)),100*E13*80*12/F13,"") | I13: =IF(AND(ISNUMBER(G13),ISNUMBER(C13)),1000*G13/C13,"")
A14: 10 | B14: Cáceres | C14: 388190 | D14: 862.125 | E14: 4.7381 | F14: 12760.542 | G14: 1054.392 | H14: =IF(AND(ISNUMBER(E14),ISNUMBER(F14)),100*E14*80*12/F14,"") | I14: =IF(AND(ISNUMBER(G14),ISNUMBER(C14)),1000*G14/C14,"")
A15: 11 | B15: Cádiz | C15: 1261420 | D15: 1639.05 | E15: 7.1429 | F15: 12353.371 | G15: 17193.765 | H15: =IF(AND(ISNUMBER(E15),ISNUMBER(F15)),100*E15*80*12/F15,"") | I15: =IF(AND(ISNUMBER(G15),ISNUMBER(C15)),1000*G15/C15,"")
A16: 12 | B16: Castellón/Castelló | C16: 627620 | D16: 1168.85 | E16: 5.1671 | F16: 14035.644 | G16: 19633.18 | H16: =IF(AND(ISNUMBER(E16),ISNUMBER(F16)),100*E16*80*12/F16,"") | I16: =IF(AND(ISNUMBER(G16),ISNUMBER(C16)),1000*G16/C16,"")
... A54: 50 | B54: Zaragoza | C54: 998443 | D54: 1529.8 | E54: 7.4468 | F54: 15662.834 | G54: 17396.998 | H54: =IF(AND(ISNUMBER(E54),ISNUMBER(F54)),100*E54*80*12/F54,"") | I54: =IF(AND(ISNUMBER(G54),ISNUMBER(C54)),1000*G54/C54,"")
A55: 51 | B55: Ceuta | C55: 83567 | E55: 9.4488 | F55: 14611.621 | G55: 1066.787 | H55: =IF(AND(ISNUMBER(E55),ISNUMBER(F55)),100*E55*80*12/F55,"") | I55: =IF(AND(ISNUMBER(G55),ISNUMBER(C55)),1000*G55/C55,"")
A56: 52 | B56: Melilla | C56: 87067 | E56: 9.104 | F56: 13978.762 | G56: 997.367 | H56: =IF(AND(ISNUMBER(E56),ISNUMBER(F56)),100*E56*80*12/F56,"") | I56: =IF(AND(ISNUMBER(G56),ISNUMBER(C56)),1000*G56/C56,"")

Sheet CV_municipios
A1: CV_municipios: datos de entrada en azul; cálculos de esta hoja en negro
A2: Fuente: INE censo anual; MIVAU SERPAVI; INE VUT; Catastro. Fecha del dato: 2019-2026. Capa: C4.
A4: cod_municipio | B4: nombre | C4: pob_2021 | D4: pob_2025 | E4: alquiler_m2_2019 | F4: alquiler_m2_2024 | G4: vut_ine_2026_05 | H4: inmuebles_residenciales_catastro | I4: var_pob_pct | J4: var_alquiler_pct | K4: vut_por_100_inmuebles
A5: 03001 | B5: Atzúbia, l' | C5: 625 | D5: 601 | H5: 593 | I5: =IF(AND(ISNUMBER(D5),C5>0),100*(D5/C5-1),"") | J5: =IF(AND(ISNUMBER(F5),ISNUMBER(E5)),100*(F5/E5-1),"") | K5: =IF(AND(ISNUMBER(G5),ISNUMBER(H5)),100*G5/H5,"")
A6: 03002 | B6: Agost | C6: 4909 | D6: 5224 | E6: 2.6889 | F6: 3.3784 | H6: 2929 | I6: =IF(AND(ISNUMBER(D6),C6>0),100*(D6/C6-1),"") | J6: =IF(AND(ISNUMBER(F6),ISNUMBER(E6)),100*(F6/E6-1),"") | K6: =IF(AND(ISNUMBER(G6),ISNUMBER(H6)),100*G6/H6,"")
A7: 03003 | B7: Agres | C7: 582 | D7: 625 | H7: 608 | I7: =IF(AND(ISNUMBER(D7),C7>0),100*(D7/C7-1),"") | J7: =IF(AND(ISNUMBER(F7),ISNUMBER(E7)),100*(F7/E7-1),"") | K7: =IF(AND(ISNUMBER(G7),ISNUMBER(H7)),100*G7/H7,"")
A8: 03004 | B8: Aigües | C8: 1045 | D8: 1187 | H8: 970 | I8: =IF(AND(ISNUMBER(D8),C8>0),100*(D8/C8-1),"") | J8: =IF(AND(ISNUMBER(F8),ISNUMBER(E8)),100*(F8/E8-1),"") | K8: =IF(AND(ISNUMBER(G8),ISNUMBER(H8)),100*G8/H8,"")
A9: 03005 | B9: Albatera | C9: 12704 | D9: 13476 | E9: 2.6846 | F9: 3.5356 | H9: 6744 | I9: =IF(AND(ISNUMBER(D9),C9>0),100*(D9/C9-1),"") | J9: =IF(AND(ISNUMBER(F9),ISNUMBER(E9)),100*(F9/E9-1),"") | K9: =IF(AND(ISNUMBER(G9),ISNUMBER(H9)),100*G9/H9,"")
A10: 03006 | B10: Alcalalí | C10: 1321 | D10: 1405 | H10: 1073 | I10: =IF(AND(ISNUMBER(D10),C10>0),100*(D10/C10-1),"") | J10: =IF(AND(ISNUMBER(F10),ISNUMBER(E10)),100*(F10/E10-1),"") | K10: =IF(AND(ISNUMBER(G10),ISNUMBER(H10)),100*G10/H10,"")
A11: 03007 | B11: Alcosser | C11: 245 | D11: 263 | H11: 224 | I11: =IF(AND(ISNUMBER(D11),C11>0),100*(D11/C11-1),"") | J11: =IF(AND(ISNUMBER(F11),ISNUMBER(E11)),100*(F11/E11-1),"") | K11: =IF(AND(ISNUMBER(G11),ISNUMBER(H11)),100*G11/H11,"")
A12: 03008 | B12: Alcoleja | C12: 186 | D12: 186 | H12: 205 | I12: =IF(AND(ISNUMBER(D12),C12>0),100*(D12/C12-1),"") | J12: =IF(AND(ISNUMBER(F12),ISNUMBER(E12)),100*(F12/E12-1),"") | K12: =IF(AND(ISNUMBER(G12),ISNUMBER(H12)),100*G12/H12,"")
A13: 03009 | B13: Alcoi/Alcoy | C13: 59187 | D13: 61613 | E13: 3.5088 | F13: 4.4945 | H13: 31707 | I13: =IF(AND(ISNUMBER(D13),C13>0),100*(D13/C13-1),"") | J13: =IF(AND(ISNUMBER(F13),ISNUMBER(E13)),100*(F13/E13-1),"") | K13: =IF(AND(ISNUMBER(G13),ISNUMBER(H13)),100*G13/H13,"")
A14: 03010 | B14: Alfafara | C14: 408 | D14: 417 | H14: 333 | I14: =IF(AND(ISNUMBER(D14),C14>0),100*(D14/C14-1),"") | J14: =IF(AND(ISNUMBER(F14),ISNUMBER(E14)),100*(F14/E14-1),"") | K14: =IF(AND(ISNUMBER(G14),ISNUMBER(H14)),100*G14/H14,"")
A15: 03011 | B15: Alfàs del Pi, l' | C15: 19615 | D15: 21046 | E15: 6.6176 | F15: 7.8818 | H15: 12250 | I15: =IF(AND(ISNUMBER(D15),C15>0),100*(D15/C15-1),"") | J15: =IF(AND(ISNUMBER(F15),ISNUMBER(E15)),100*(F15/E15-1),"") | K15: =IF(AND(ISNUMBER(G15),ISNUMBER(H15)),100*G15/H15,"")
A16: 03012 | B16: Algorfa | C16: 3459 | D16: 3749 | E16: 5.0794 | F16: 6.6667 | H16: 4498 | I16: =IF(AND(ISNUMBER(D16),C16>0),100*(D16/C16-1),"") | J16: =IF(AND(ISNUMBER(F16),ISNUMBER(E16)),100*(F16/E16-1),"") | K16: =IF(AND(ISNUMBER(G16),ISNUMBER(H16)),100*G16/H16,"")
A17: 03013 | B17: Algueña | C17: 1339 | D17: 1327 | H17: 843 | I17: =IF(AND(ISNUMBER(D17),C17>0),100*(D17/C17-1),"") | J17: =IF(AND(ISNUMBER(F17),ISNUMBER(E17)),100*(F17/E17-1),"") | K17: =IF(AND(ISNUMBER(G17),ISNUMBER(H17)),100*G17/H17,"")
A18: 03014 | B18: Alacant/Alicante | C18: 338768 | D18: 365586 | E18: 5.4128 | F18: 7.1053 | H18: 188462 | I18: =IF(AND(ISNUMBER(D18),C18>0),100*(D18/C18-1),"") | J18: =IF(AND(ISNUMBER(F18),ISNUMBER(E18)),100*(F18/E18-1),"") | K18: =IF(AND(ISNUMBER(G18),ISNUMBER(H18)),100*G18/H18,"")
A19: 03015 | B19: Almoradí | C19: 21303 | D19: 22874 | E19: 3.2051 | F19: 4.345 | H19: 9900 | I19: =IF(AND(ISNUMBER(D19),C19>0),100*(D19/C19-1),"") | J19: =IF(AND(ISNUMBER(F19),ISNUMBER(E19)),100*(F19/E19-1),"") | K19: =IF(AND(ISNUMBER(G19),ISNUMBER(H19)),100*G19/H19,"")
A20: 03016 | B20: Almudaina | C20: 118 | D20: 127 | H20: 122 | I20: =IF(AND(ISNUMBER(D20),C20>0),100*(D20/C20-1),"") | J20: =IF(AND(ISNUMBER(F20),ISNUMBER(E20)),100*(F20/E20-1),"") | K20: =IF(AND(ISNUMBER(G20),ISNUMBER(H20)),100*G20/H20,"")
A21: 03017 | B21: Alqueria d'Asnar, l' | C21: 498 | D21: 519 | H21: 296 | I21: =IF(AND(ISNUMBER(D21),C21>0),100*(D21/C21-1),"") | J21: =IF(AND(ISNUMBER(F21),ISNUMBER(E21)),100*(F21/E21-1),"") | K21: =IF(AND(ISNUMBER(G21),ISNUMBER(H21)),100*G21/H21,"")
A22: 03018 | B22: Altea | C22: 22810 | D22: 24731 | E22: 5.618 | F22: 7.0588 | H22: 15814 | I22: =IF(AND(ISNUMBER(D22),C22>0),100*(D22/C22-1),"") | J22: =IF(AND(ISNUMBER(F22),ISNUMBER(E22)),100*(F22/E22-1),"") | K22: =IF(AND(ISNUMBER(G22),ISNUMBER(H22)),100*G22/H22,"")
A23: 03019 | B23: Aspe | C23: 21065 | D23: 22354 | E23: 3.15 | F23: 4.1551 | H23: 8986 | I23: =IF(AND(ISNUMBER(D23),C23>0),100*(D23/C23-1),"") | J23: =IF(AND(ISNUMBER(F23),ISNUMBER(E23)),100*(F23/E23-1),"") | K23: =IF(AND(ISNUMBER(G23),ISNUMBER(H23)),100*G23/H23,"")
A24: 03020 | B24: Balones | C24: 134 | D24: 133 | H24: 129 | I24: =IF(AND(ISNUMBER(D24),C24>0),100*(D24/C24-1),"") | J24: =IF(AND(ISNUMBER(F24),ISNUMBER(E24)),100*(F24/E24-1),"") | K24: =IF(AND(ISNUMBER(G24),ISNUMBER(H24)),100*G24/H24,"")
A25: 03021 | B25: Banyeres de Mariola | C25: 7103 | D25: 7336 | E25: 2.3333 | F25: 3.2313 | H25: 4396 | I25: =IF(AND(ISNUMBER(D25),C25>0),100*(D25/C25-1),"") | J25: =IF(AND(ISNUMBER(F25),ISNUMBER(E25)),100*(F25/E25-1),"") | K25: =IF(AND(ISNUMBER(G25),ISNUMBER(H25)),100*G25/H25,"")
A26: 03022 | B26: Benasau | C26: 167 | D26: 174 | H26: 180 | I26: =IF(AND(ISNUMBER(D26),C26>0),100*(D26/C26-1),"") | J26: =IF(AND(ISNUMBER(F26),ISNUMBER(E26)),100*(F26/E26-1),"") | K26: =IF(AND(ISNUMBER(G26),ISNUMBER(H26)),100*G26/H26,"")
A27: 03023 | B27: Beneixama | C27: 1719 | D27: 1704 | E27: 1.2553 | F27: 3.182 | H27: 1348 | I27: =IF(AND(ISNUMBER(D27),C27>0),100*(D27/C27-1),"") | J27: =IF(AND(ISNUMBER(F27),ISNUMBER(E27)),100*(F27/E27-1),"") | K27: =IF(AND(ISNUMBER(G27),ISNUMBER(H27)),100*G27/H27,"")
A28: 03024 | B28: Benejúzar | C28: 5487 | D28: 5829 | E28: 3.3329 | F28: 4.0179 | H28: 2609 | I28: =IF(AND(ISNUMBER(D28),C28>0),100*(D28/C28-1),"") | J28: =IF(AND(ISNUMBER(F28),ISNUMBER(E28)),100*(F28/E28-1),"") | K28: =IF(AND(ISNUMBER(G28),ISNUMBER(H28)),100*G28/H28,"")
A29: 03025 | B29: Benferri | C29: 1934 | D29: 2098 | E29: 4.7526 | F29: 5.1587 | H29: 1128 | I29: =IF(AND(ISNUMBER(D29),C29>0),100*(D29/C29-1),"") | J29: =IF(AND(ISNUMBER(F29),ISNUMBER(E29)),100*(F29/E29-1),"") | K29: =IF(AND(ISNUMBER(G29),ISNUMBER(H29)),100*G29/H29,"")
A30: 03026 | B30: Beniarbeig | C30: 2237 | D30: 2540 | E30: 5.0515 | F30: 6.2238 | H30: 1405 | I30: =IF(AND(ISNUMBER(D30),C30>0),100*(D30/C30-1),"") | J30: =IF(AND(ISNUMBER(F30),ISNUMBER(E30)),100*(F30/E30-1),"") | K30: =IF(AND(ISNUMBER(G30),ISNUMBER(H30)),100*G30/H30,"")
A31: 03027 | B31: Beniardà | C31: 197 | D31: 233 | H31: 173 | I31: =IF(AND(ISNUMBER(D31),C31>0),100*(D31/C31-1),"") | J31: =IF(AND(ISNUMBER(F31),ISNUMBER(E31)),100*(F31/E31-1),"") | K31: =IF(AND(ISNUMBER(G31),ISNUMBER(H31)),100*G31/H31,"")
A32: 03028 | B32: Beniarrés | C32: 1088 | D32: 1116 | H32: 725 | I32: =IF(AND(ISNUMBER(D32),C32>0),100*(D32/C32-1),"") | J32: =IF(AND(ISNUMBER(F32),ISNUMBER(E32)),100*(F32/E32-1),"") | K32: =IF(AND(ISNUMBER(G32),ISNUMBER(H32)),100*G32/H32,"")
A33: 03029 | B33: Benigembla | C33: 477 | D33: 581 | H33: 347 | I33: =IF(AND(ISNUMBER(D33),C33>0),100*(D33/C33-1),"") | J33: =IF(AND(ISNUMBER(F33),ISNUMBER(E33)),100*(F33/E33-1),"") | K33: =IF(AND(ISNUMBER(G33),ISNUMBER(H33)),100*G33/H33,"")
A34: 03030 | B34: Benidoleig | C34: 1153 | D34: 1274 | E34: 3.7916 | F34: 4.9721 | H34: 923 | I34: =IF(AND(ISNUMBER(D34),C34>0),100*(D34/C34-1),"") | J34: =IF(AND(ISNUMBER(F34),ISNUMBER(E34)),100*(F34/E34-1),"") | K34: =IF(AND(ISNUMBER(G34),ISNUMBER(H34)),100*G34/H34,"")
A35: 03031 | B35: Benidorm | C35: 68874 | D35: 77211 | E35: 6.8922 | F35: 8.4456 | H35: 61577 | I35: =IF(AND(ISNUMBER(D35),C35>0),100*(D35/C35-1),"") | J35: =IF(AND(ISNUMBER(F35),ISNUMBER(E35)),100*(F35/E35-1),"") | K35: =IF(AND(ISNUMBER(G35),ISNUMBER(H35)),100*G35/H35,"")
A36: 03032 | B36: Benifallim | C36: 102 | D36: 130 | H36: 138 | I36: =IF(AND(ISNUMBER(D36),C36>0),100*(D36/C36-1),"") | J36: =IF(AND(ISNUMBER(F36),ISNUMBER(E36)),100*(F36/E36-1),"") | K36: =IF(AND(ISNUMBER(G36),ISNUMBER(H36)),100*G36/H36,"")
A37: 03033 | B37: Benifato | C37: 133 | D37: 160 | H37: 182 | I37: =IF(AND(ISNUMBER(D37),C37>0),100*(D37/C37-1),"") | J37: =IF(AND(ISNUMBER(F37),ISNUMBER(E37)),100*(F37/E37-1),"") | K37: =IF(AND(ISNUMBER(G37),ISNUMBER(H37)),100*G37/H37,"")
A38: 03034 | B38: Benijófar | C38: 3303 | D38: 3696 | E38: 4.3284 | F38: 5.2326 | H38: 2636 | I38: =IF(AND(ISNUMBER(D38),C38>0),100*(D38/C38-1),"") | J38: =IF(AND(ISNUMBER(F38),ISNUMBER(E38)),100*(F38/E38-1),"") | K38: =IF(AND(ISNUMBER(G38),ISNUMBER(H38)),100*G38/H38,"")
A39: 03035 | B39: Benilloba | C39: 739 | D39: 746 | H39: 592 | I39: =IF(AND(ISNUMBER(D39),C39>0),100*(D39/C39-1),"") | J39: =IF(AND(ISNUMBER(F39),ISNUMBER(E39)),100*(F39/E39-1),"") | K39: =IF(AND(ISNUMBER(G39),ISNUMBER(H39)),100*G39/H39,"")
A40: 03036 | B40: Benillup | C40: 102 | D40: 111 | H40: 71 | I40: =IF(AND(ISNUMBER(D40),C40>0),100*(D40/C40-1),"") | J40: =IF(AND(ISNUMBER(F40),ISNUMBER(E40)),100*(F40/E40-1),"") | K40: =IF(AND(ISNUMBER(G40),ISNUMBER(H40)),100*G40/H40,"")
A41: 03037 | B41: Benimantell | C41: 496 | D41: 544 | E41: 3.9773 | F41: 6.3416 | H41: 471 | I41: =IF(AND(ISNUMBER(D41),C41>0),100*(D41/C41-1),"") | J41: =IF(AND(ISNUMBER(F41),ISNUMBER(E41)),100*(F41/E41-1),"") | K41: =IF(AND(ISNUMBER(G41),ISNUMBER(H41)),100*G41/H41,"")
...

Sheet Valencia_barrios
A1: Valencia_barrios: datos de entrada en azul; cálculos de esta hoja en negro
A2: Fuente: INE (censo anual, ADRH, VUT, Censo 2021); MIVAU SERPAVI; Ajuntament de València. Fecha del dato: 2019-2026. Capa: C4 (recuentos de población por barrio repartidos por área).
A4: cod_barrio | B4: nombre | C4: pob_2021 | D4: pob_2025 | E4: extranj_2021 | F4: extranj_2025 | G4: vut_2026_05 | H4: viviendas_2021 | I4: alquiler_m2_2019 | J4: alquiler_m2_2024 | K4: renta_persona_2023 | L4: indice_presion_descriptivo | M4: pct_extranj_2025 | N4: vut_por_100_viv | O4: var_alquiler_pct
A5: 462500101 | B5: LA SEU | C5: 2650.7541 | D5: 2882.0196 | E5: 513.7337 | F5: 780.2082 | G5: 128.6064 | H5: 2100.9075 | I5: 7.8744 | J5: 10.9196 | K5: 22623.023 | L5: 1.4491 | M5: =IF(D5>0,100*F5/D5,"") | N5: =IF(H5>0,100*G5/H5,"") | O5: =IF(AND(ISNUMBER(J5),ISNUMBER(I5)),100*(J5/I5-1),"")
A6: 462500102 | B6: LA XEREA | C6: 3747.223 | D6: 4074.1442 | E6: 490.7897 | F6: 836.9888 | G6: 68.2465 | H6: 2703.1298 | I6: 8.4918 | J6: 11.0511 | K6: 27716.342 | L6: 0.4493 | M6: =IF(D6>0,100*F6/D6,"") | N6: =IF(H6>0,100*G6/H6,"") | O6: =IF(AND(ISNUMBER(J6),ISNUMBER(I6)),100*(J6/I6-1),"")
A7: 462500103 | B7: EL CARME | C7: 6438.6377 | D7: 7245.0523 | E7: 1222.6724 | F7: 2100.0953 | G7: 191.0404 | H7: 4480.9474 | I7: 7.6584 | J7: 10.4632 | K7: 17966.132 | L7: 1.185 | M7: =IF(D7>0,100*F7/D7,"") | N7: =IF(H7>0,100*G7/H7,"") | O7: =IF(AND(ISNUMBER(J7),ISNUMBER(I7)),100*(J7/I7-1),"")
A8: 462500104 | B8: EL PILAR | C8: 4497.403 | D8: 5443.0408 | E8: 927.0217 | F8: 1849.1444 | G8: 95.4393 | H8: 2982.2206 | I8: 7.4764 | J8: 10.844 | K8: 17876.32 | L8: 1.7284 | M8: =IF(D8>0,100*F8/D8,"") | N8: =IF(H8>0,100*G8/H8,"") | O8: =IF(AND(ISNUMBER(J8),ISNUMBER(I8)),100*(J8/I8-1),"")
A9: 462500105 | B9: EL MERCAT | C9: 3510.2424 | D9: 4021.1157 | E9: 686.9059 | F9: 1276.1038 | G9: 255.7394 | H9: 3052.761 | I9: 7.9511 | J9: 10.945 | K9: 20070.351 | L9: 2.2463 | M9: =IF(D9>0,100*F9/D9,"") | N9: =IF(H9>0,100*G9/H9,"") | O9: =IF(AND(ISNUMBER(J9),ISNUMBER(I9)),100*(J9/I9-1),"")
A10: 462500106 | B10: SANT FRANCESC | C10: 5641.1351 | D10: 6227.9798 | E10: 737.5947 | F10: 1426.6209 | G10: 179.7145 | H10: 4727.5148 | I10: 8.7409 | J10: 11.3585 | K10: 26394.336 | L10: 0.9472 | M10: =IF(D10>0,100*F10/D10,"") | N10: =IF(H10>0,100*G10/H10,"") | O10: =IF(AND(ISNUMBER(J10),ISNUMBER(I10)),100*(J10/I10-1),"")
A11: 462500201 | B11: RUSSAFA | C11: 21995.013 | D11: 25056.521 | E11: 2999.2571 | F11: 5014.1849 | G11: 288.6907 | H11: 13766.018 | I11: 6.7129 | J11: 9.3169 | K11: 19262.085 | L11: 0.3615 | M11: =IF(D11>0,100*F11/D11,"") | N11: =IF(H11>0,100*G11/H11,"") | O11: =IF(AND(ISNUMBER(J11),ISNUMBER(I11)),100*(J11/I11-1),"")
A12: 462500202 | B12: EL PLA DEL REMEI | C12: 6140.9861 | D12: 7320.1241 | E12: 391.0968 | F12: 928.303 | G12: 30.3428 | H12: 3738.32 | I12: 7.9834 | J12: 10.6115 | K12: 34421.438 | L12: 0.0816 | M12: =IF(D12>0,100*F12/D12,"") | N12: =IF(H12>0,100*G12/H12,"") | O12: =IF(AND(ISNUMBER(J12),ISNUMBER(I12)),100*(J12/I12-1),"")
A13: 462500203 | B13: LA GRAN VIA | C13: 12079.17 | D13: 12678.074 | E13: 973.3068 | F13: 1873.5381 | G13: 41.4699 | H13: 6722.7598 | I13: 6.8783 | J13: 9.489 | K13: 25548.01 | L13: 0.1223 | M13: =IF(D13>0,100*F13/D13,"") | N13: =IF(H13>0,100*G13/H13,"") | O13: =IF(AND(ISNUMBER(J13),ISNUMBER(I13)),100*(J13/I13-1),"")
A14: 462500301 | B14: EL BOTANIC | C14: 6139.8017 | D14: 6590.4153 | E14: 851.0087 | F14: 1391.6963 | G14: 89.0657 | H14: 3869.3745 | I14: 6.9179 | J14: 9.6568 | K14: 19208.438 | L14: 0.5688 | M14: =IF(D14>0,100*F14/D14,"") | N14: =IF(H14>0,100*G14/H14,"") | O14: =IF(AND(ISNUMBER(J14),ISNUMBER(I14)),100*(J14/I14-1),"")
A15: 462500302 | B15: LA ROQUETA | C15: 4175.5757 | D15: 4747.8907 | E15: 875.257 | F15: 1339.9511 | G15: 122.9653 | H15: 3045.0554 | I15: 6.5843 | J15: 9.6743 | K15: 19216.343 | L15: 1.1865 | M15: =IF(D15>0,100*F15/D15,"") | N15: =IF(H15>0,100*G15/H15,"") | O15: =IF(AND(ISNUMBER(J15),ISNUMBER(I15)),100*(J15/I15-1),"")
A16: 462500303 | B16: LA PETXINA | C16: 15032.08 | D16: 15809.081 | E16: 1393.7756 | F16: 2379.3059 | G16: 90.0818 | H16: 8103.452 | I16: 5.9749 | J16: 8.3427 | K16: 18743.913 | L16: 0.0126 | M16: =IF(D16>0,100*F16/D16,"") | N16: =IF(H16>0,100*G16/H16,"") | O16: =IF(AND(ISNUMBER(J16),ISNUMBER(I16)),100*(J16/I16-1),"")
... A91: 462501908 | B91: FAITANAR | C91: 2594.6852 | D91: 3046.2743 | E91: 495.0639 | F91: 795.9469 | G91: 21.7892 | H91: 1540.3121 | I91: 4.6323 | J91: 6.7552 | K91: 12511.973 | L91: 0.2024 | M91: =IF(D91>0,100*F91/D91,"") | N91: =IF(H91>0,100*G91/H91,"") | O91: =IF(AND(ISNUMBER(J91),ISNUMBER(I91)),100*(J91/I91-1),"")

Sheet Quien_ECV
A1: Quien_ECV: datos de entrada en azul; cálculos de esta hoja en negro
A2: Fuente: INE ECV (microdatos), cálculo propio. Fecha del dato: ECV 2025. Capa: C1 o C4 según fila (columna capa).
A4: anio | B4: grupo | C4: categoria | D4: indicador | E4: valor | F4: ic95_inf | G4: ic95_sup | H4: n_muestral | I4: capa | J4: amplitud_ic
A5: 2025 | B5: total | C5: Total | D5: sobrecarga_30 | E5: 12.011 | F5: 11.362 | G5: 12.66 | H5: 71161 | I5: C4 | J5: =IF(ISNUMBER(G5),G5-F5,"")
A6: 2025 | B6: total | C6: Total | D6: sobrecarga_40 | E6: 7.172 | F6: 6.6701 | G6: 7.6739 | H6: 71161 | I6: C1 | J6: =IF(ISNUMBER(G6),G6-F6,"")
A7: 2025 | B7: total | C7: Total | D7: esfuerzo_alquiler_30 | E7: 28.584 | F7: 26.1628 | G7: 31.0051 | H7: 8856 | I7: C4 | J7: =IF(ISNUMBER(G7),G7-F7,"")
A8: 2025 | B8: total | C8: Total | D8: esfuerzo_alquiler_40 | E8: 17.2252 | F8: 15.2426 | G8: 19.2079 | H8: 8856 | I8: C4 | J8: =IF(ISNUMBER(G8),G8-F8,"")
A9: 2025 | B9: total | C9: Total | D9: esfuerzo_hipoteca_30 | E9: 8.8028 | F9: 7.7827 | G9: 9.8228 | H9: 20116 | I9: C4 | J9: =IF(ISNUMBER(G9),G9-F9,"")
A10: 2025 | B10: total | C10: Total | D10: hacinamiento | E10: 8.6255 | F10: 7.826 | G10: 9.4251 | H10: 71191 | I10: C4 | J10: =IF(ISNUMBER(G10),G10-F10,"")
A11: 2025 | B11: total | C11: Total | D11: tenencia_1 | E11: 45.5223 | F11: 44.6058 | G11: 46.4387 | H11: 71398 | I11: C4 | J11: =IF(ISNUMBER(G11),G11-F11,"")
A12: 2025 | B12: total | C12: Total | D12: tenencia_2 | E12: 28.1333 | F12: 27.3029 | G12: 28.9636 | H12: 71398 | I12: C4 | J12: =IF(ISNUMBER(G12),G12-F12,"")
A13: 2025 | B13: total | C13: Total | D13: tenencia_3 | E13: 17.3503 | F13: 16.4476 | G13: 18.253 | H13: 71398 | I13: C4 | J13: =IF(ISNUMBER(G13),G13-F13,"")
A14: 2025 | B14: total | C14: Total | D14: tenencia_4 | E14: 3.45 | F14: 3.0901 | G14: 3.8099 | H14: 71398 | I14: C4 | J14: =IF(ISNUMBER(G14),G14-F14,"")
A15: 2025 | B15: total | C15: Total | D15: tenencia_5 | E15: 5.5441 | F15: 5.1768 | G15: 5.9115 | H15: 71398 | I15: C4 | J15: =IF(ISNUMBER(G15),G15-F15,"")
A16: 2025 | B16: total | C16: Total | D16: esfuerzo_alquiler_mediana | E16: 22.0562 | F16: 21.1879 | G16: 23.0747 | H16: 8856 | I16: C4 | J16: =IF(ISNUMBER(G16),G16-F16,"")
... A622: 2025 | B622: tenencia | C622: propiedad sin hipoteca | D622: hacinamiento | E622: 5.183 | F622: 4.3793 | G622: 5.9868 | H622: 34303 | I622: C4 | J622: =IF(ISNUMBER(G622),G622-F622,"")
