Workbook

Sheet impactos
A1: impactos: tabla del resumen ejecutivo del Documento de Trabajo V18
A2: Fuente: pestaña magnitudes (vínculos). AZUL: dato introducido (fuente en la nota de la celda); NEGRO: fórmula de esta hoja; VERDE: vínculo a otra pestaña.
A3: factor | B3: magnitud preferida | C3: min | D3: max | E3: clasificación | F3: estado B5 | G3: n estudios | H3: confianza | I3: limitación principal
A4: =magnitudes!A4 | B4: =magnitudes!D4 | C4: =magnitudes!E4 | D4: =magnitudes!F4 | E4: =magnitudes!H4 | F4: =magnitudes!I4 | G4: =magnitudes!J4 | H4: =IF(AND(LEFT(F4,18)="magnitud preferida",G4>=3),"media",IF(LEFT(F4,22)="rango de la literatura","muy baja","baja")) | I4: =magnitudes!K4
A5: =magnitudes!A5 | B5: =magnitudes!D5 | C5: =magnitudes!E5 | D5: =magnitudes!F5 | E5: =magnitudes!H5 | F5: =magnitudes!I5 | G5: =magnitudes!J5 | H5: =IF(AND(LEFT(F5,18)="magnitud preferida",G5>=3),"media",IF(LEFT(F5,22)="rango de la literatura","muy baja","baja")) | I5: =magnitudes!K5
A6: =magnitudes!A6 | B6: =magnitudes!D6 | C6: =magnitudes!E6 | D6: =magnitudes!F6 | E6: =magnitudes!H6 | F6: =magnitudes!I6 | G6: =magnitudes!J6 | H6: =IF(AND(LEFT(F6,18)="magnitud preferida",G6>=3),"media",IF(LEFT(F6,22)="rango de la literatura","muy baja","baja")) | I6: =magnitudes!K6
A7: =magnitudes!A7 | B7: =magnitudes!D7 | C7: =magnitudes!E7 | D7: =magnitudes!F7 | E7: =magnitudes!H7 | F7: =magnitudes!I7 | G7: =magnitudes!J7 | H7: =IF(AND(LEFT(F7,18)="magnitud preferida",G7>=3),"media",IF(LEFT(F7,22)="rango de la literatura","muy baja","baja")) | I7: =magnitudes!K7
A8: =magnitudes!A8 | B8: =magnitudes!D8 | C8: =magnitudes!E8 | D8: =magnitudes!F8 | E8: =magnitudes!H8 | F8: =magnitudes!I8 | G8: =magnitudes!J8 | H8: =IF(AND(LEFT(F8,18)="magnitud preferida",G8>=3),"media",IF(LEFT(F8,22)="rango de la literatura","muy baja","baja")) | I8: =magnitudes!K8
A9: =magnitudes!A9 | B9: =magnitudes!D9 | C9: =magnitudes!E9 | D9: =magnitudes!F9 | E9: =magnitudes!H9 | F9: =magnitudes!I9 | G9: =magnitudes!J9 | H9: =IF(AND(LEFT(F9,18)="magnitud preferida",G9>=3),"media",IF(LEFT(F9,22)="rango de la literatura","muy baja","baja")) | I9: =magnitudes!K9
A10: =magnitudes!A10 | B10: =magnitudes!D10 | C10: =magnitudes!E10 | D10: =magnitudes!F10 | E10: =magnitudes!H10 | F10: =magnitudes!I10 | G10: =magnitudes!J10 | H10: =IF(AND(LEFT(F10,18)="magnitud preferida",G10>=3),"media",IF(LEFT(F10,22)="rango de la literatura","muy baja","baja")) | I10: =magnitudes!K10
A11: =magnitudes!A11 | B11: =magnitudes!D11 | C11: =magnitudes!E11 | D11: =magnitudes!F11 | E11: =magnitudes!H11 | F11: =magnitudes!I11 | G11: =magnitudes!J11 | H11: =IF(AND(LEFT(F11,18)="magnitud preferida",G11>=3),"media",IF(LEFT(F11,22)="rango de la literatura","muy baja","baja")) | I11: =magnitudes!K11
A12: =magnitudes!A12 | B12: =magnitudes!D12 | C12: =magnitudes!E12 | D12: =magnitudes!F12 | E12: =magnitudes!H12 | F12: =magnitudes!I12 | G12: =magnitudes!J12 | H12: =IF(AND(LEFT(F12,18)="magnitud preferida",G12>=3),"media",IF(LEFT(F12,22)="rango de la literatura","muy baja","baja")) | I12: =magnitudes!K12

Sheet magnitudes
A1: magnitudes: magnitud preferida por factor (B5)
A2: Fuente: output/v5/cifras_clave.csv (V18-B5-E*) y output/v18/f5/magnitudes.csv. AZUL: dato introducido (fuente en la nota de la celda); NEGRO: fórmula de esta hoja; VERDE: vínculo a otra pestaña.
A3: factor | B3: id | C3: indicador | D3: valor | E3: min | F3: max | G3: unidad | H3: clasificacion_v18 | I3: estado_b5 | J3: n_estudios_meta | K3: limitacion | L3: ancho (max - min)
A4: E1 | B4: V18-B5-E1 | C4: Magnitud preferida de vivienda turística (E1): Δln del alquiler por +1 pp de viviendas turísticas sobre el parque | D4: 0.038 | E4: 0.0145 | F4: 0.0615 | G4: Δln del alquiler por +1 pp de viviendas turísticas sobre el parque | H4: NO ESTIMABLE | I4: magnitud de un solo estudio | J4: 1 | K4: un solo estudio en la unidad: sin heterogeneidad estimable | L4: =IF(AND(ISNUMBER(E4),ISNUMBER(F4)),F4-E4,"")
A5: E2 | B5: V18-B5-E2 | C5: Magnitud preferida de topes al alquiler (E2): ATT en ln de la renta de los contratos regulados | E5: -0.1225 | F5: 0.0029 | G5: ATT en ln de la renta de los contratos regulados | H5: SUGESTIVO | I5: rango sin magnitud preferida (la decisión no coincide en las tres priors) | J5: 3 | K5: herramienta meta_bayes NO APTO por conservadora (intervalos que cubren de más; el prior s/2 queda corto en calibración); episodio compartido con el original: cuenta una vez (rho = 0,8) | L5: =IF(AND(ISNUMBER(E5),ISNUMBER(F5)),F5-E5,"")
A6: E3 | B6: V18-B5-E3 | C6: Magnitud preferida de inmigración (E3): % de precio por +1 % de población por entrada de inmigrantes | E6: -0.4902 | F6: 3.5146 | G6: % de precio por +1 % de población por entrada de inmigrantes | H6: NO ESTIMABLE | I6: rango sin magnitud preferida (I² > 75 % y el intervalo de predicción cambia de signo) | J6: 5 | K6: herramienta meta_bayes NO APTO por conservadora (intervalos que cubren de más; el prior s/2 queda corto en calibración) | L6: =IF(AND(ISNUMBER(E6),ISNUMBER(F6)),F6-E6,"")
A7: E4 | B7: V18-B5-E4 | C7: Magnitud preferida de ayudas a la demanda (E4): θ: euros de alquiler por euro de ayuda | D7: 0.0408 | E7: -0.0138 | F7: 0.0953 | G7: θ: euros de alquiler por euro de ayuda | H7: NO ESTIMABLE | I7: magnitud preferida | J7: 2 | K7: con K = 2 el efecto fijo no cubre mu si hay heterogeneidad (cobertura 0,50-0,56 en el Monte Carlo) | L7: =IF(AND(ISNUMBER(E7),ISNUMBER(F7)),F7-E7,"")
A8: E5 | B8: V18-B5-E5 | C8: Magnitud preferida de oferta y suelo (E5): elasticidad precio de la oferta de unidades | E8: -0.2016 | F8: 1.4847 | G8: elasticidad precio de la oferta de unidades | H8: NO ESTIMABLE | I8: rango sin magnitud preferida (I² > 75 % y el intervalo de predicción cambia de signo) | J8: 3 | K8: herramienta meta_bayes NO APTO por conservadora (intervalos que cubren de más; el prior s/2 queda corto en calibración) | L8: =IF(AND(ISNUMBER(E8),ISNUMBER(F8)),F8-E8,"")
A9: E6 | B9: V18-B5-E6 | C9: Magnitud preferida de obra nueva (E6): elasticidad del alquiler respecto a la oferta nueva (% por 1 %) | D9: -0.192 | E9: -0.3194 | F9: -0.0646 | G9: elasticidad del alquiler respecto a la oferta nueva (% por 1 %) | H9: NO ESTIMABLE | I9: magnitud de un solo estudio | J9: 1 | K9: un solo estudio en la unidad: sin heterogeneidad estimable | L9: =IF(AND(ISNUMBER(E9),ISNUMBER(F9)),F9-E9,"")
A10: E7 | B10: V18-B5-E7 | C10: Magnitud preferida de tipos de interés (E7): % del precio por +100 pb del tipo hipotecario, a 8 trimestres | E10: -5 | F10: -2 | G10: % del precio por +100 pb del tipo hipotecario, a 8 trimestres | H10: NO ESTIMABLE | I10: rango de la literatura, sin error típico (no hay metaanálisis ni intervalo estadístico) | J10: 0 | L10: =IF(AND(ISNUMBER(E10),ISNUMBER(F10)),F10-E10,"")
A11: E8 | B11: V18-B5-E8 | C11: Magnitud preferida de fiscalidad de la compra (ITP) (E8): % de precio por +1 pp del ITP, a 12 meses | E11: -3.5 | F11: -3 | G11: % de precio por +1 pp del ITP, a 12 meses | H11: NO ESTIMABLE | I11: rango de la literatura, sin error típico (no hay metaanálisis ni intervalo estadístico) | J11: 0 | L11: =IF(AND(ISNUMBER(E11),ISNUMBER(F11)),F11-E11,"")
A12: E9 | B12: V18-B5-E9 | C12: Magnitud preferida de compradores no residentes (E9): % de precio por +1 pp de cuota de compras de no residentes | E12: 1.4 | F12: 2.1 | G12: % de precio por +1 pp de cuota de compras de no residentes | H12: NO ESTIMABLE | I12: rango de la literatura, sin error típico (no hay metaanálisis ni intervalo estadístico) | J12: 0 | L12: =IF(AND(ISNUMBER(E12),ISNUMBER(F12)),F12-E12,"")

Sheet estimaciones
A1: estimaciones: cifras V18 de output/v5/cifras_clave.csv
A2: Fuente: output/v5/cifras_clave.csv (ids V18-E* y V18-F*; origen output/v18/f6/hechos.json). AZUL: dato introducido (fuente en la nota de la celda); NEGRO: fórmula de esta hoja; VERDE: vínculo a otra pestaña.
A3: id | B3: indicador | C3: valor | D3: min | E3: max | F3: unidad | G3: periodo | H3: cobertura | I3: capa | J3: clasificacion_v18 | K3: tipo_rango | L3: ancho (max - min) | M3: intervalo contiene el 0
A4: V18-E1-A1 | B4: MDE al 80 % de potencia (Anderson-Rubin) de la ampliación E1-A1: % de viviendas turísticas (INE-VUT) instrumentado con proximidad a atractivos × noches de la NUTS3, València, Sevilla, Málaga y Alicante | C4: 0.165617 | F4: log por punto porcentual de viviendas turísticas | G4: 2021-2024 | H4: 1316 secciones, 36 distritos censales, 2021-2024 | I4: C4 | J4: NO ESTIMABLE | K4: sin rango | L4: =IF(AND(ISNUMBER(D4),ISNUMBER(E4)),E4-D4,"") | M4: =IF(AND(ISNUMBER(D4),ISNUMBER(E4)),IF(AND(D4<=0,E4>=0),"sí","no"),"")
A5: V18-E1-P-H3 | B5: Coeficiente del % de viviendas turísticas (INE-VUT, por desviación típica intra-sección) sobre el log del alquiler mediano SERPAVI por sección: especificación de H3 de V15 en la muestra V18 | C5: -6.5e-05 | D5: -0.000886 | E5: 0.000756 | F5: log por DT intra-sección | G5: 2021-2024 | H5: 10004 secciones de España no selladas, 1208 municipios, 2021-2024 | I5: C4 | J5: SUGESTIVO | K5: rango | L5: =IF(AND(ISNUMBER(D5),ISNUMBER(E5)),E5-D5,"") | M5: =IF(AND(ISNUMBER(D5),ISNUMBER(E5)),IF(AND(D5<=0,E5>=0),"sí","no"),"")
A6: V18-E1-R1 | B6: Barrios de Barcelona cuyo stock de viviendas turísticas cambia al menos un 10 % entre el primer y el último valor anual (mínimo de datos de E1-R1) | C6: 18 | F6: barrios (mínimo 20) | G6: 2018-2024 | H6: 48 barrios no sellados; stock por barrio a partir de los puntos del registro | I6: C4 | J6: NO ESTIMABLE | K6: sin rango | L6: =IF(AND(ISNUMBER(D6),ISNUMBER(E6)),E6-D6,"") | M6: =IF(AND(ISNUMBER(D6),ISNUMBER(E6)),IF(AND(D6<=0,E6>=0),"sí","no"),"")
A7: V18-E1-R2 | B7: F efectivo de la primera etapa de la proximidad a atractivos × Google Trends sobre la densidad de viviendas turísticas (Barcelona, 2018-2024, con distancia al centro × año) | C7: 0.023264 | F7: F efectivo (MOP) | G7: 2018-2024 | H7: 769 de las 1.068 secciones de Barcelona (sin Gràcia, Sant Andreu y Nou Barris, sellados en V15 y V16), en 48 barrios; 769 con SERPAVI; viviendas del Censo 2021 como denominador | I7: C4 | J7: NO ESTIMABLE | K7: sin rango | L7: =IF(AND(ISNUMBER(D7),ISNUMBER(E7)),E7-D7,"") | M7: =IF(AND(ISNUMBER(D7),ISNUMBER(E7)),IF(AND(D7<=0,E7>=0),"sí","no"),"")
A8: V18-E1-R3 | B8: Coeficiente de la densidad de viviendas turísticas (HUT de 2018T2, por pp) × posterior (2014-2019) sobre el log del alquiler mediano SERPAVI por sección, Barcelona | C8: 0.004428 | D8: 0.001989 | E8: 0.006867 | F8: log por pp de densidad HUT (por 100 viviendas) | G8: 2011-2019 | H8: 769 de las 1.068 secciones de Barcelona (sin Gràcia, Sant Andreu y Nou Barris, sellados en V15 y V16), en 48 barrios; 769 con SERPAVI; viviendas del Censo 2021 como denominador | I8: C4 | J8: ASOCIACIÓN | K8: rango | L8: =IF(AND(ISNUMBER(D8),ISNUMBER(E8)),E8-D8,"") | M8: =IF(AND(ISNUMBER(D8),ISNUMBER(E8)),IF(AND(D8<=0,E8>=0),"sí","no"),"")
A9: V18-E1-R4 | B9: Coeficiente de estar a menos de 500 m de la Sagrada Família × posterior (2014-2019) sobre el log del alquiler mediano SERPAVI por sección, frente al anillo de 500-1.000 m | C9: 0.001659 | D9: -0.034597 | E9: 0.067167 | F9: log (diferencia entre radio y anillo, posterior frente a 2013) | G9: 2011-2019 | H9: 22 secciones en el radio y 55 en el anillo, no selladas; el anillo conserva 55 de 70 secciones | I9: C4 | J9: NO CONCLUYENTE | K9: rango | L9: =IF(AND(ISNUMBER(D9),ISNUMBER(E9)),E9-D9,"") | M9: =IF(AND(ISNUMBER(D9),ISNUMBER(E9)),IF(AND(D9<=0,E9>=0),"sí","no"),"")
A10: V18-E10-A1 | B10: Alquiler municipal por m² y % de viviendas de grandes tenedores: asociación transversal (E10-A1) | C10: 1.0683 | D10: -0.0682 | E10: 2.2047 | F10: % de variación del alquiler por m² (log × 100) por punto porcentual de viviendas de grandes tenedores en el municipio | G10: 2019-2024 | H10: 1365 municipios | I10: C4 | J10: ASOCIACIÓN | K10: rango | L10: =IF(AND(ISNUMBER(D10),ISNUMBER(E10)),E10-D10,"") | M10: =IF(AND(ISNUMBER(D10),ISNUMBER(E10)),IF(AND(D10<=0,E10>=0),"sí","no"),"")
A11: V18-E10-A1-d | B11: Alquiler municipal por m² y % de viviendas de grandes tenedores: asociación transversal (E10-A1-d) | C11: 0.1048 | D11: -0.4369 | E11: 0.6465 | F11: % de variación del alquiler por m² (log × 100) por punto porcentual de viviendas de grandes tenedores en el municipio | G11: 2019-2024 | H11: 1219 municipios | I11: C4 | J11: ASOCIACIÓN | K11: rango | L11: =IF(AND(ISNUMBER(D11),ISNUMBER(E11)),E11-D11,"") | M11: =IF(AND(ISNUMBER(D11),ISNUMBER(E11)),IF(AND(D11<=0,E11>=0),"sí","no"),"")
A12: V18-E10-A1-d-v1 | B12: Alquiler municipal por m² y % de viviendas de grandes tenedores: asociación transversal (E10-A1-d-v1) | C12: 0.4304 | D12: 0.0961 | E12: 0.7647 | F12: % de variación del alquiler por m² (log × 100) por punto porcentual de viviendas de grandes tenedores en el municipio | G12: 2019-2024 | H12: 1219 municipios | I12: C4 | J12: ASOCIACIÓN | K12: rango | L12: =IF(AND(ISNUMBER(D12),ISNUMBER(E12)),E12-D12,"") | M12: =IF(AND(ISNUMBER(D12),ISNUMBER(E12)),IF(AND(D12<=0,E12>=0),"sí","no"),"")
A13: V18-E10-A1-d-v2 | B13: Alquiler municipal por m² y % de viviendas de grandes tenedores: asociación transversal (E10-A1-d-v2) | C13: 0.1069 | D13: -0.4355 | E13: 0.6494 | F13: % de variación del alquiler por m² (log × 100) por punto porcentual de viviendas de grandes tenedores en el municipio | G13: 2019-2024 | H13: 1218 municipios | I13: C4 | J13: ASOCIACIÓN | K13: rango | L13: =IF(AND(ISNUMBER(D13),ISNUMBER(E13)),E13-D13,"") | M13: =IF(AND(ISNUMBER(D13),ISNUMBER(E13)),IF(AND(D13<=0,E13>=0),"sí","no"),"")
A14: V18-E10-A1-d-v3 | B14: Alquiler municipal por m² y % de viviendas de grandes tenedores: asociación transversal (E10-A1-d-v3) | C14: -0.0031 | D14: -0.4711 | E14: 0.4649 | F14: % de variación del alquiler por m² (log × 100) por punto porcentual de viviendas de grandes tenedores en el municipio | G14: 2019-2024 | H14: 1219 municipios | I14: C4 | J14: ASOCIACIÓN | K14: rango | L14: =IF(AND(ISNUMBER(D14),ISNUMBER(E14)),E14-D14,"") | M14: =IF(AND(ISNUMBER(D14),ISNUMBER(E14)),IF(AND(D14<=0,E14>=0),"sí","no"),"")
A15: V18-E10-A1-d-v4 | B15: Alquiler municipal por m² y % de viviendas de grandes tenedores: asociación transversal (E10-A1-d-v4) | C15: -0.0196 | D15: -0.4127 | E15: 0.3734 | F15: % de variación del alquiler por m² (log × 100) por punto porcentual de viviendas de grandes tenedores en el municipio | G15: 2019-2024 | H15: 394 municipios | I15: C4 | J15: ASOCIACIÓN | K15: rango | L15: =IF(AND(ISNUMBER(D15),ISNUMBER(E15)),E15-D15,"") | M15: =IF(AND(ISNUMBER(D15),ISNUMBER(E15)),IF(AND(D15<=0,E15>=0),"sí","no"),"")
A16: V18-E10-A1-d-vF | B16: Alquiler municipal por m² y % de viviendas de grandes tenedores: asociación transversal (E10-A1-d-vF) | C16: 0.1041 | D16: -0.477 | E16: 0.6851 | F16: % de variación del alquiler por m² (log × 100) por punto porcentual de viviendas de grandes tenedores en el municipio | G16: 2019-2024 | H16: 1100 municipios | I16: C4 | J16: ASOCIACIÓN | K16: rango | L16: =IF(AND(ISNUMBER(D16),ISNUMBER(E16)),E16-D16,"") | M16: =IF(AND(ISNUMBER(D16),ISNUMBER(E16)),IF(AND(D16<=0,E16>=0),"sí","no"),"")
A17: V18-E10-A1-v1 | B17: Alquiler municipal por m² y % de viviendas de grandes tenedores: asociación transversal (E10-A1-v1) | C17: 2.7075 | D17: 1.5415 | E17: 3.8735 | F17: % de variación del alquiler por m² (log × 100) por punto porcentual de viviendas de grandes tenedores en el municipio | G17: 2019-2024 | H17: 1365 municipios | I17: C4 | J17: ASOCIACIÓN | K17: rango | L17: =IF(AND(ISNUMBER(D17),ISNUMBER(E17)),E17-D17,"") | M17: =IF(AND(ISNUMBER(D17),ISNUMBER(E17)),IF(AND(D17<=0,E17>=0),"sí","no"),"")
A18: V18-E10-A1-v2 | B18: Alquiler municipal por m² y % de viviendas de grandes tenedores: asociación transversal (E10-A1-v2) | C18: 1.0716 | D18: -0.0647 | E18: 2.208 | F18: % de variación del alquiler por m² (log × 100) por punto porcentual de viviendas de grandes tenedores en el municipio | G18: 2019-2024 | H18: 1364 municipios | I18: C4 | J18: ASOCIACIÓN | K18: rango | L18: =IF(AND(ISNUMBER(D18),ISNUMBER(E18)),E18-D18,"") | M18: =IF(AND(ISNUMBER(D18),ISNUMBER(E18)),IF(AND(D18<=0,E18>=0),"sí","no"),"")
A19: V18-E10-A1-v3 | B19: Alquiler municipal por m² y % de viviendas de grandes tenedores: asociación transversal (E10-A1-v3) | C19: 2.3926 | D19: 1.2219 | E19: 3.5634 | F19: % de variación del alquiler por m² (log × 100) por punto porcentual de viviendas de grandes tenedores en el municipio | G19: 2019-2024 | H19: 1365 municipios | I19: C4 | J19: ASOCIACIÓN | K19: rango | L19: =IF(AND(ISNUMBER(D19),ISNUMBER(E19)),E19-D19,"") | M19: =IF(AND(ISNUMBER(D19),ISNUMBER(E19)),IF(AND(D19<=0,E19>=0),"sí","no"),"")
... A22: V18-E12-A1 | B22: Viviendas libres iniciadas: respuesta a la vivienda protegida calificada, IV provincial (E12-A1) | C22: 6.5067 | D22: -1.1918 | E22: 170.0367 | F22: viviendas libres iniciadas por 100 viviendas del parque, por vivienda protegida calificada (por 100 del parque): viviendas privadas por vivienda protegida | G22: 2002-2024 | H22: 38 provincias | I22: C4 | J22: NO ESTIMABLE | K22: rango | L22: =IF(AND(ISNUMBER(D22),ISNUMBER(E22)),E22-D22,"") | M22: =IF(AND(ISNUMBER(D22),ISNUMBER(E22)),IF(AND(D22<=0,E22>=0),"sí","no"),"")
A23: V18-E12-A1-sin-atipicos | B23: Viviendas libres iniciadas: respuesta a la vivienda protegida calificada, IV provincial (E12-A1-sin-atipicos) | C23: 12.4061 | F23: viviendas libres iniciadas por 100 viviendas del parque, por vivienda protegida calificada (por 100 del parque): viviendas privadas por vivienda protegida | G23: 2002-2024 | H23: 36 provincias | I23: C4 | J23: NO ESTIMABLE | K23: sin rango | L23: =IF(AND(ISNUMBER(D23),ISNUMBER(E23)),E23-D23,"") | M23: =IF(AND(ISNUMBER(D23),ISNUMBER(E23)),IF(AND(D23<=0,E23>=0),"sí","no"),"")
A24: V18-E12-A1-v1 | B24: Viviendas libres iniciadas: respuesta a la vivienda protegida calificada, IV provincial (E12-A1-v1) | C24: 4.4909 | F24: viviendas libres iniciadas por 100 viviendas del parque, por vivienda protegida calificada (por 100 del parque): viviendas privadas por vivienda protegida | G24: 2002-2024 | H24: 38 provincias | I24: C4 | J24: NO ESTIMABLE | K24: sin rango | L24: =IF(AND(ISNUMBER(D24),ISNUMBER(E24)),E24-D24,"") | M24: =IF(AND(ISNUMBER(D24),ISNUMBER(E24)),IF(AND(D24<=0,E24>=0),"sí","no"),"")
A25: V18-E12-A1-v2 | B25: Viviendas libres iniciadas: respuesta a la vivienda protegida calificada, IV provincial (E12-A1-v2) | C25: 6.7716 | F25: viviendas libres iniciadas por 100 viviendas del parque, por vivienda protegida calificada (por 100 del parque): viviendas privadas por vivienda protegida | G25: 2002-2024 | H25: 37 provincias | I25: C4 | J25: NO ESTIMABLE | K25: sin rango | L25: =IF(AND(ISNUMBER(D25),ISNUMBER(E25)),E25-D25,"") | M25: =IF(AND(ISNUMBER(D25),ISNUMBER(E25)),IF(AND(D25<=0,E25>=0),"sí","no"),"")
A26: V18-E12-A1-v4 | B26: Viviendas libres iniciadas: respuesta a la vivienda protegida calificada, IV provincial (E12-A1-v4) | C26: 94.0749 | F26: viviendas libres iniciadas por 100 viviendas del parque, por vivienda protegida calificada (por 100 del parque): viviendas privadas por vivienda protegida | G26: 2002-2013 | H26: 38 provincias | I26: C4 | J26: NO ESTIMABLE | K26: sin rango | L26: =IF(AND(ISNUMBER(D26),ISNUMBER(E26)),E26-D26,"") | M26: =IF(AND(ISNUMBER(D26),ISNUMBER(E26)),IF(AND(D26<=0,E26>=0),"sí","no"),"")
A27: V18-E12-A2 | B27: Viviendas valor tasado: respuesta a la vivienda protegida calificada, IV provincial (E12-A2) | C27: 22.084 | F27: % del valor tasado real (variación anual) por cada 100 viviendas protegidas calificadas por 100 del parque | G27: 2003-2024 | H27: 33 provincias | I27: C4 | J27: ASOCIACIÓN | K27: sin rango | L27: =IF(AND(ISNUMBER(D27),ISNUMBER(E27)),E27-D27,"") | M27: =IF(AND(ISNUMBER(D27),ISNUMBER(E27)),IF(AND(D27<=0,E27>=0),"sí","no"),"")
A28: V18-E12-A2-v1 | B28: Viviendas valor tasado: respuesta a la vivienda protegida calificada, IV provincial (E12-A2-v1) | C28: 21.9526 | F28: % del valor tasado real (variación anual) por cada 100 viviendas protegidas calificadas por 100 del parque | G28: 2003-2024 | H28: 32 provincias | I28: C4 | J28: ASOCIACIÓN | K28: sin rango | L28: =IF(AND(ISNUMBER(D28),ISNUMBER(E28)),E28-D28,"") | M28: =IF(AND(ISNUMBER(D28),ISNUMBER(E28)),IF(AND(D28<=0,E28>=0),"sí","no"),"")
A29: V18-E12-A2-v2 | B29: Viviendas valor tasado: respuesta a la vivienda protegida calificada, IV provincial (E12-A2-v2) | C29: 147.2348 | F29: % del valor tasado real (variación anual) por cada 100 viviendas protegidas calificadas por 100 del parque | G29: 2003-2013 | H29: 33 provincias | I29: C4 | J29: ASOCIACIÓN | K29: sin rango | L29: =IF(AND(ISNUMBER(D29),ISNUMBER(E29)),E29-D29,"") | M29: =IF(AND(ISNUMBER(D29),ISNUMBER(E29)),IF(AND(D29<=0,E29>=0),"sí","no"),"")
A30: V18-E2-A1 | B30: MDE al 80 % de potencia de la ampliación a las zonas tensionadas de 2024 de Cataluña (log de la renta media) | C30: 0.040822 | F30: log (MDE80) | G30: 2019T1-2026T1 | H30: 169 tratados y 20 controles | I30: C4 | J30: NO ESTIMABLE | K30: sin rango | L30: =IF(AND(ISNUMBER(D30),ISNUMBER(E30)),E30-D30,"") | M30: =IF(AND(ISNUMBER(D30),ISNUMBER(E30)),IF(AND(D30<=0,E30>=0),"sí","no"),"")
A31: V18-E2-A2 | B31: Zonas tensionadas fuera de Cataluña (País Vasco, EMAL): recuento de municipios tratados con datos | C31: 6 | F31: municipios | G31: 2016T1-2025T4 | H31: 6 municipios tratados con EMAL no sellados (mínimo 10) y trimestres posteriores por cohorte {'2025T2': np.int64(3), '2025T3': np.int64(2), '2025T4': np.int64(1), '2026T2': np.int64(0), '2026T3': np.int64(0)} (mínimo 3) | I31: C4 | J31: NO ESTIMABLE | K31: sin rango | L31: =IF(AND(ISNUMBER(D31),ISNUMBER(E31)),E31-D31,"") | M31: =IF(AND(ISNUMBER(D31),ISNUMBER(E31)),IF(AND(D31<=0,E31>=0),"sí","no"),"")
A32: V18-E2-A3 | B32: Desplazamiento a la venta: compraventas municipales por 1.000 habitantes, controles disponibles en la serie municipal de MIVAU | C32: 2 | F32: municipios de control | G32: 2016-2022 | H32: 44 tratados y 2 controles en la serie municipal de MIVAU | I32: C4 | J32: NO ESTIMABLE | K32: sin rango | L32: =IF(AND(ISNUMBER(D32),ISNUMBER(E32)),E32-D32,"") | M32: =IF(AND(ISNUMBER(D32),ISNUMBER(E32)),IF(AND(D32<=0,E32>=0),"sí","no"),"")
A33: V18-E2-A4 | B33: MDE al 80 % de potencia del desbordamiento a municipios vecinos (log de la renta media) | C33: 0.044404 | F33: log (MDE80) | G33: 2019T1-2022T1 | H33: 84 tratados y 12 controles | I33: C4 | J33: NO ESTIMABLE | K33: sin rango | L33: =IF(AND(ISNUMBER(D33),ISNUMBER(E33)),E33-D33,"") | M33: =IF(AND(ISNUMBER(D33),ISNUMBER(E33)),IF(AND(D33<=0,E33>=0),"sí","no"),"")
A34: V18-E2-B6-A | B34: Salto en 2022T2 del coeficiente de Reg por trimestre sobre la extrapolación de la recta de 2021T1-2022T1 (log de la renta media; E2-R1, robustez a posteriori) | C34: -0.021664 | D34: -0.046751 | E34: 0.003423 | F34: log | G34: 2019T1-2022T2 | H34: 49 regulados y 94 controles, panel equilibrado 2019T1-2022T2 | I34: C4 | J34: SUGESTIVO | K34: rango | L34: =IF(AND(ISNUMBER(D34),ISNUMBER(E34)),E34-D34,"") | M34: =IF(AND(ISNUMBER(D34),ISNUMBER(E34)),IF(AND(D34<=0,E34>=0),"sí","no"),"")
A35: V18-E2-B6-B | B35: Coeficiente Reg × Post con densidad HUT 2019 y ln(población 2019) por efectos de trimestre (E2-R1, robustez a posteriori) | C35: -0.024163 | D35: -0.046151 | E35: -0.002176 | F35: log | G35: 2019T1-2022T1 | H35: 49 regulados y 94 controles | I35: C4 | J35: SUGESTIVO | K35: rango | L35: =IF(AND(ISNUMBER(D35),ISNUMBER(E35)),E35-D35,"") | M35: =IF(AND(ISNUMBER(D35),ISNUMBER(E35)),IF(AND(D35<=0,E35>=0),"sí","no"),"")
A36: V18-E2-B6-C | B36: Coeficiente Reg × Post con controles emparejados por el crecimiento de la renta 2017-2019 (E2-R1, robustez a posteriori) | C36: -0.054625 | D36: -0.080597 | E36: -0.028653 | F36: log | G36: 2019T1-2022T1 | H36: 49 regulados y 31 controles emparejados con reposición | I36: C4 | J36: SUGESTIVO | K36: rango | L36: =IF(AND(ISNUMBER(D36),ISNUMBER(E36)),E36-D36,"") | M36: =IF(AND(ISNUMBER(D36),ISNUMBER(E36)),IF(AND(D36<=0,E36>=0),"sí","no"),"")
A37: V18-E2-B6-D | B37: Estimación SDID de Reg × Post con controles ponderados, todos los no regulados con serie completa (E2-R1, robustez a posteriori) | C37: -0.044 | D37: -0.062427 | E37: -0.025572 | F37: log | G37: 2019T1-2022T1 | H37: 49 regulados y 146 controles | I37: C4 | J37: SUGESTIVO | K37: rango | L37: =IF(AND(ISNUMBER(D37),ISNUMBER(E37)),E37-D37,"") | M37: =IF(AND(ISNUMBER(D37),ISNUMBER(E37)),IF(AND(D37<=0,E37>=0),"sí","no"),"")
A38: V18-E2-B6-R1CV1 | B38: Coeficiente Reg × Post sobre el log de contratos nuevos por 1.000 hogares inquilinos del Censo 2021 (E2-R1c-v1) | C38: -0.031396 | D38: -0.084619 | E38: 0.021828 | F38: log | G38: 2019T1-2022T1 | H38: 49 regulados y 38 controles de 10.000 habitantes o más (Censo 2021, muestra del 10 %) | I38: C4 | J38: ASOCIACIÓN | K38: rango | L38: =IF(AND(ISNUMBER(D38),ISNUMBER(E38)),E38-D38,"") | M38: =IF(AND(ISNUMBER(D38),ISNUMBER(E38)),IF(AND(D38<=0,E38>=0),"sí","no"),"")
A39: V18-E2-R1 | B39: Coeficiente Reg × Post sobre el log de la renta media de contratos nuevos de alquiler (Ley 11/2020, Cataluña, Incasòl) | C39: -0.038434 | D39: -0.050944 | E39: -0.02618 | F39: log (diferencia entre regulados y controles, posterior frente a previo) | G39: 2019T1-2022T1 | H39: 49 municipios regulados por la Ley 11/2020 y 94 controles de Cataluña, panel trimestral equilibrado 2019T1-2022T1 sin Barcelona ciudad; sin los municipios sellados en v6, V15 y V16 | I39: C4 | J39: SUGESTIVO | K39: rango | L39: =IF(AND(ISNUMBER(D39),ISNUMBER(E39)),E39-D39,"") | M39: =IF(AND(ISNUMBER(D39),ISNUMBER(E39)),IF(AND(D39<=0,E39>=0),"sí","no"),"")
A40: V18-E2-R1-REV | B40: Coeficiente de la reversión en 2022T2-2023T4 (tras la STC 37/2022) sobre el log de la renta media, municipios regulados frente a controles | C40: -0.001566 | D40: -0.016786 | E40: 0.013653 | F40: log (nivel posterior a la norma frente a previo) | G40: 2019T1-2023T4 | H40: 49 regulados y 91 controles, panel 2019T1-2023T4 | I40: C4 | J40: SUGESTIVO | K40: rango | L40: =IF(AND(ISNUMBER(D40),ISNUMBER(E40)),E40-D40,"") | M40: =IF(AND(ISNUMBER(D40),ISNUMBER(E40)),IF(AND(D40<=0,E40>=0),"sí","no"),"")
A41: V18-E2-R1c | B41: Coeficiente Reg × Post sobre el log de contratos nuevos por 1.000 habitantes (Ley 11/2020, Cataluña, Incasòl) | C41: 0.017322 | D41: -0.024899 | E41: 0.059521 | F41: log (diferencia entre regulados y controles, posterior frente a previo) | G41: 2019T1-2022T1 | H41: 49 regulados y 156 controles, panel trimestral equilibrado | I41: C4 | J41: ASOCIACIÓN | K41: rango | L41: =IF(AND(ISNUMBER(D41),ISNUMBER(E41)),E41-D41,"") | M41: =IF(AND(ISNUMBER(D41),ISNUMBER(E41)),IF(AND(D41<=0,E41>=0),"sí","no"),"")
A42: V18-E3-1HHI | B42: E3: número efectivo de choques (1/HHI de los pesos por origen) | C42: 7.858302 | F42: choques efectivos | G42: 2002, 2004-2008 | H42: 8 grupos de origen | I42: C4 | J42: NO CONCLUYENTE | K42: sin rango | L42: =IF(AND(ISNUMBER(D42),ISNUMBER(E42)),E42-D42,"") | M42: =IF(AND(ISNUMBER(D42),ISNUMBER(E42)),IF(AND(D42<=0,E42>=0),"sí","no"),"")
...

Sheet contabilidad
A1: contabilidad: cifras V18 de output/v5/cifras_clave.csv
A2: Fuente: output/v5/cifras_clave.csv (ids V18-C5-*: contabilidad principal; V18-C5I-*: ilustración con magnitudes de la literatura, no es una atribución). AZUL: dato introducido (fuente en la nota de la celda); NEGRO: fórmula de esta hoja; VERDE: vínculo a otra pestaña.
A3: id | B3: indicador | C3: valor | D3: min | E3: max | F3: unidad | G3: periodo | H3: cobertura | I3: capa | J3: clasificacion_v18 | K3: tipo_rango | L3: ancho (max - min) | M3: intervalo contiene el 0
A4: V18-C5-1995T1-2007T4-00-NOEXPL-A | B4: Variación del alquiler real sin explicar, 1995T1-2007T4, Nacional | C4: 1.7972 | D4: 1.7972 | E4: 1.7972 | F4: pp (100·Δln) | G4: 1995T1-2007T4 | H4: Nacional; 2002T1 a 2007T4 | I4: C4 | J4: NO ESTIMABLE | K4: rango | L4: =IF(AND(ISNUMBER(D4),ISNUMBER(E4)),E4-D4,"") | M4: =IF(AND(ISNUMBER(D4),ISNUMBER(E4)),IF(AND(D4<=0,E4>=0),"sí","no"),"")
A5: V18-C5-1995T1-2007T4-00-NOEXPL-P | B5: Variación del precio real sin explicar, 1995T1-2007T4, Nacional | C5: 68.9809 | D5: 68.9809 | E5: 68.9809 | F5: pp (100·Δln) | G5: 1995T1-2007T4 | H5: Nacional; 1995T1 a 2007T4 | I5: C4 | J5: NO ESTIMABLE | K5: rango | L5: =IF(AND(ISNUMBER(D5),ISNUMBER(E5)),E5-D5,"") | M5: =IF(AND(ISNUMBER(D5),ISNUMBER(E5)),IF(AND(D5<=0,E5>=0),"sí","no"),"")
A6: V18-C5-1995T1-2007T4-01-NOEXPL-A | B6: Variación del alquiler real sin explicar, 1995T1-2007T4, Andalucía | C6: 3.0977 | D6: 3.0977 | E6: 3.0977 | F6: pp (100·Δln) | G6: 1995T1-2007T4 | H6: Andalucía; 2002T1 a 2007T4 (media de provincias no selladas, ponderada por población) | I6: C4 | J6: NO ESTIMABLE | K6: rango | L6: =IF(AND(ISNUMBER(D6),ISNUMBER(E6)),E6-D6,"") | M6: =IF(AND(ISNUMBER(D6),ISNUMBER(E6)),IF(AND(D6<=0,E6>=0),"sí","no"),"")
A7: V18-C5-1995T1-2007T4-01-NOEXPL-P | B7: Variación del precio real sin explicar, 1995T1-2007T4, Andalucía | C7: 9.2104 | D7: 9.2104 | E7: 9.2104 | F7: pp (100·Δln) | G7: 1995T1-2007T4 | H7: Andalucía; 2002T1 a 2007T4 (media de provincias no selladas, ponderada por población) | I7: C4 | J7: NO ESTIMABLE | K7: rango | L7: =IF(AND(ISNUMBER(D7),ISNUMBER(E7)),E7-D7,"") | M7: =IF(AND(ISNUMBER(D7),ISNUMBER(E7)),IF(AND(D7<=0,E7>=0),"sí","no"),"")
A8: V18-C5-1995T1-2007T4-07-NOEXPL-A | B8: Variación del alquiler real sin explicar, 1995T1-2007T4, Castilla y León | C8: -2.7872 | D8: -2.7872 | E8: -2.7872 | F8: pp (100·Δln) | G8: 1995T1-2007T4 | H8: Castilla y León; 2002T1 a 2007T4 (media de provincias no selladas, ponderada por población) | I8: C4 | J8: NO ESTIMABLE | K8: rango | L8: =IF(AND(ISNUMBER(D8),ISNUMBER(E8)),E8-D8,"") | M8: =IF(AND(ISNUMBER(D8),ISNUMBER(E8)),IF(AND(D8<=0,E8>=0),"sí","no"),"")
A9: V18-C5-1995T1-2007T4-07-NOEXPL-P | B9: Variación del precio real sin explicar, 1995T1-2007T4, Castilla y León | C9: -13.1981 | D9: -13.1981 | E9: -13.1981 | F9: pp (100·Δln) | G9: 1995T1-2007T4 | H9: Castilla y León; 2002T1 a 2007T4 (media de provincias no selladas, ponderada por población) | I9: C4 | J9: NO ESTIMABLE | K9: rango | L9: =IF(AND(ISNUMBER(D9),ISNUMBER(E9)),E9-D9,"") | M9: =IF(AND(ISNUMBER(D9),ISNUMBER(E9)),IF(AND(D9<=0,E9>=0),"sí","no"),"")
A10: V18-C5-1995T1-2007T4-08-NOEXPL-A | B10: Variación del alquiler real sin explicar, 1995T1-2007T4, Castilla-La Mancha | C10: -0.5646 | D10: -0.5646 | E10: -0.5646 | F10: pp (100·Δln) | G10: 1995T1-2007T4 | H10: Castilla-La Mancha; 2002T1 a 2007T4 (media de provincias no selladas, ponderada por población) | I10: C4 | J10: NO ESTIMABLE | K10: rango | L10: =IF(AND(ISNUMBER(D10),ISNUMBER(E10)),E10-D10,"") | M10: =IF(AND(ISNUMBER(D10),ISNUMBER(E10)),IF(AND(D10<=0,E10>=0),"sí","no"),"")
A11: V18-C5-1995T1-2007T4-08-NOEXPL-P | B11: Variación del precio real sin explicar, 1995T1-2007T4, Castilla-La Mancha | C11: 2.7742 | D11: 2.7742 | E11: 2.7742 | F11: pp (100·Δln) | G11: 1995T1-2007T4 | H11: Castilla-La Mancha; 2002T1 a 2007T4 (media de provincias no selladas, ponderada por población) | I11: C4 | J11: NO ESTIMABLE | K11: rango | L11: =IF(AND(ISNUMBER(D11),ISNUMBER(E11)),E11-D11,"") | M11: =IF(AND(ISNUMBER(D11),ISNUMBER(E11)),IF(AND(D11<=0,E11>=0),"sí","no"),"")
A12: V18-C5-1995T1-2007T4-09-NOEXPL-A | B12: Variación del alquiler real sin explicar, 1995T1-2007T4, Cataluña | C12: 5.191 | D12: 5.191 | E12: 5.191 | F12: pp (100·Δln) | G12: 1995T1-2007T4 | H12: Cataluña; 2002T1 a 2007T4 (media de provincias no selladas, ponderada por población) | I12: C4 | J12: NO ESTIMABLE | K12: rango | L12: =IF(AND(ISNUMBER(D12),ISNUMBER(E12)),E12-D12,"") | M12: =IF(AND(ISNUMBER(D12),ISNUMBER(E12)),IF(AND(D12<=0,E12>=0),"sí","no"),"")
A13: V18-C5-1995T1-2007T4-09-NOEXPL-P | B13: Variación del precio real sin explicar, 1995T1-2007T4, Cataluña | C13: -3.4503 | D13: -3.4503 | E13: -3.4503 | F13: pp (100·Δln) | G13: 1995T1-2007T4 | H13: Cataluña; 2002T1 a 2007T4 (media de provincias no selladas, ponderada por población) | I13: C4 | J13: NO ESTIMABLE | K13: rango | L13: =IF(AND(ISNUMBER(D13),ISNUMBER(E13)),E13-D13,"") | M13: =IF(AND(ISNUMBER(D13),ISNUMBER(E13)),IF(AND(D13<=0,E13>=0),"sí","no"),"")
A14: V18-C5-1995T1-2007T4-10-NOEXPL-A | B14: Variación del alquiler real sin explicar, 1995T1-2007T4, Comunitat Valenciana | C14: 1.4901 | D14: 1.4901 | E14: 1.4901 | F14: pp (100·Δln) | G14: 1995T1-2007T4 | H14: Comunitat Valenciana; 2002T1 a 2007T4 (media de provincias no selladas, ponderada por población) | I14: C4 | J14: NO ESTIMABLE | K14: rango | L14: =IF(AND(ISNUMBER(D14),ISNUMBER(E14)),E14-D14,"") | M14: =IF(AND(ISNUMBER(D14),ISNUMBER(E14)),IF(AND(D14<=0,E14>=0),"sí","no"),"")
A15: V18-C5-1995T1-2007T4-10-NOEXPL-P | B15: Variación del precio real sin explicar, 1995T1-2007T4, Comunitat Valenciana | C15: 37.8577 | D15: 37.8577 | E15: 37.8577 | F15: pp (100·Δln) | G15: 1995T1-2007T4 | H15: Comunitat Valenciana; 1995T1 a 2007T4 (media de provincias no selladas, ponderada por población) | I15: C4 | J15: NO ESTIMABLE | K15: rango | L15: =IF(AND(ISNUMBER(D15),ISNUMBER(E15)),E15-D15,"") | M15: =IF(AND(ISNUMBER(D15),ISNUMBER(E15)),IF(AND(D15<=0,E15>=0),"sí","no"),"")
... A293: V18-C5I-2022T3-2026T2-16-NOEXPL_alt_E9-P | B293: Ilustración: variación sin explicar, precio real, 2022T3-2026T2, País Vasco (no_explicado_alternativa) | C293: -5.3839 | D293: -5.5611 | E293: -5.2107 | F293: pp (100·Δln) | G293: 2022T3-2026T2 | H293: País Vasco | I293: C4 | J293: NO ESTIMABLE | K293: rango | L293: =IF(AND(ISNUMBER(D293),ISNUMBER(E293)),E293-D293,"") | M293: =IF(AND(ISNUMBER(D293),ISNUMBER(E293)),IF(AND(D293<=0,E293>=0),"sí","no"),"")
