Workbook

Sheet Leeme
A1: Tablas V8 (F6). Generado por src/v8/f6_tablas.py a partir de salidas versionadas; no estima nada.
A2: Capas: C3s (svar_hd, H8-1…H8-4) condicionada a las restricciones de signo; C4 (asociación) el resto: sin lectura causal.
A3: Fuentes: output/v8/M0…M9 (coeficientes.csv, hipotesis_*.csv, resumen_multiverso.csv, fuera_muestra*), output/v8/F5 (regla_s9, ranking, atribucion_combinada, regional_ranking, fuera_muestra_comun).
A4: Convenciones de color:
A5: AZUL (0000FF): entrada tomada de un fichero de datos o salida; la columna «fuente» da la ruta del fichero.
A6: NEGRO (000000): cálculo hecho en la hoja con fórmula de Excel (=SUM, =COUNTIF, =SUMIFS, cocientes).
A7: VERDE (008000): vínculo a otra hoja del libro (=Hoja!A1).
A8: Sin paneles inmovilizados. Estrellas (si las hay) basadas en el p AJUSTADO. Modelos destacados: véase tablas_modelos_destacados.md.
A9: Hojas: Destacados, Hipotesis, Votos_s9, Atribucion, Ranking, Fuera_muestra, Regional, Multiverso.
A11: Resumen enlazado (verde = vínculo a otra hoja)
A12: Celdas designadas (hoja Votos_s9) | B12: =Votos_s9!B13
A13: Hipótesis tabuladas (hoja Hipotesis, filas) | B13: =COUNTA(Hipotesis!A2:A200)

Sheet Destacados
A1: modelo_id | B1: modulo | C1: familia_modelo | D1: mercado | E1: ambito | F1: periodo | G1: dependiente | H1: transformacion | I1: medida_precio | J1: variable | K1: beta | L1: ee | M1: tipo_ee | N1: t | O1: p | P1: p_ajustado | Q1: metodo_ajuste | R1: ic95_lo | S1: ic95_hi | T1: beta_std | U1: elasticidad | V1: n | W1: r2 | X1: r2_adj | Y1: aic | Z1: bic | AA1: vel_ajuste | AB1: semivida | AC1: coint_p | AD1: bg_p | AE1: bp_p | AF1: jb_p | AG1: reset_p | AH1: cusum_estable | AI1: vif_max | AJ1: f1_etapa | AK1: ar_lo | AL1: ar_hi | AM1: capa | AN1: n_multiverso | AO1: pct_mismo_signo | AP1: pct_sig_bh | AQ1: cumple_regla_m0 | AR1: cumple_multiverso | AS1: destacado | AT1: motivo_destacado | AU1: script | AV1: criterio_destacado | AW1: oos_ref | AX1: no_cumple_regla | AY1: fuente | AZ1: rmse_oos (vínculo) | BA1: rmse_ar4_oos (vínculo) | BB1: ratio_rmse_vs_ar4_calc
A2: M0_compra_base_P1 | B2: M0 | C2: ols_tramos_hac | D2: compra | E2: nacional | F2: P1 | G2: d4_ln_p_tasado_real | H2: d4_ln*100 | I2: valor tasado MIVAU, real (IPC general) | J2: d4_pob_total | K2: -3.6695463 | L2: 1.5114349 | M2: HAC-NW(4), t(32) | N2: -2.427856 | O2: 0.02099081 | P2: 0.045917396 | Q2: BH | R2: -6.7482385 | S2: -0.59085415 | T2: -0.62215703 | V2: 38 | W2: 0.69611677 | X2: 0.64863502 | Y2: 173.70026 | Z2: 183.52578 | AM2: C4 | AN2: 96 | AO2: 0.5 | AP2: 0.13541667 | AQ2: no_evaluable | AR2: no | AS2: si | AT2: (b) mejor de la familia ols_tramos_hac: ecuacion AR1+X por periodo; unico candidato con OOS en la familia; NO CUMPLE LA REGLA (§8 y multiverso) en ninguna variable; RMSE 1.802 vs AR(4) 1.216 (peor que AR(4)) | AU2: src/v8/m0_periodos.py | AV2: (b) mejor de la familia ols_tramos_hac: ecuacion AR1+X por periodo; unico candidato con OOS en la familia | AW2: M0:AR1+X_por_periodo | AX2: si | AY2: output/v8/M0/coeficientes.csv | AZ2: =Fuera_muestra!F16 | BA2: =Fuera_muestra!G16 | BB2: =AZ2/BA2
A3: M0_compra_base_P1 | B3: M0 | C3: ols_tramos_hac | D3: compra | E3: nacional | F3: P1 | G3: d4_ln_p_tasado_real | H3: d4_ln*100 | I3: valor tasado MIVAU, real (IPC general) | J3: d4_pib_vol | K3: -3.5195761 | L3: 0.88831237 | M3: HAC-NW(4), t(32) | N3: -3.9620928 | O3: 0.0003895504 | P3: 0.0015198921 | Q3: BH | R3: -5.3290091 | S3: -1.710143 | T3: -0.68910399 | V3: 38 | W3: 0.69611677 | X3: 0.64863502 | Y3: 173.70026 | Z3: 183.52578 | AM3: C4 | AN3: 96 | AO3: 0.875 | AP3: 0.03125 | AQ3: no_evaluable | AR3: no | AS3: si | AT3: (b) mejor de la familia ols_tramos_hac: ecuacion AR1+X por periodo; unico candidato con OOS en la familia; NO CUMPLE LA REGLA (§8 y multiverso) en ninguna variable; RMSE 1.802 vs AR(4) 1.216 (peor que AR(4)) | AU3: src/v8/m0_periodos.py | AV3: (b) mejor de la familia ols_tramos_hac: ecuacion AR1+X por periodo; unico candidato con OOS en la familia | AW3: M0:AR1+X_por_periodo | AX3: si | AY3: output/v8/M0/coeficientes.csv | AZ3: =Fuera_muestra!F16 | BA3: =Fuera_muestra!G16 | BB3: =AZ3/BA3
A4: M0_compra_base_P1 | B4: M0 | C4: ols_tramos_hac | D4: compra | E4: nacional | F4: P1 | G4: d4_ln_p_tasado_real | H4: d4_ln*100 | I4: valor tasado MIVAU, real (IPC general) | J4: tipo_hip_real | K4: -2.2040111 | L4: 0.43568509 | M4: HAC-NW(4), t(32) | N4: -5.0587251 | O4: 1.6752769e-05 | P4: 0.00011115901 | Q4: BH | R4: -3.0914726 | S4: -1.3165496 | T4: -0.73447329 | V4: 38 | W4: 0.69611677 | X4: 0.64863502 | Y4: 173.70026 | Z4: 183.52578 | AM4: C4 | AN4: 96 | AO4: 0.95833333 | AP4: 0.65625 | AQ4: no_evaluable | AR4: sí | AS4: si | AT4: (b) mejor de la familia ols_tramos_hac: ecuacion AR1+X por periodo; unico candidato con OOS en la familia; NO CUMPLE LA REGLA (§8 y multiverso) en ninguna variable; RMSE 1.802 vs AR(4) 1.216 (peor que AR(4)) | AU4: src/v8/m0_periodos.py | AV4: (b) mejor de la familia ols_tramos_hac: ecuacion AR1+X por periodo; unico candidato con OOS en la familia | AW4: M0:AR1+X_por_periodo | AX4: si | AY4: output/v8/M0/coeficientes.csv | AZ4: =Fuera_muestra!F16 | BA4: =Fuera_muestra!G16 | BB4: =AZ4/BA4
A5: M0_compra_base_P1 | B5: M0 | C5: ols_tramos_hac | D5: compra | E5: nacional | F5: P1 | G5: d4_ln_p_tasado_real | H5: d4_ln*100 | I5: valor tasado MIVAU, real (IPC general) | J5: d4_credito_vivienda_real | K5: -0.086771298 | L5: 0.11049968 | M5: HAC-NW(4), t(32) | N5: -0.7852629 | O5: 0.43807508 | P5: 0.53798694 | Q5: BH | R5: -0.31185178 | S5: 0.13830918 | T5: -0.10157474 | V5: 38 | W5: 0.69611677 | X5: 0.64863502 | Y5: 173.70026 | Z5: 183.52578 | AM5: C4 | AQ5: no_evaluable | AR5: no_evaluable | AS5: si | AT5: (b) mejor de la familia ols_tramos_hac: ecuacion AR1+X por periodo; unico candidato con OOS en la familia; NO CUMPLE LA REGLA (§8 y multiverso) en ninguna variable; RMSE 1.802 vs AR(4) 1.216 (peor que AR(4)) | AU5: src/v8/m0_periodos.py | AV5: (b) mejor de la familia ols_tramos_hac: ecuacion AR1+X por periodo; unico candidato con OOS en la familia | AW5: M0:AR1+X_por_periodo | AX5: si | AY5: output/v8/M0/coeficientes.csv | AZ5: =Fuera_muestra!F16 | BA5: =Fuera_muestra!G16 | BB5: =AZ5/BA5
A6: M0_compra_base_P1 | B6: M0 | C6: ols_tramos_hac | D6: compra | E6: nacional | F6: P1 | G6: d4_ln_p_tasado_real | H6: d4_ln*100 | I6: valor tasado MIVAU, real (IPC general) | J6: d4_terminadas | K6: -0.043045333 | L6: 0.047215423 | M6: HAC-NW(4), t(32) | N6: -0.91167949 | O6: 0.36875468 | P6: 0.47801533 | Q6: BH | R6: -0.13922 | S6: 0.053129337 | T6: -0.11942732 | V6: 38 | W6: 0.69611677 | X6: 0.64863502 | Y6: 173.70026 | Z6: 183.52578 | AM6: C4 | AN6: 84 | AO6: 0.52380952 | AP6: 0.14285714 | AQ6: no_evaluable | AR6: no | AS6: si | AT6: (b) mejor de la familia ols_tramos_hac: ecuacion AR1+X por periodo; unico candidato con OOS en la familia; NO CUMPLE LA REGLA (§8 y multiverso) en ninguna variable; RMSE 1.802 vs AR(4) 1.216 (peor que AR(4)) | AU6: src/v8/m0_periodos.py | AV6: (b) mejor de la familia ols_tramos_hac: ecuacion AR1+X por periodo; unico candidato con OOS en la familia | AW6: M0:AR1+X_por_periodo | AX6: si | AY6: output/v8/M0/coeficientes.csv | AZ6: =Fuera_muestra!F16 | BA6: =Fuera_muestra!G16 | BB6: =AZ6/BA6
A7: M0_compra_base_P2 | B7: M0 | C7: ols_tramos_hac | D7: compra | E7: nacional | F7: P2 | G7: d4_ln_p_tasado_real | H7: d4_ln*100 | I7: valor tasado MIVAU, real (IPC general) | J7: d4_pob_total | K7: -1.897405 | L7: 0.54384567 | M7: HAC-NW(4), t(16) | N7: -3.4888666 | O7: 0.0030340583 | P7: 0.0084953632 | Q7: BH | R7: -3.0503063 | S7: -0.74450365 | T7: -0.41838559 | V7: 22 | W7: 0.9372564 | X7: 0.91764902 | Y7: 53.427308 | Z7: 59.973563 | AM7: C4 | AN7: 192 | AO7: 0.72916667 | AP7: 0.125 | AQ7: no | AR7: no | AS7: si | AT7: (b) mejor de la familia ols_tramos_hac: ecuacion AR1+X por periodo; unico candidato con OOS en la familia; NO CUMPLE LA REGLA (§8 y multiverso) en ninguna variable; RMSE 1.802 vs AR(4) 1.216 (peor que AR(4)) | AU7: src/v8/m0_periodos.py | AV7: (b) mejor de la familia ols_tramos_hac: ecuacion AR1+X por periodo; unico candidato con OOS en la familia | AW7: M0:AR1+X_por_periodo | AX7: si | AY7: output/v8/M0/coeficientes.csv | AZ7: =Fuera_muestra!F16 | BA7: =Fuera_muestra!G16 | BB7: =AZ7/BA7
A8: M0_compra_base_P2 | B8: M0 | C8: ols_tramos_hac | D8: compra | E8: nacional | F8: P2 | G8: d4_ln_p_tasado_real | H8: d4_ln*100 | I8: valor tasado MIVAU, real (IPC general) | J8: d4_pib_vol | K8: 1.3792567 | L8: 0.13502259 | M8: HAC-NW(4), t(16) | N8: 10.215007 | O8: 2.0414556e-08 | P8: 2.8580378e-07 | Q8: BH | R8: 1.0930216 | S8: 1.6654918 | T8: 0.87455114 | V8: 22 | W8: 0.9372564 | X8: 0.91764902 | Y8: 53.427308 | Z8: 59.973563 | AM8: C4 | AN8: 192 | AO8: 0.75 | AP8: 0.30729167 | AQ8: si | AR8: no | AS8: si | AT8: (b) mejor de la familia ols_tramos_hac: ecuacion AR1+X por periodo; unico candidato con OOS en la familia; NO CUMPLE LA REGLA (§8 y multiverso) en ninguna variable; RMSE 1.802 vs AR(4) 1.216 (peor que AR(4)) | AU8: src/v8/m0_periodos.py | AV8: (b) mejor de la familia ols_tramos_hac: ecuacion AR1+X por periodo; unico candidato con OOS en la familia | AW8: M0:AR1+X_por_periodo | AX8: si | AY8: output/v8/M0/coeficientes.csv | AZ8: =Fuera_muestra!F16 | BA8: =Fuera_muestra!G16 | BB8: =AZ8/BA8
A9: M0_compra_base_P2 | B9: M0 | C9: ols_tramos_hac | D9: compra | E9: nacional | F9: P2 | G9: d4_ln_p_tasado_real | H9: d4_ln*100 | I9: valor tasado MIVAU, real (IPC general) | J9: tipo_hip_real | K9: 1.1695795 | L9: 0.19990836 | M9: HAC-NW(4), t(16) | N9: 5.8505785 | O9: 2.4603182e-05 | P9: 0.00013247867 | Q9: BH | R9: 0.74579275 | S9: 1.5933663 | T9: 0.65363243 | V9: 22 | W9: 0.9372564 | X9: 0.91764902 | Y9: 53.427308 | Z9: 59.973563 | AM9: C4 | AN9: 192 | AO9: 0.63541667 | AP9: 0.265625 | AQ9: no | AR9: no | AS9: si | AT9: (b) mejor de la familia ols_tramos_hac: ecuacion AR1+X por periodo; unico candidato con OOS en la familia; NO CUMPLE LA REGLA (§8 y multiverso) en ninguna variable; RMSE 1.802 vs AR(4) 1.216 (peor que AR(4)) | AU9: src/v8/m0_periodos.py | AV9: (b) mejor de la familia ols_tramos_hac: ecuacion AR1+X por periodo; unico candidato con OOS en la familia | AW9: M0:AR1+X_por_periodo | AX9: si | AY9: output/v8/M0/coeficientes.csv | AZ9: =Fuera_muestra!F16 | BA9: =Fuera_muestra!G16 | BB9: =AZ9/BA9
A10: M0_compra_base_P2 | B10: M0 | C10: ols_tramos_hac | D10: compra | E10: nacional | F10: P2 | G10: d4_ln_p_tasado_real | H10: d4_ln*100 | I10: valor tasado MIVAU, real (IPC general) | J10: d4_credito_vivienda_real | K10: 0.52750169 | L10: 0.14945028 | M10: HAC-NW(4), t(16) | N10: 3.5296132 | O10: 0.0027838559 | P10: 0.0081221688 | Q10: BH | R10: 0.21068125 | S10: 0.84432214 | T10: 0.62245652 | V10: 22 | W10: 0.9372564 | X10: 0.91764902 | Y10: 53.427308 | Z10: 59.973563 | AM10: C4 | AQ10: no | AR10: no_evaluable | AS10: si | AT10: (b) mejor de la familia ols_tramos_hac: ecuacion AR1+X por periodo; unico candidato con OOS en la familia; NO CUMPLE LA REGLA (§8 y multiverso) en ninguna variable; RMSE 1.802 vs AR(4) 1.216 (peor que AR(4)) | AU10: src/v8/m0_periodos.py | AV10: (b) mejor de la familia ols_tramos_hac: ecuacion AR1+X por periodo; unico candidato con OOS en la familia | AW10: M0:AR1+X_por_periodo | AX10: si | AY10: output/v8/M0/coeficientes.csv | AZ10: =Fuera_muestra!F16 | BA10: =Fuera_muestra!G16 | BB10: =AZ10/BA10
A11: M0_compra_base_P2 | B11: M0 | C11: ols_tramos_hac | D11: compra | E11: nacional | F11: P2 | G11: d4_ln_p_tasado_real | H11: d4_ln*100 | I11: valor tasado MIVAU, real (IPC general) | J11: d4_terminadas | K11: 0.0042193887 | L11: 0.0075889186 | M11: HAC-NW(4), t(16) | N11: 0.5559934 | O11: 0.58590728 | P11: 0.66087919 | Q11: BH | R11: -0.0118684 | S11: 0.020307177 | T11: 0.028597206 | V11: 22 | W11: 0.9372564 | X11: 0.91764902 | Y11: 53.427308 | Z11: 59.973563 | AM11: C4 | AN11: 192 | AO11: 0.59375 | AP11: 0.10416667 | AQ11: no | AR11: no | AS11: si | AT11: (b) mejor de la familia ols_tramos_hac: ecuacion AR1+X por periodo; unico candidato con OOS en la familia; NO CUMPLE LA REGLA (§8 y multiverso) en ninguna variable; RMSE 1.802 vs AR(4) 1.216 (peor que AR(4)) | AU11: src/v8/m0_periodos.py | AV11: (b) mejor de la familia ols_tramos_hac: ecuacion AR1+X por periodo; unico candidato con OOS en la familia | AW11: M0:AR1+X_por_periodo | AX11: si | AY11: output/v8/M0/coeficientes.csv | AZ11: =Fuera_muestra!F16 | BA11: =Fuera_muestra!G16 | BB11: =AZ11/BA11
A12: M0_compra_base_P3 | B12: M0 | C12: ols_tramos_hac | D12: compra | E12: nacional | F12: P3 | G12: d4_ln_p_tasado_real | H12: d4_ln*100 | I12: valor tasado MIVAU, real (IPC general) | J12: d4_pob_total | K12: 4.0791809 | L12: 0.84917918 | M12: HAC-NW(4), t(18) | N12: 4.8036752 | O12: 0.00014225215 | P12: 0.00066384336 | Q12: BH | R12: 2.2951217 | S12: 5.8632402 | T12: 0.79136062 | V12: 24 | W12: 0.8902504 | X12: 0.85976439 | Y12: 55.981075 | Z12: 63.049398 | AM12: C4 | AN12: 192 | AO12: 0.71875 | AP12: 0.140625 | AQ12: no | AR12: no | AS12: si | AT12: (b) mejor de la familia ols_tramos_hac: ecuacion AR1+X por periodo; unico candidato con OOS en la familia; NO CUMPLE LA REGLA (§8 y multiverso) en ninguna variable; RMSE 1.802 vs AR(4) 1.216 (peor que AR(4)) | AU12: src/v8/m0_periodos.py | AV12: (b) mejor de la familia ols_tramos_hac: ecuacion AR1+X por periodo; unico candidato con OOS en la familia | AW12: M0:AR1+X_por_periodo | AX12: si | AY12: output/v8/M0/coeficientes.csv | AZ12: =Fuera_muestra!F16 | BA12: =Fuera_muestra!G16 | BB12: =AZ12/BA12
A13: M0_compra_base_P3 | B13: M0 | C13: ols_tramos_hac | D13: compra | E13: nacional | F13: P3 | G13: d4_ln_p_tasado_real | H13: d4_ln*100 | I13: valor tasado MIVAU, real (IPC general) | J13: d4_pib_vol | K13: 1.4539043 | L13: 0.1936462 | M13: HAC-NW(4), t(18) | N13: 7.5080445 | O13: 5.9783509e-07 | P13: 5.2310571e-06 | Q13: BH | R13: 1.0470687 | S13: 1.8607399 | T13: 0.72317695 | V13: 24 | W13: 0.8902504 | X13: 0.85976439 | Y13: 55.981075 | Z13: 63.049398 | AM13: C4 | AN13: 192 | AO13: 0.94791667 | AP13: 0.43229167 | AQ13: no | AR13: no | AS13: si | AT13: (b) mejor de la familia ols_tramos_hac: ecuacion AR1+X por periodo; unico candidato con OOS en la familia; NO CUMPLE LA REGLA (§8 y multiverso) en ninguna variable; RMSE 1.802 vs AR(4) 1.216 (peor que AR(4)) | AU13: src/v8/m0_periodos.py | AV13: (b) mejor de la familia ols_tramos_hac: ecuacion AR1+X por periodo; unico candidato con OOS en la familia | AW13: M0:AR1+X_por_periodo | AX13: si | AY13: output/v8/M0/coeficientes.csv | AZ13: =Fuera_muestra!F16 | BA13: =Fuera_muestra!G16 | BB13: =AZ13/BA13
A14: M0_compra_base_P3 | B14: M0 | C14: ols_tramos_hac | D14: compra | E14: nacional | F14: P3 | G14: d4_ln_p_tasado_real | H14: d4_ln*100 | I14: valor tasado MIVAU, real (IPC general) | J14: tipo_hip_real | K14: 0.21910839 | L14: 0.16985097 | M14: HAC-NW(4), t(18) | N14: 1.2900038 | O14: 0.213377 | P14: 0.30482429 | Q14: BH | R14: -0.13773525 | S14: 0.57595203 | T14: 0.15358176 | V14: 24 | W14: 0.8902504 | X14: 0.85976439 | Y14: 55.981075 | Z14: 63.049398 | AM14: C4 | AN14: 192 | AO14: 0.78125 | AP14: 0.19270833 | AQ14: no | AR14: no | AS14: si | AT14: (b) mejor de la familia ols_tramos_hac: ecuacion AR1+X por periodo; unico candidato con OOS en la familia; NO CUMPLE LA REGLA (§8 y multiverso) en ninguna variable; RMSE 1.802 vs AR(4) 1.216 (peor que AR(4)) | AU14: src/v8/m0_periodos.py | AV14: (b) mejor de la familia ols_tramos_hac: ecuacion AR1+X por periodo; unico candidato con OOS en la familia | AW14: M0:AR1+X_por_periodo | AX14: si | AY14: output/v8/M0/coeficientes.csv | AZ14: =Fuera_muestra!F16 | BA14: =Fuera_muestra!G16 | BB14: =AZ14/BA14
A15: M0_compra_base_P3 | B15: M0 | C15: ols_tramos_hac | D15: compra | E15: nacional | F15: P3 | G15: d4_ln_p_tasado_real | H15: d4_ln*100 | I15: valor tasado MIVAU, real (IPC general) | J15: d4_credito_vivienda_real | K15: 0.28219487 | L15: 0.20801528 | M15: HAC-NW(4), t(18) | N15: 1.3566065 | O15: 0.19167832 | P15: 0.28547835 | Q15: BH | R15: -0.15482901 | S15: 0.71921875 | T15: 0.16327856 | V15: 24 | W15: 0.8902504 | X15: 0.85976439 | Y15: 55.981075 | Z15: 63.049398 | AM15: C4 | AQ15: no | AR15: no_evaluable | AS15: si | AT15: (b) mejor de la familia ols_tramos_hac: ecuacion AR1+X por periodo; unico candidato con OOS en la familia; NO CUMPLE LA REGLA (§8 y multiverso) en ninguna variable; RMSE 1.802 vs AR(4) 1.216 (peor que AR(4)) | AU15: src/v8/m0_periodos.py | AV15: (b) mejor de la familia ols_tramos_hac: ecuacion AR1+X por periodo; unico candidato con OOS en la familia | AW15: M0:AR1+X_por_periodo | AX15: si | AY15: output/v8/M0/coeficientes.csv | AZ15: =Fuera_muestra!F16 | BA15: =Fuera_muestra!G16 | BB15: =AZ15/BA15
A16: M0_compra_base_P3 | B16: M0 | C16: ols_tramos_hac | D16: compra | E16: nacional | F16: P3 | G16: d4_ln_p_tasado_real | H16: d4_ln*100 | I16: valor tasado MIVAU, real (IPC general) | J16: d4_terminadas | K16: -0.013674199 | L16: 0.0086162836 | M16: HAC-NW(4), t(18) | N16: -1.5870183 | O16: 0.12991913 | P16: 0.21149626 | Q16: BH | R16: -0.03177634 | S16: 0.0044279407 | T16: -0.17565484 | V16: 24 | W16: 0.8902504 | X16: 0.85976439 | Y16: 55.981075 | Z16: 63.049398 | AM16: C4 | AN16: 192 | AO16: 0.57291667 | AP16: 0.1875 | AQ16: no | AR16: no | AS16: si | AT16: (b) mejor de la familia ols_tramos_hac: ecuacion AR1+X por periodo; unico candidato con OOS en la familia; NO CUMPLE LA REGLA (§8 y multiverso) en ninguna variable; RMSE 1.802 vs AR(4) 1.216 (peor que AR(4)) | AU16: src/v8/m0_periodos.py | AV16: (b) mejor de la familia ols_tramos_hac: ecuacion AR1+X por periodo; unico candidato con OOS en la familia | AW16: M0:AR1+X_por_periodo | AX16: si | AY16: output/v8/M0/coeficientes.csv | AZ16: =Fuera_muestra!F16 | BA16: =Fuera_muestra!G16 | BB16: =AZ16/BA16
A17: M0_compra_base_P4 | B17: M0 | C17: ols_tramos_hac | D17: compra | E17: nacional | F17: P4 | G17: d4_ln_p_tasado_real | H17: d4_ln*100 | I17: valor tasado MIVAU, real (IPC general) | J17: d4_pob_total | K17: 0.19554702 | L17: 3.094337 | M17: HAC-NW(4), t(3) | N17: 0.063195126 | O17: 0.95358611 | P17: 0.95358611 | Q17: BH | R17: -9.6520144 | S17: 10.043108 | T17: 0.054769703 | V17: 9 | W17: 0.89261072 | X17: 0.71362859 | Y17: 14.15451 | Z17: 15.337857 | AM17: C4 | AN17: 240 | AO17: 0.66666667 | AP17: 0.24166667 | AQ17: no | AR17: no | AS17: si | AT17: (b) mejor de la familia ols_tramos_hac: ecuacion AR1+X por periodo; unico candidato con OOS en la familia; NO CUMPLE LA REGLA (§8 y multiverso) en ninguna variable; RMSE 1.802 vs AR(4) 1.216 (peor que AR(4)) | AU17: src/v8/m0_periodos.py | AV17: (b) mejor de la familia ols_tramos_hac: ecuacion AR1+X por periodo; unico candidato con OOS en la familia | AW17: M0:AR1+X_por_periodo | AX17: si | AY17: output/v8/M0/coeficientes.csv | AZ17: =Fuera_muestra!F16 | BA17: =Fuera_muestra!G16 | BB17: =AZ17/BA17
A18: M0_compra_base_P4 | B18: M0 | C18: ols_tramos_hac | D18: compra | E18: nacional | F18: P4 | G18: d4_ln_p_tasado_real | H18: d4_ln*100 | I18: valor tasado MIVAU, real (IPC general) | J18: d4_pib_vol | K18: -0.14704456 | L18: 0.028814289 | M18: HAC-NW(4), t(3) | N18: -5.1031822 | O18: 0.014552864 | P18: 0.035127602 | Q18: BH | R18: -0.23874449 | S18: -0.055344638 | T18: -2.0955713 | V18: 9 | W18: 0.89261072 | X18: 0.71362859 | Y18: 14.15451 | Z18: 15.337857 | AM18: C4 | AN18: 240 | AO18: 0.525 | AP18: 0.2625 | AQ18: no | AR18: no | AS18: si | AT18: (b) mejor de la familia ols_tramos_hac: ecuacion AR1+X por periodo; unico candidato con OOS en la familia; NO CUMPLE LA REGLA (§8 y multiverso) en ninguna variable; RMSE 1.802 vs AR(4) 1.216 (peor que AR(4)) | AU18: src/v8/m0_periodos.py | AV18: (b) mejor de la familia ols_tramos_hac: ecuacion AR1+X por periodo; unico candidato con OOS en la familia | AW18: M0:AR1+X_por_periodo | AX18: si | AY18: output/v8/M0/coeficientes.csv | AZ18: =Fuera_muestra!F16 | BA18: =Fuera_muestra!G16 | BB18: =AZ18/BA18
A19: M0_compra_base_P4 | B19: M0 | C19: ols_tramos_hac | D19: compra | E19: nacional | F19: P4 | G19: d4_ln_p_tasado_real | H19: d4_ln*100 | I19: valor tasado MIVAU, real (IPC general) | J19: tipo_hip_real | K19: -1.4423387 | L19: 0.88310688 | M19: HAC-NW(4), t(3) | N19: -1.633255 | O19: 0.20092229 | P19: 0.29301167 | Q19: BH | R19: -4.252779 | S19: 1.3681015 | T19: -6.0423175 | V19: 9 | W19: 0.89261072 | X19: 0.71362859 | Y19: 14.15451 | Z19: 15.337857 | AM19: C4 | AN19: 240 | AO19: 0.525 | AP19: 0.225 | AQ19: no | AR19: no | AS19: si | AT19: (b) mejor de la familia ols_tramos_hac: ecuacion AR1+X por periodo; unico candidato con OOS en la familia; NO CUMPLE LA REGLA (§8 y multiverso) en ninguna variable; RMSE 1.802 vs AR(4) 1.216 (peor que AR(4)) | AU19: src/v8/m0_periodos.py | AV19: (b) mejor de la familia ols_tramos_hac: ecuacion AR1+X por periodo; unico candidato con OOS en la familia | AW19: M0:AR1+X_por_periodo | AX19: si | AY19: output/v8/M0/coeficientes.csv | AZ19: =Fuera_muestra!F16 | BA19: =Fuera_muestra!G16 | BB19: =AZ19/BA19
A20: M0_compra_base_P4 | B20: M0 | C20: ols_tramos_hac | D20: compra | E20: nacional | F20: P4 | G20: d4_ln_p_tasado_real | H20: d4_ln*100 | I20: valor tasado MIVAU, real (IPC general) | J20: d4_credito_vivienda_real | K20: 1.7856297 | L20: 1.2107281 | M20: HAC-NW(4), t(3) | N20: 1.4748395 | O20: 0.23671084 | P20: 0.32394163 | Q20: BH | R20: -2.0674476 | S20: 5.638707 | T20: 4.9513316 | V20: 9 | W20: 0.89261072 | X20: 0.71362859 | Y20: 14.15451 | Z20: 15.337857 | AM20: C4 | AQ20: no | AR20: no_evaluable | AS20: si | AT20: (b) mejor de la familia ols_tramos_hac: ecuacion AR1+X por periodo; unico candidato con OOS en la familia; NO CUMPLE LA REGLA (§8 y multiverso) en ninguna variable; RMSE 1.802 vs AR(4) 1.216 (peor que AR(4)) | AU20: src/v8/m0_periodos.py | AV20: (b) mejor de la familia ols_tramos_hac: ecuacion AR1+X por periodo; unico candidato con OOS en la familia | AW20: M0:AR1+X_por_periodo | AX20: si | AY20: output/v8/M0/coeficientes.csv | AZ20: =Fuera_muestra!F16 | BA20: =Fuera_muestra!G16 | BB20: =AZ20/BA20
A21: M0_compra_base_P4 | B21: M0 | C21: ols_tramos_hac | D21: compra | E21: nacional | F21: P4 | G21: d4_ln_p_tasado_real | H21: d4_ln*100 | I21: valor tasado MIVAU, real (IPC general) | J21: d4_terminadas | K21: 0.065167699 | L21: 0.018470034 | M21: HAC-NW(4), t(3) | N21: 3.5282935 | O21: 0.038686491 | P21: 0.079648658 | Q21: BH | R21: 0.0063878085 | S21: 0.12394759 | T21: 1.3022608 | V21: 9 | W21: 0.89261072 | X21: 0.71362859 | Y21: 14.15451 | Z21: 15.337857 | AM21: C4 | AN21: 240 | AO21: 0.61666667 | AP21: 0.11666667 | AQ21: si | AR21: no | AS21: si | AT21: (b) mejor de la familia ols_tramos_hac: ecuacion AR1+X por periodo; unico candidato con OOS en la familia; NO CUMPLE LA REGLA (§8 y multiverso) en ninguna variable; RMSE 1.802 vs AR(4) 1.216 (peor que AR(4)) | AU21: src/v8/m0_periodos.py | AV21: (b) mejor de la familia ols_tramos_hac: ecuacion AR1+X por periodo; unico candidato con OOS en la familia | AW21: M0:AR1+X_por_periodo | AX21: si | AY21: output/v8/M0/coeficientes.csv | AZ21: =Fuera_muestra!F16 | BA21: =Fuera_muestra!G16 | BB21: =AZ21/BA21
A22: M0_compra_base_P5 | B22: M0 | C22: ols_tramos_hac | D22: compra | E22: nacional | F22: P5 | G22: d4_ln_p_tasado_real | H22: d4_ln*100 | I22: valor tasado MIVAU, real (IPC general) | J22: d4_pob_total | K22: -10.182187 | L22: 2.0248415 | M22: HAC-NW(4), t(10) | N22: -5.028634 | O22: 0.00051515768 | P22: 0.0018979493 | Q22: BH | R22: -14.693815 | S22: -5.6705588 | T22: -0.20573425 | V22: 16 | W22: 0.98349136 | X22: 0.97523704 | Y22: 40.195018 | Z22: 44.830551 | AM22: C4 | AN22: 192 | AO22: 0.59375 | AP22: 0.19791667 | AQ22: no | AR22: no | AS22: si | AT22: (b) mejor de la familia ols_tramos_hac: ecuacion AR1+X por periodo; unico candidato con OOS en la familia; NO CUMPLE LA REGLA (§8 y multiverso) en ninguna variable; RMSE 1.802 vs AR(4) 1.216 (peor que AR(4)) | AU22: src/v8/m0_periodos.py | AV22: (b) mejor de la familia ols_tramos_hac: ecuacion AR1+X por periodo; unico candidato con OOS en la familia | AW22: M0:AR1+X_por_periodo | AX22: si | AY22: output/v8/M0/coeficientes.csv | AZ22: =Fuera_muestra!F16 | BA22: =Fuera_muestra!G16 | BB22: =AZ22/BA22
A23: M0_compra_base_P5 | B23: M0 | C23: ols_tramos_hac | D23: compra | E23: nacional | F23: P5 | G23: d4_ln_p_tasado_real | H23: d4_ln*100 | I23: valor tasado MIVAU, real (IPC general) | J23: d4_pib_vol | K23: -1.155329 | L23: 0.26917651 | M23: HAC-NW(4), t(10) | N23: -4.2920869 | O23: 0.0015810058 | P23: 0.0050304731 | Q23: BH | R23: -1.7550916 | S23: -0.55556633 | T23: -0.27151887 | V23: 16 | W23: 0.98349136 | X23: 0.97523704 | Y23: 40.195018 | Z23: 44.830551 | AM23: C4 | AN23: 192 | AO23: 0.85416667 | AP23: 0.28645833 | AQ23: no | AR23: no | AS23: si | AT23: (b) mejor de la familia ols_tramos_hac: ecuacion AR1+X por periodo; unico candidato con OOS en la familia; NO CUMPLE LA REGLA (§8 y multiverso) en ninguna variable; RMSE 1.802 vs AR(4) 1.216 (peor que AR(4)) | AU23: src/v8/m0_periodos.py | AV23: (b) mejor de la familia ols_tramos_hac: ecuacion AR1+X por periodo; unico candidato con OOS en la familia | AW23: M0:AR1+X_por_periodo | AX23: si | AY23: output/v8/M0/coeficientes.csv | AZ23: =Fuera_muestra!F16 | BA23: =Fuera_muestra!G16 | BB23: =AZ23/BA23
A24: M0_compra_base_P5 | B24: M0 | C24: ols_tramos_hac | D24: compra | E24: nacional | F24: P5 | G24: d4_ln_p_tasado_real | H24: d4_ln*100 | I24: valor tasado MIVAU, real (IPC general) | J24: tipo_hip_real | K24: 0.19636616 | L24: 0.12653838 | M24: HAC-NW(4), t(10) | N24: 1.5518308 | O24: 0.15174994 | P24: 0.23605547 | Q24: BH | R24: -0.085578918 | S24: 0.47831123 | T24: 0.09430851 | V24: 16 | W24: 0.98349136 | X24: 0.97523704 | Y24: 40.195018 | Z24: 44.830551 | AM24: C4 | AN24: 192 | AO24: 0.875 | AP24: 0.5 | AQ24: no | AR24: sí | AS24: si | AT24: (b) mejor de la familia ols_tramos_hac: ecuacion AR1+X por periodo; unico candidato con OOS en la familia; NO CUMPLE LA REGLA (§8 y multiverso) en ninguna variable; RMSE 1.802 vs AR(4) 1.216 (peor que AR(4)) | AU24: src/v8/m0_periodos.py | AV24: (b) mejor de la familia ols_tramos_hac: ecuacion AR1+X por periodo; unico candidato con OOS en la familia | AW24: M0:AR1+X_por_periodo | AX24: si | AY24: output/v8/M0/coeficientes.csv | AZ24: =Fuera_muestra!F16 | BA24: =Fuera_muestra!G16 | BB24: =AZ24/BA24
A25: M0_compra_base_P5 | B25: M0 | C25: ols_tramos_hac | D25: compra | E25: nacional | F25: P5 | G25: d4_ln_p_tasado_real | H25: d4_ln*100 | I25: valor tasado MIVAU, real (IPC general) | J25: d4_credito_vivienda_real | K25: 1.0467998 | L25: 0.080231014 | M25: HAC-NW(4), t(10) | N25: 13.047322 | O25: 1.3250259e-07 | P25: 1.5458635e-06 | Q25: BH | R25: 0.86803399 | S25: 1.2255657 | T25: 0.72656099 | V25: 16 | W25: 0.98349136 | X25: 0.97523704 | Y25: 40.195018 | Z25: 44.830551 | AM25: C4 | AQ25: no | AR25: no_evaluable | AS25: si | AT25: (b) mejor de la familia ols_tramos_hac: ecuacion AR1+X por periodo; unico candidato con OOS en la familia; NO CUMPLE LA REGLA (§8 y multiverso) en ninguna variable; RMSE 1.802 vs AR(4) 1.216 (peor que AR(4)) | AU25: src/v8/m0_periodos.py | AV25: (b) mejor de la familia ols_tramos_hac: ecuacion AR1+X por periodo; unico candidato con OOS en la familia | AW25: M0:AR1+X_por_periodo | AX25: si | AY25: output/v8/M0/coeficientes.csv | AZ25: =Fuera_muestra!F16 | BA25: =Fuera_muestra!G16 | BB25: =AZ25/BA25
A26: M0_compra_base_P5 | B26: M0 | C26: ols_tramos_hac | D26: compra | E26: nacional | F26: P5 | G26: d4_ln_p_tasado_real | H26: d4_ln*100 | I26: valor tasado MIVAU, real (IPC general) | J26: d4_terminadas | K26: -0.0059417541 | L26: 0.016916515 | M26: HAC-NW(4), t(10) | N26: -0.35123985 | O26: 0.73269609 | P26: 0.77710191 | Q26: BH | R26: -0.043634097 | S26: 0.031750589 | T26: -0.010223354 | V26: 16 | W26: 0.98349136 | X26: 0.97523704 | Y26: 40.195018 | Z26: 44.830551 | AM26: C4 | AN26: 192 | AO26: 0.52083333 | AP26: 0.098958333 | AQ26: no | AR26: no | AS26: si | AT26: (b) mejor de la familia ols_tramos_hac: ecuacion AR1+X por periodo; unico candidato con OOS en la familia; NO CUMPLE LA REGLA (§8 y multiverso) en ninguna variable; RMSE 1.802 vs AR(4) 1.216 (peor que AR(4)) | AU26: src/v8/m0_periodos.py | AV26: (b) mejor de la familia ols_tramos_hac: ecuacion AR1+X por periodo; unico candidato con OOS en la familia | AW26: M0:AR1+X_por_periodo | AX26: si | AY26: output/v8/M0/coeficientes.csv | AZ26: =Fuera_muestra!F16 | BA26: =Fuera_muestra!G16 | BB26: =AZ26/BA26
A27: M4_compra_C1_sin_rupturas_ardl | B27: M4 | C27: ardl_bounds_uecm | D27: compra | E27: nacional | F27: completo | G27: ln_p_tasado_real | H27: ln niveles; tipo en pp | I27: valor tasado MIVAU, real (IPC general) | J27: renta | K27: -0.69059925 | L27: 1.2340515 | M27: delta (OLS clasico) | N27: -0.55961949 | O27: 0.57573901 | P27: 0.74059734 | Q27: BH | R27: -3.1093401 | S27: 1.7281416 | T27: -0.44808162 | U27: -0.69059925 | V27: 113 | W27: 0.31575678 | X27: 0.27702603 | Y27: -582.91065 | Z27: -563.81894 | AA27: -0.017257219 | AB27: 39.818057 | AC27: 0.1 | AD27: 1.6662665e-18 | AE27: 0.034617396 | AF27: 0.32078518 | AG27: 0.21544114 | AH27: 1 | AI27: 1.2670878 | AM27: C4 | AQ27: no_evaluable | AR27: no_evaluable | AS27: si | AT27: (b) mejor de la familia dols/fmols/ardl: especificacion C1 de menor RMSE (ECM); el OOS se hace con beta OLS estatico y es comun a los tres estimadores; NO CUMPLE LA REGLA (§8 y multiverso) en ninguna variable; RMSE 1.407 vs AR(4) 1.283 (peor que AR(4)) | AU27: src/v8/m4_largo_plazo.py | AV27: (b) mejor de la familia dols/fmols/ardl: especificacion C1 de menor RMSE (ECM); el OOS se hace con beta OLS estatico y es comun a los tres estimadores | AW27: M4:C1_sin_rupturas_ECM | AX27: si | AY27: output/v8/M4/coeficientes.csv | AZ27: =Fuera_muestra!F22 | BA27: =Fuera_muestra!G22 | BB27: =AZ27/BA27
A28: M4_compra_C1_sin_rupturas_ardl | B28: M4 | C28: ardl_bounds_uecm | D28: compra | E28: nacional | F28: completo | G28: ln_p_tasado_real | H28: ln niveles; tipo en pp | I28: valor tasado MIVAU, real (IPC general) | J28: tipo | K28: 0.00065753919 | L28: 0.057032015 | M28: delta (OLS clasico) | N28: 0.0115293 | O28: 0.99080115 | P28: 0.99189545 | Q28: BH | R28: -0.11112521 | S28: 0.11244029 | T28: 0.0069807824 | V28: 113 | W28: 0.31575678 | X28: 0.27702603 | Y28: -582.91065 | Z28: -563.81894 | AA28: -0.017257219 | AB28: 39.818057 | AC28: 0.1 | AD28: 1.6662665e-18 | AE28: 0.034617396 | AF28: 0.32078518 | AG28: 0.21544114 | AH28: 1 | AI28: 1.2670878 | AM28: C4 | AQ28: no_evaluable | AR28: no_evaluable | AS28: si | AT28: (b) mejor de la familia dols/fmols/ardl: especificacion C1 de menor RMSE (ECM); el OOS se hace con beta OLS estatico y es comun a los tres estimadores; NO CUMPLE LA REGLA (§8 y multiverso) en ninguna variable; RMSE 1.407 vs AR(4) 1.283 (peor que AR(4)) | AU28: src/v8/m4_largo_plazo.py | AV28: (b) mejor de la familia dols/fmols/ardl: especificacion C1 de menor RMSE (ECM); el OOS se hace con beta OLS estatico y es comun a los tres estimadores | AW28: M4:C1_sin_rupturas_ECM | AX28: si | AY28: output/v8/M4/coeficientes.csv | AZ28: =Fuera_muestra!F22 | BA28: =Fuera_muestra!G22 | BB28: =AZ28/BA28
A29: M4_compra_C1_sin_rupturas_dols | B29: M4 | C29: dols | D29: compra | E29: nacional | F29: completo | G29: ln_p_tasado_real | H29: ln niveles; tipo en pp | I29: valor tasado MIVAU, real (IPC general) | J29: renta | K29: 0.68815749 | L29: 0.30112114 | M29: HAC-NW(4) | N29: 2.2853177 | O29: 0.022294204 | P29: 0.063974671 | Q29: BH | R29: 0.097970893 | S29: 1.2783441 | T29: 0.44649733 | U29: 0.68815749 | V29: 113 | W29: 0.20013756 | X29: 0.13860968 | Y29: -65.141199 | Z29: -40.594708 | AA29: -0.016358797 | AB29: 42.023998 | AC29: 0.62515886 | AD29: 1.1307661e-72 | AE29: 0.80967642 | AF29: 0.00031753395 | AG29: 3.4334947e-08 | AH29: 0 | AI29: 1.2670878 | AM29: C4 | AQ29: no_evaluable | AR29: no_evaluable | AS29: si | AT29: (b) mejor de la familia dols/fmols/ardl: especificacion C1 de menor RMSE (ECM); el OOS se hace con beta OLS estatico y es comun a los tres estimadores; NO CUMPLE LA REGLA (§8 y multiverso) en ninguna variable; RMSE 1.407 vs AR(4) 1.283 (peor que AR(4)) | AU29: src/v8/m4_largo_plazo.py | AV29: (b) mejor de la familia dols/fmols/ardl: especificacion C1 de menor RMSE (ECM); el OOS se hace con beta OLS estatico y es comun a los tres estimadores | AW29: M4:C1_sin_rupturas_ECM | AX29: si | AY29: output/v8/M4/coeficientes.csv | AZ29: =Fuera_muestra!F22 | BA29: =Fuera_muestra!G22 | BB29: =AZ29/BA29
A30: M4_compra_C1_sin_rupturas_dols | B30: M4 | C30: dols | D30: compra | E30: nacional | F30: completo | G30: ln_p_tasado_real | H30: ln niveles; tipo en pp | I30: valor tasado MIVAU, real (IPC general) | J30: tipo | K30: 0.0059963734 | L30: 0.019582482 | M30: HAC-NW(4) | N30: 0.3062111 | O30: 0.75944392 | P30: 0.8553464 | Q30: BH | R30: -0.032384587 | S30: 0.044377334 | T30: 0.063660659 | V30: 113 | W30: 0.20013756 | X30: 0.13860968 | Y30: -65.141199 | Z30: -40.594708 | AA30: -0.016358797 | AB30: 42.023998 | AC30: 0.62515886 | AD30: 1.1307661e-72 | AE30: 0.80967642 | AF30: 0.00031753395 | AG30: 3.4334947e-08 | AH30: 0 | AI30: 1.2670878 | AM30: C4 | AQ30: no_evaluable | AR30: no_evaluable | AS30: si | AT30: (b) mejor de la familia dols/fmols/ardl: especificacion C1 de menor RMSE (ECM); el OOS se hace con beta OLS estatico y es comun a los tres estimadores; NO CUMPLE LA REGLA (§8 y multiverso) en ninguna variable; RMSE 1.407 vs AR(4) 1.283 (peor que AR(4)) | AU30: src/v8/m4_largo_plazo.py | AV30: (b) mejor de la familia dols/fmols/ardl: especificacion C1 de menor RMSE (ECM); el OOS se hace con beta OLS estatico y es comun a los tres estimadores | AW30: M4:C1_sin_rupturas_ECM | AX30: si | AY30: output/v8/M4/coeficientes.csv | AZ30: =Fuera_muestra!F22 | BA30: =Fuera_muestra!G22 | BB30: =AZ30/BA30
A31: M4_compra_C1_sin_rupturas_fmols | B31: M4 | C31: fmols | D31: compra | E31: nacional | F31: completo | G31: ln_p_tasado_real | H31: ln niveles; tipo en pp | I31: valor tasado MIVAU, real (IPC general) | J31: renta | K31: 0.61837276 | L31: 0.3257678 | M31: FMOLS Omega_u.e (Bartlett) | N31: 1.898201 | O31: 0.057669612 | P31: 0.13782796 | Q31: BH | R31: -0.020132131 | S31: 1.2568777 | T31: 0.4012189 | U31: 0.61837276 | V31: 112 | W31: 0.1572982 | X31: 0.14183578 | Y31: -392.50463 | Z31: -384.34913 | AA31: -0.016724123 | AB31: 41.098403 | AC31: 0.62515886 | AD31: 6.6502279e-81 | AE31: 0.37435497 | AF31: 0.00053782407 | AG31: 0.019327627 | AH31: 0 | AI31: 1.2670878 | AM31: C4 | AQ31: no_evaluable | AR31: no_evaluable | AS31: si | AT31: (b) mejor de la familia dols/fmols/ardl: especificacion C1 de menor RMSE (ECM); el OOS se hace con beta OLS estatico y es comun a los tres estimadores; NO CUMPLE LA REGLA (§8 y multiverso) en ninguna variable; RMSE 1.407 vs AR(4) 1.283 (peor que AR(4)) | AU31: src/v8/m4_largo_plazo.py | AV31: (b) mejor de la familia dols/fmols/ardl: especificacion C1 de menor RMSE (ECM); el OOS se hace con beta OLS estatico y es comun a los tres estimadores | AW31: M4:C1_sin_rupturas_ECM | AX31: si | AY31: output/v8/M4/coeficientes.csv | AZ31: =Fuera_muestra!F22 | BA31: =Fuera_muestra!G22 | BB31: =AZ31/BA31
A32: M4_compra_C1_sin_rupturas_fmols | B32: M4 | C32: fmols | D32: compra | E32: nacional | F32: completo | G32: ln_p_tasado_real | H32: ln niveles; tipo en pp | I32: valor tasado MIVAU, real (IPC general) | J32: tipo | K32: 0.0040101428 | L32: 0.019564575 | M32: FMOLS Omega_u.e (Bartlett) | N32: 0.20496959 | O32: 0.83759589 | P32: 0.90479941 | Q32: BH | R32: -0.034336424 | S32: 0.04235671 | T32: 0.042573789 | V32: 112 | W32: 0.1572982 | X32: 0.14183578 | Y32: -392.50463 | Z32: -384.34913 | AA32: -0.016724123 | AB32: 41.098403 | AC32: 0.62515886 | AD32: 6.6502279e-81 | AE32: 0.37435497 | AF32: 0.00053782407 | AG32: 0.019327627 | AH32: 0 | AI32: 1.2670878 | AM32: C4 | AQ32: no_evaluable | AR32: no_evaluable | AS32: si | AT32: (b) mejor de la familia dols/fmols/ardl: especificacion C1 de menor RMSE (ECM); el OOS se hace con beta OLS estatico y es comun a los tres estimadores; NO CUMPLE LA REGLA (§8 y multiverso) en ninguna variable; RMSE 1.407 vs AR(4) 1.283 (peor que AR(4)) | AU32: src/v8/m4_largo_plazo.py | AV32: (b) mejor de la familia dols/fmols/ardl: especificacion C1 de menor RMSE (ECM); el OOS se hace con beta OLS estatico y es comun a los tres estimadores | AW32: M4:C1_sin_rupturas_ECM | AX32: si | AY32: output/v8/M4/coeficientes.csv | AZ32: =Fuera_muestra!F22 | BA32: =Fuera_muestra!G22 | BB32: =AZ32/BA32
A33: M6_ols_compra_trimestral_completo | B33: M6 | C33: ols_familias | D33: compra | E33: nacional | F33: completo | G33: d_ln_tasado_real | H33: trimestral | I33: tasado | J33: const | K33: -0.70338909 | L33: 0.47222358 | M33: EWC | N33: -1.4895256 | O33: 0.17467738 | P33: 0.29360667 | Q33: BH | R33: -1.7923386 | S33: 0.38556043 | V33: 96 | W33: 0.46568303 | X33: 0.42318055 | Y33: 361.168 | Z33: 381.68278 | AD33: 1.1624361e-09 | AE33: 0.027089553 | AF33: 0.0063835048 | AG33: 0.17232653 | AH33: 0 | AI33: 1.1057624 | AM33: C4 | AQ33: no_evaluable | AR33: no_evaluable | AS33: si | AT33: (b) mejor de la familia ols_familias: ols_factores trimestral, periodo completo; NO CUMPLE LA REGLA (§8 y multiverso) en ninguna variable; RMSE 2.830 vs AR(4) 1.038 (peor que AR(4)) | AU33: src/v8/m6_colinealidad.py | AV33: (b) mejor de la familia ols_familias: ols_factores trimestral, periodo completo | AW33: M6:ols_factores | AX33: si | AY33: output/v8/M6/coeficientes.csv | AZ33: =Fuera_muestra!F49 | BA33: =Fuera_muestra!G49 | BB33: =AZ33/BA33
A34: M6_ols_compra_trimestral_completo | B34: M6 | C34: ols_familias | D34: compra | E34: nacional | F34: completo | G34: d_ln_tasado_real | H34: trimestral | I34: tasado | J34: hogares_epa | K34: 1.9795045 | L34: 1.0987707 | M34: EWC | N34: 1.8015628 | O34: 0.10929162 | P34: 0.20557234 | Q34: BH | R34: -0.55426535 | S34: 4.5132744 | T34: 0.27764163 | U34: 1.9795045 | V34: 96 | W34: 0.46568303 | X34: 0.42318055 | Y34: 361.168 | Z34: 381.68278 | AD34: 1.1624361e-09 | AE34: 0.027089553 | AF34: 0.0063835048 | AG34: 0.17232653 | AH34: 0 | AI34: 1.1057624 | AM34: C4 | AN34: 1152 | AO34: 0.72222222 | AP34: 0.2109375 | AQ34: no_evaluable | AR34: no | AS34: si | AT34: (b) mejor de la familia ols_familias: ols_factores trimestral, periodo completo; NO CUMPLE LA REGLA (§8 y multiverso) en ninguna variable; RMSE 2.830 vs AR(4) 1.038 (peor que AR(4)) | AU34: src/v8/m6_colinealidad.py | AV34: (b) mejor de la familia ols_familias: ols_factores trimestral, periodo completo | AW34: M6:ols_factores | AX34: si | AY34: output/v8/M6/coeficientes.csv | AZ34: =Fuera_muestra!F49 | BA34: =Fuera_muestra!G49 | BB34: =AZ34/BA34
A35: M6_ols_compra_trimestral_completo | B35: M6 | C35: ols_familias | D35: compra | E35: nacional | F35: completo | G35: d_ln_tasado_real | H35: trimestral | I35: tasado | J35: pib_vol | K35: 0.080293891 | L35: 0.030005919 | M35: EWC | N35: 2.6759351 | O35: 0.028102498 | P35: 0.076295772 | Q35: BH | R35: 0.011100118 | S35: 0.14948766 | T35: 0.10718294 | U35: 0.080293891 | V35: 96 | W35: 0.46568303 | X35: 0.42318055 | Y35: 361.168 | Z35: 381.68278 | AD35: 1.1624361e-09 | AE35: 0.027089553 | AF35: 0.0063835048 | AG35: 0.17232653 | AH35: 0 | AI35: 1.1057624 | AM35: C4 | AN35: 1152 | AO35: 0.88715278 | AP35: 0.22395833 | AQ35: no_evaluable | AR35: no | AS35: si | AT35: (b) mejor de la familia ols_familias: ols_factores trimestral, periodo completo; NO CUMPLE LA REGLA (§8 y multiverso) en ninguna variable; RMSE 2.830 vs AR(4) 1.038 (peor que AR(4)) | AU35: src/v8/m6_colinealidad.py | AV35: (b) mejor de la familia ols_familias: ols_factores trimestral, periodo completo | AW35: M6:ols_factores | AX35: si | AY35: output/v8/M6/coeficientes.csv | AZ35: =Fuera_muestra!F49 | BA35: =Fuera_muestra!G49 | BB35: =AZ35/BA35
A36: M6_ols_compra_trimestral_completo | B36: M6 | C36: ols_familias | D36: compra | E36: nacional | F36: completo | G36: d_ln_tasado_real | H36: trimestral | I36: tasado | J36: tipo_hip_real | K36: -0.032704484 | L36: 0.093515867 | M36: EWC | N36: -0.34972123 | O36: 0.73557599 | P36: 0.7960343 | Q36: BH | R36: -0.24835246 | S36: 0.18294349 | T36: -0.032546979 | V36: 96 | W36: 0.46568303 | X36: 0.42318055 | Y36: 361.168 | Z36: 381.68278 | AD36: 1.1624361e-09 | AE36: 0.027089553 | AF36: 0.0063835048 | AG36: 0.17232653 | AH36: 0 | AI36: 1.1057624 | AM36: C4 | AN36: 1152 | AO36: 0.75520833 | AP36: 0.36371528 | AQ36: no_evaluable | AR36: no | AS36: si | AT36: (b) mejor de la familia ols_familias: ols_factores trimestral, periodo completo; NO CUMPLE LA REGLA (§8 y multiverso) en ninguna variable; RMSE 2.830 vs AR(4) 1.038 (peor que AR(4)) | AU36: src/v8/m6_colinealidad.py | AV36: (b) mejor de la familia ols_familias: ols_factores trimestral, periodo completo | AW36: M6:ols_factores | AX36: si | AY36: output/v8/M6/coeficientes.csv | AZ36: =Fuera_muestra!F49 | BA36: =Fuera_muestra!G49 | BB36: =AZ36/BA36
A37: M6_ols_compra_trimestral_completo | B37: M6 | C37: ols_familias | D37: compra | E37: nacional | F37: completo | G37: d_ln_tasado_real | H37: trimestral | I37: tasado | J37: terminadas | K37: 0.0048216501 | L37: 0.0086248354 | M37: EWC | N37: 0.55904256 | O37: 0.5914339 | P37: 0.69736236 | Q37: BH | R37: -0.015067256 | S37: 0.024710556 | T37: 0.04191819 | U37: 0.0048216501 | V37: 96 | W37: 0.46568303 | X37: 0.42318055 | Y37: 361.168 | Z37: 381.68278 | AD37: 1.1624361e-09 | AE37: 0.027089553 | AF37: 0.0063835048 | AG37: 0.17232653 | AH37: 0 | AI37: 1.1057624 | AM37: C4 | AN37: 1152 | AO37: 0.76736111 | AP37: 0.43142361 | AQ37: no_evaluable | AR37: no | AS37: si | AT37: (b) mejor de la familia ols_familias: ols_factores trimestral, periodo completo; NO CUMPLE LA REGLA (§8 y multiverso) en ninguna variable; RMSE 2.830 vs AR(4) 1.038 (peor que AR(4)) | AU37: src/v8/m6_colinealidad.py | AV37: (b) mejor de la familia ols_familias: ols_factores trimestral, periodo completo | AW37: M6:ols_factores | AX37: si | AY37: output/v8/M6/coeficientes.csv | AZ37: =Fuera_muestra!F49 | BA37: =Fuera_muestra!G49 | BB37: =AZ37/BA37
A38: M6_ols_compra_trimestral_completo | B38: M6 | C38: ols_familias | D38: compra | E38: nacional | F38: completo | G38: d_ln_tasado_real | H38: trimestral | I38: tasado | J38: bis_hpi_xm_real | K38: 1.0851875 | L38: 0.35207371 | M38: EWC | N38: 3.0822737 | O38: 0.015064902 | P38: 0.050231711 | Q38: BH | R38: 0.27330411 | S38: 1.897071 | T38: 0.59808777 | U38: 1.0851875 | V38: 96 | W38: 0.46568303 | X38: 0.42318055 | Y38: 361.168 | Z38: 381.68278 | AD38: 1.1624361e-09 | AE38: 0.027089553 | AF38: 0.0063835048 | AG38: 0.17232653 | AH38: 0 | AI38: 1.1057624 | AM38: C4 | AN38: 960 | AO38: 0.71458333 | AP38: 0.346875 | AQ38: no_evaluable | AR38: no | AS38: si | AT38: (b) mejor de la familia ols_familias: ols_factores trimestral, periodo completo; NO CUMPLE LA REGLA (§8 y multiverso) en ninguna variable; RMSE 2.830 vs AR(4) 1.038 (peor que AR(4)) | AU38: src/v8/m6_colinealidad.py | AV38: (b) mejor de la familia ols_familias: ols_factores trimestral, periodo completo | AW38: M6:ols_factores | AX38: si | AY38: output/v8/M6/coeficientes.csv | AZ38: =Fuera_muestra!F49 | BA38: =Fuera_muestra!G49 | BB38: =AZ38/BA38
A39: M6_ols_compra_trimestral_completo | B39: M6 | C39: ols_familias | D39: compra | E39: nacional | F39: completo | G39: d_ln_tasado_real | H39: trimestral | I39: tasado | J39: covid | K39: -1.3751379 | L39: 0.37665158 | M39: EWC | N39: -3.6509549 | O39: 0.0064854075 | P39: 0.03543864 | Q39: BH | R39: -2.243698 | S39: -0.50657784 | T39: -0.11974596 | V39: 96 | W39: 0.46568303 | X39: 0.42318055 | Y39: 361.168 | Z39: 381.68278 | AD39: 1.1624361e-09 | AE39: 0.027089553 | AF39: 0.0063835048 | AG39: 0.17232653 | AH39: 0 | AI39: 1.1057624 | AM39: C4 | AQ39: no_evaluable | AR39: no_evaluable | AS39: si | AT39: (b) mejor de la familia ols_familias: ols_factores trimestral, periodo completo; NO CUMPLE LA REGLA (§8 y multiverso) en ninguna variable; RMSE 2.830 vs AR(4) 1.038 (peor que AR(4)) | AU39: src/v8/m6_colinealidad.py | AV39: (b) mejor de la familia ols_familias: ols_factores trimestral, periodo completo | AW39: M6:ols_factores | AX39: si | AY39: output/v8/M6/coeficientes.csv | AZ39: =Fuera_muestra!F49 | BA39: =Fuera_muestra!G49 | BB39: =AZ39/BA39
A40: M6_ols_compra_trimestral_completo | B40: M6 | C40: ols_familias | D40: compra | E40: nacional | F40: completo | G40: d_ln_tasado_real | H40: trimestral | I40: tasado | J40: epa2021_q | K40: 2.2482144 | L40: 1.5551236 | M40: EWC | N40: 1.4456822 | O40: 0.18627618 | P40: 0.30867695 | Q40: BH | R40: -1.337907 | S40: 5.8343357 | T40: 0.11423838 | V40: 96 | W40: 0.46568303 | X40: 0.42318055 | Y40: 361.168 | Z40: 381.68278 | AD40: 1.1624361e-09 | AE40: 0.027089553 | AF40: 0.0063835048 | AG40: 0.17232653 | AH40: 0 | AI40: 1.1057624 | AM40: C4 | AQ40: no_evaluable | AR40: no_evaluable | AS40: si | AT40: (b) mejor de la familia ols_familias: ols_factores trimestral, periodo completo; NO CUMPLE LA REGLA (§8 y multiverso) en ninguna variable; RMSE 2.830 vs AR(4) 1.038 (peor que AR(4)) | AU40: src/v8/m6_colinealidad.py | AV40: (b) mejor de la familia ols_familias: ols_factores trimestral, periodo completo | AW40: M6:ols_factores | AX40: si | AY40: output/v8/M6/coeficientes.csv | AZ40: =Fuera_muestra!F49 | BA40: =Fuera_muestra!G49 | BB40: =AZ40/BA40
...

Sheet Hipotesis
A1: id | B1: hipotesis | C1: estimacion | D1: p | E1: p_holm | F1: metodo_ajuste | G1: capa | H1: decision | I1: fuente | J1: rechaza_H0_calc (p_holm < 0,05)
A2: H8-1 | B2: En P5, la contribucion del shock demografico a la subida del alquiler real es positiva | C2: contribucion acumulada 0.07 pp (mediana 0.04; banda 68 % [-1.92; 2.13]); P(signo esperado) = 0.506 | D2: 0.49374973 | E2: 0.98749946 | F2: Holm | G2: C3s | H2: no respaldada tras Holm (C3s: condicionada a las restricciones de signo) | I2: output/v8/M2/hipotesis_m2.csv | J2: =IF(E2<0.05,"sí","no")
A3: H8-2 | B3: En P5, la contribucion de credito y tipos al precio real de compra es negativa | C3: contribucion acumulada -0.47 pp (mediana 3.37; banda 68 % [-2.82; 12.77]); P(signo esperado) = 0.293 | D3: 0.70664204 | E3: 0.98749946 | F3: Holm | G3: C3s | H3: no respaldada tras Holm (C3s: condicionada a las restricciones de signo) | I3: output/v8/M2/hipotesis_m2.csv | J3: =IF(E3<0.05,"sí","no")
A4: H8-3 | B4: En P3, la contribucion de actividad y renta al precio real de compra es positiva | C4: contribucion acumulada 7.72 pp (mediana 5.22; banda 68 % [-3.47; 18.23]); P(signo esperado) = 0.721 | D4: 0.27926802 | E4: 0.83780405 | F4: Holm | G4: C3s | H4: no respaldada tras Holm (C3s: condicionada a las restricciones de signo) | I4: output/v8/M2/hipotesis_m2.csv | J4: =IF(E4<0.05,"sí","no")
A5: H8-4 | B5: En P2, la contribucion conjunta de credito y tipos y de actividad y renta al precio real de compra es negativa | C5: contribucion acumulada -19.23 pp (mediana -16.71; banda 68 % [-34.59; -4.15]); P(signo esperado) = 0.914 | D5: 0.085658416 | E5: 0.34263366 | F5: Holm | G5: C3s | H5: no respaldada tras Holm (C3s: condicionada a las restricciones de signo) | I5: output/v8/M2/hipotesis_m2.csv | J5: =IF(E5<0.05,"sí","no")
A6: H8-5 | B6: Un shock monetario contractivo del BCE reduce el precio real de compra a h = 4-8 | C6: beta descriptivo (cociente) -8.78 (no es evidencia); F efectivo 1.83; IC AR95 [-inf; inf]; signo forma reducida 1 (esperado -1) | D6: 0.72438721 | E6: 1 | F6: Holm | G6: C4 | H6: no respaldada tras Holm; no respaldada tras Holm (instrumento no supera C3) | I6: output/v8/M5/hipotesis_m5.csv | J6: =IF(E6<0.05,"sí","no")
A7: H8-6 | B7: Un shock monetario contractivo del BCE reduce el alquiler real a h = 4-8 | C7: beta descriptivo (cociente) -2.91 (no es evidencia); F efectivo 0.77; IC AR95 [-inf; inf]; signo forma reducida 1 (esperado -1) | D7: 0.63493905 | E7: 1 | F7: Holm | G7: C4 | H7: no respaldada tras Holm; no respaldada tras Holm (instrumento no supera C3) | I7: output/v8/M5/hipotesis_m5.csv | J7: =IF(E7<0.05,"sí","no")
A8: H8-7 | B8: El empuje migratorio aumenta el alquiler real | C8: beta descriptivo (cociente) -0.51 (no es evidencia); F efectivo 0.05; IC AR95 [-inf; inf]; signo forma reducida -1 (esperado 1) | D8: 0.53637094 | E8: 1 | F8: Holm | G8: C4 | H8: no respaldada tras Holm; no respaldada tras Holm (instrumento no supera C3) | I8: output/v8/M5/hipotesis_m5.csv | J8: =IF(E8<0.05,"sí","no")
A9: H8-8 | B9: El componente comun de las 17 CCAA explica mas del 50 % de la varianza del crecimiento interanual del precio real de compra en cada periodo | C9: {"P1": 0.6474, "P2": 0.4527, "P3": 0.5958, "P4": 0.455, "P5": 0.9279} | D9: 0.669 | E9: 0.669 | F9: Holm | G9: C4 | H9: no respaldada tras Holm (C4: asociacion, sin lectura causal) | I9: output/v8/M1/hipotesis_m1.csv | J9: =IF(E9<0.05,"sí","no")
A10: H8-9 | B10: El factor comun espanol covaria positivamente con el crecimiento del HPI de la zona euro | C10: 0.5976 | D10: 0.01 | E10: 0.02 | F10: Holm | G10: C4 | H10: respaldada tras Holm (C4: asociacion, sin lectura causal) | I10: output/v8/M1/hipotesis_m1.csv | J10: =IF(E10<0.05,"sí","no")

Sheet Votos_s9
A1: mercado | B1: periodo | C1: voto_svar_hd | D1: voto_dominancia | E1: voto_lpiv | F1: voto_contabilidad | G1: factor_evaluado | H1: n_votos | I1: cond1 | J1: cond2 | K1: cond3 | L1: resultado | M1: capa | N1: fuente | O1: votos_factor_calc (COUNTIF) | P1: cond1_calc (>=3)
A2: compra | B2: P1 | C2: empleo_renta | D2: abstiene | E2: abstiene | F2: abstiene | G2: empleo_renta | H2: 1 | I2: no | J2: sí | K2: sí | L2: no designado | M2: C4 (ranking; sin designacion) | N2: output/v8/F5/regla_s9.csv | O2: =COUNTIF(C2:F2,G2) | P2: =IF(O2>=3,"sí","no")
A3: compra | B3: P2 | C3: empleo_renta | D3: factor_europeo | E3: abstiene | F3: abstiene | G3: empleo_renta | H3: 1 | I3: no | J3: no | K3: no | L3: no designado | M3: C4 (ranking; sin designacion) | N3: output/v8/F5/regla_s9.csv | O3: =COUNTIF(C3:F3,G3) | P3: =IF(O3>=3,"sí","no")
A4: compra | B4: P3 | C4: empleo_renta | D4: empleo_renta | E4: abstiene | F4: demografia | G4: empleo_renta | H4: 2 | I4: no | J4: sí | K4: no | L4: no designado | M4: C4 (ranking; sin designacion) | N4: output/v8/F5/regla_s9.csv | O4: =COUNTIF(C4:F4,G4) | P4: =IF(O4>=3,"sí","no")
A5: compra | B5: P4 | C5: empleo_renta | D5: credito_tipos | E5: credito_tipos | F5: abstiene | G5: credito_tipos | H5: 2 | I5: no | J5: no | K5: no | L5: no designado | M5: C4 (ranking; sin designacion) | N5: output/v8/F5/regla_s9.csv | O5: =COUNTIF(C5:F5,G5) | P5: =IF(O5>=3,"sí","no")
A6: compra | B6: P5 | C6: credito_tipos | D6: credito_tipos | E6: abstiene | F6: demografia | G6: credito_tipos | H6: 2 | I6: no | J6: no | K6: no | L6: no designado | M6: C4 (ranking; sin designacion) | N6: output/v8/F5/regla_s9.csv | O6: =COUNTIF(C6:F6,G6) | P6: =IF(O6>=3,"sí","no")
A7: alquiler | B7: P1 | C7: abstiene | D7: factor_europeo | E7: abstiene | F7: abstiene | G7: factor_europeo | H7: 1 | I7: no | J7: no | K7: no | L7: no designado | M7: C4 (ranking; sin designacion) | N7: output/v8/F5/regla_s9.csv | O7: =COUNTIF(C7:F7,G7) | P7: =IF(O7>=3,"sí","no")
A8: alquiler | B8: P2 | C8: empleo_renta | D8: empleo_renta | E8: abstiene | F8: abstiene | G8: empleo_renta | H8: 2 | I8: no | J8: no | K8: no | L8: no designado | M8: C4 (ranking; sin designacion) | N8: output/v8/F5/regla_s9.csv | O8: =COUNTIF(C8:F8,G8) | P8: =IF(O8>=3,"sí","no")
A9: alquiler | B9: P3 | C9: demografia | D9: demanda_externa | E9: abstiene | F9: abstiene | G9: demografia | H9: 1 | I9: no | J9: no | K9: no | L9: no designado | M9: C4 (ranking; sin designacion) | N9: output/v8/F5/regla_s9.csv | O9: =COUNTIF(C9:F9,G9) | P9: =IF(O9>=3,"sí","no")
A10: alquiler | B10: P4 | C10: demanda_vivienda | D10: credito_tipos | E10: abstiene | F10: abstiene | G10: demanda_vivienda | H10: 1 | I10: no | J10: no | K10: no | L10: no designado | M10: C4 (ranking; sin designacion) | N10: output/v8/F5/regla_s9.csv | O10: =COUNTIF(C10:F10,G10) | P10: =IF(O10>=3,"sí","no")
A11: alquiler | B11: P5 | C11: credito_tipos | D11: credito_tipos | E11: abstiene | F11: abstiene | G11: credito_tipos | H11: 2 | I11: no | J11: no | K11: no | L11: no designado | M11: C4 (ranking; sin designacion) | N11: output/v8/F5/regla_s9.csv | O11: =COUNTIF(C11:F11,G11) | P11: =IF(O11>=3,"sí","no")
A13: Celdas designadas (calc.) | B13: =COUNTIF(L2:L11,"designado")
A14: Celdas con condición 1 (calc.) | B14: =COUNTIF(P2:P11,"sí")

Sheet Atribucion
A1: mercado | B1: ambito | C1: periodo | D1: factor | E1: metodo | F1: contribucion_pp | G1: media | H1: mediana | I1: pct_signo | J1: b68_lo | K1: b68_hi | L1: b90_lo | M1: b90_hi | N1: capa | O1: compite | P1: vota | Q1: variante | R1: delta_y_metodo_pp | S1: notas | T1: fuente | U1: pct_total_calc (contribución / ΔY) | V1: suma_contribuciones_celda_calc (SUMIFS)
A2: compra | B2: nacional | C2: P2 | D2: empleo_renta | E2: svar_hd | F2: -10.6353 | G2: -10.6353 | H2: -7.57201 | I2: 0.241701 | J2: -23.5243 | K2: 0.660395 | L2: -38.8394 | M2: 7.26832 | N2: C3s | O2: si | P2: si | Q2: V3 | R2: -44.0018 | S2: media posterior (aditiva); R0; C3s condicionada a los supuestos | T2: output/v8/F5/atribucion_combinada.csv | U2: =IF(R2=0,"",F2/R2) | V2: =SUMIFS(F$2:F$1589,A$2:A$1589,A2,C$2:C$1589,C2,E$2:E$1589,E2,Q$2:Q$1589,Q2)
A3: compra | B3: nacional | C3: P2 | D3: demografia | E3: svar_hd | F3: -2.93343 | G3: -2.93343 | H3: -1.59917 | I3: 0.0666662 | J3: -10.7148 | K3: 4.04962 | L3: -20.6099 | M3: 11.0989 | N3: C3s | O3: si | P3: no | Q3: V3 | R3: -44.0018 | S3: media posterior (aditiva); R0; C3s condicionada a los supuestos | T3: output/v8/F5/atribucion_combinada.csv | U3: =IF(R3=0,"",F3/R3) | V3: =SUMIFS(F$2:F$1589,A$2:A$1589,A3,C$2:C$1589,C3,E$2:E$1589,E3,Q$2:Q$1589,Q3)
A4: compra | B4: nacional | C4: P2 | D4: demanda_vivienda | E4: svar_hd | F4: -7.40779 | G4: -7.40779 | H4: -3.54416 | I4: 0.168352 | J4: -17.8842 | K4: 1.99552 | L4: -34.0416 | M4: 6.11398 | N4: C3s | O4: si | P4: no | Q4: V3 | R4: -44.0018 | S4: media posterior (aditiva); R0; C3s condicionada a los supuestos | T4: output/v8/F5/atribucion_combinada.csv | U4: =IF(R4=0,"",F4/R4) | V4: =SUMIFS(F$2:F$1589,A$2:A$1589,A4,C$2:C$1589,C4,E$2:E$1589,E4,Q$2:Q$1589,Q4)
A5: compra | B5: nacional | C5: P2 | D5: oferta | E5: svar_hd | F5: -4.81136 | G5: -4.81136 | H5: -2.0535 | I5: 0.109345 | J5: -13.2992 | K5: 2.48894 | L5: -25.0249 | M5: 7.58723 | N5: C3s | O5: si | P5: no | Q5: V3 | R5: -44.0018 | S5: media posterior (aditiva); R0; C3s condicionada a los supuestos | T5: output/v8/F5/atribucion_combinada.csv | U5: =IF(R5=0,"",F5/R5) | V5: =SUMIFS(F$2:F$1589,A$2:A$1589,A5,C$2:C$1589,C5,E$2:E$1589,E5,Q$2:Q$1589,Q5)
A6: compra | B6: nacional | C6: P2 | D6: credito_tipos | E6: svar_hd | F6: -8.59653 | G6: -8.59653 | H6: -5.88471 | I6: 0.195368 | J6: -18.8749 | K6: 0.542165 | L6: -32.8942 | M6: 5.23205 | N6: C3s | O6: si | P6: no | Q6: V3 | R6: -44.0018 | S6: media posterior (aditiva); R0; C3s condicionada a los supuestos | T6: output/v8/F5/atribucion_combinada.csv | U6: =IF(R6=0,"",F6/R6) | V6: =SUMIFS(F$2:F$1589,A$2:A$1589,A6,C$2:C$1589,C6,E$2:E$1589,E6,Q$2:Q$1589,Q6)
A7: compra | B7: nacional | C7: P2 | D7: no_identificados | E7: svar_hd | F7: -7.86463 | G7: -7.86463 | H7: -6.49137 | I7: 0.178734 | J7: -18.8391 | K7: 2.34579 | L7: -29.573 | M7: 12.0855 | N7: C3s | O7: no | P7: no_compite | Q7: V3 | R7: -44.0018 | S7: media posterior (aditiva); R0; C3s condicionada a los supuestos | T7: output/v8/F5/atribucion_combinada.csv | U7: =IF(R7=0,"",F7/R7) | V7: =SUMIFS(F$2:F$1589,A$2:A$1589,A7,C$2:C$1589,C7,E$2:E$1589,E7,Q$2:Q$1589,Q7)
A8: compra | B8: nacional | C8: P2 | D8: determinista | E8: svar_hd | F8: -1.75281 | G8: -1.75281 | H8: -3.18546 | I8: 0.0398349 | J8: -16.3721 | K8: 13.1959 | L8: -26.7554 | M8: 25.8187 | N8: C3s | O8: no | P8: no_compite | Q8: V3 | R8: -44.0018 | S8: media posterior (aditiva); R0; C3s condicionada a los supuestos | T8: output/v8/F5/atribucion_combinada.csv | U8: =IF(R8=0,"",F8/R8) | V8: =SUMIFS(F$2:F$1589,A$2:A$1589,A8,C$2:C$1589,C8,E$2:E$1589,E8,Q$2:Q$1589,Q8)
A9: compra | B9: nacional | C9: P3 | D9: empleo_renta | E9: svar_hd | F9: 7.72218 | G9: 7.72218 | H9: 5.22264 | I9: 0.939816 | J9: -3.46639 | K9: 18.2318 | L9: -15.2388 | M9: 31.2052 | N9: C3s | O9: si | P9: si | Q9: V3 | R9: 8.2167 | S9: media posterior (aditiva); R0; C3s condicionada a los supuestos | T9: output/v8/F5/atribucion_combinada.csv | U9: =IF(R9=0,"",F9/R9) | V9: =SUMIFS(F$2:F$1589,A$2:A$1589,A9,C$2:C$1589,C9,E$2:E$1589,E9,Q$2:Q$1589,Q9)
A10: compra | B10: nacional | C10: P3 | D10: demografia | E10: svar_hd | F10: 0.141604 | G10: 0.141604 | H10: -0.177369 | I10: 0.0172337 | J10: -6.57831 | K10: 6.81486 | L10: -13.9672 | M10: 17.345 | N10: C3s | O10: si | P10: no | Q10: V3 | R10: 8.2167 | S10: media posterior (aditiva); R0; C3s condicionada a los supuestos | T10: output/v8/F5/atribucion_combinada.csv | U10: =IF(R10=0,"",F10/R10) | V10: =SUMIFS(F$2:F$1589,A$2:A$1589,A10,C$2:C$1589,C10,E$2:E$1589,E10,Q$2:Q$1589,Q10)
A11: compra | B11: nacional | C11: P3 | D11: demanda_vivienda | E11: svar_hd | F11: -0.411954 | G11: -0.411954 | H11: 0.532209 | I11: -0.0501362 | J11: -7.20665 | K11: 8.99381 | L11: -18.366 | M11: 17.6965 | N11: C3s | O11: si | P11: no | Q11: V3 | R11: 8.2167 | S11: media posterior (aditiva); R0; C3s condicionada a los supuestos | T11: output/v8/F5/atribucion_combinada.csv | U11: =IF(R11=0,"",F11/R11) | V11: =SUMIFS(F$2:F$1589,A$2:A$1589,A11,C$2:C$1589,C11,E$2:E$1589,E11,Q$2:Q$1589,Q11)
A12: compra | B12: nacional | C12: P3 | D12: oferta | E12: svar_hd | F12: 0.380583 | G12: 0.380583 | H12: 0.18425 | I12: 0.0463182 | J12: -7.29269 | K12: 8.02427 | L12: -16.8044 | M12: 18.9594 | N12: C3s | O12: si | P12: no | Q12: V3 | R12: 8.2167 | S12: media posterior (aditiva); R0; C3s condicionada a los supuestos | T12: output/v8/F5/atribucion_combinada.csv | U12: =IF(R12=0,"",F12/R12) | V12: =SUMIFS(F$2:F$1589,A$2:A$1589,A12,C$2:C$1589,C12,E$2:E$1589,E12,Q$2:Q$1589,Q12)
A13: compra | B13: nacional | C13: P3 | D13: credito_tipos | E13: svar_hd | F13: -1.55002 | G13: -1.55002 | H13: -0.684626 | I13: -0.188642 | J13: -9.78341 | K13: 7.07096 | L13: -17.7135 | M13: 18.4172 | N13: C3s | O13: si | P13: no | Q13: V3 | R13: 8.2167 | S13: media posterior (aditiva); R0; C3s condicionada a los supuestos | T13: output/v8/F5/atribucion_combinada.csv | U13: =IF(R13=0,"",F13/R13) | V13: =SUMIFS(F$2:F$1589,A$2:A$1589,A13,C$2:C$1589,C13,E$2:E$1589,E13,Q$2:Q$1589,Q13)
... A62: compra | B62: nacional | C62: P1 | D62: determinista | E62: svar_hd | F62: 23.0593 | G62: 23.0593 | H62: 22.5386 | I62: 0.306022 | J62: -1.04812 | K62: 50.2903 | L62: -23.2178 | M62: 76.3301 | N62: C3s | O62: no | P62: no_compite | Q62: larga | R62: 75.3518 | S62: media posterior (aditiva); R0; C3s condicionada a los supuestos | T62: output/v8/F5/atribucion_combinada.csv | U62: =IF(R62=0,"",F62/R62) | V62: =SUMIFS(F$2:F$1589,A$2:A$1589,A62,C$2:C$1589,C62,E$2:E$1589,E62,Q$2:Q$1589,Q62)
A63: compra | B63: nacional | C63: P1 | D63: demografia | E63: dominancia | F63: 15.3085 | I63: 0.2047 | J63: 6.97915 | K63: 20.2422 | L63: 3.22483 | M63: 23.2585 | N63: C4 | O63: si | P63: abstiene | Q63: interanual_ipc_tasado | R63: 74.7849 | S63: cuota LMG x R2 x dY (asociacion; no causal) | T63: output/v8/F5/atribucion_combinada.csv | U63: =IF(R63=0,"",F63/R63) | V63: =SUMIFS(F$2:F$1589,A$2:A$1589,A63,C$2:C$1589,C63,E$2:E$1589,E63,Q$2:Q$1589,Q63)
A64: compra | B64: nacional | C64: P1 | D64: empleo_renta | E64: dominancia | F64: 2.82591 | I64: 0.0377872 | J64: 0 | K64: 3.70053 | L64: 0 | M64: 4.31351 | N64: C4 | O64: si | P64: abstiene | Q64: interanual_ipc_tasado | R64: 74.7849 | S64: cuota LMG x R2 x dY (asociacion; no causal) | T64: output/v8/F5/atribucion_combinada.csv | U64: =IF(R64=0,"",F64/R64) | V64: =SUMIFS(F$2:F$1589,A$2:A$1589,A64,C$2:C$1589,C64,E$2:E$1589,E64,Q$2:Q$1589,Q64)
