Workbook

Sheet Léeme
A1: Tablas V9 · qué causa qué (Borja Romero, economista; firma individual, independiente)
A2: Generado por src/v9/f5_excel.py desde output/v5/cifras_clave.csv (ids «V9-»). No editar a mano.
A3: Colores: azul = entrada (cifra publicada con su fuente); negro = cálculo (fórmula); verde = enlace a otra hoja.
A4: Ningún resultado de V9 alcanza C3/C3s: todas las cifras son asociaciones o descripciones (C4) o recuentos.
A5: Efectos en puntos logarítmicos ×100 (≈ %). Pre-registro: docs/v9/hipotesis.md y docs/v9/hipotesis_addendum_a1.md.

Sheet Entradas
A1: id | B1: indicador | C1: valor | D1: min | E1: max | F1: unidad | G1: periodo | H1: cobertura | I1: fuentes | J1: capa | K1: origen
A2: V9-D1a-contratos-att | B2: zonas tensionadas (Ley 12/2023): ATT sobre contratos de contratos nuevos (CS) | C2: -6.25 | D2: -13.206 | E2: 0.706 | F2: % | G2: 2022T2-2026T1 | H2: Cataluña, municipios | I2: Incasòl (fianzas; no redistribuible), BOE; elaboración propia | J2: C4 | K2: output/v9/F5/hechos.json:V9-D1a-contratos-att
A3: V9-D1a-contratos-placebo-p | B3: zonas tensionadas (Ley 12/2023), log contratos: p del placebo de fecha (4 trimestres antes) | C3: 0.61261 | F3: p-valor | G3: 2022T2-2026T1 | H3: Cataluña, municipios | I3: Incasòl (fianzas; no redistribuible), BOE; elaboración propia | J3: C4 | K3: output/v9/F5/hechos.json:V9-D1a-contratos-placebo-p
A4: V9-D1a-contratos-pretend-p | B4: zonas tensionadas (Ley 12/2023), log contratos: p del contraste conjunto de pretendencias | C4: 0.03134 | F4: p-valor | G4: 2022T2-2026T1 | H4: Cataluña, municipios | I4: Incasòl (fianzas; no redistribuible), BOE; elaboración propia | J4: C4 | K4: output/v9/F5/hechos.json:V9-D1a-contratos-pretend-p
A5: V9-D1a-contratos-ruptura | B5: zonas tensionadas (Ley 12/2023), log contratos: M̄ de ruptura de Honest DiD (magnitudes relativas, simplificado) | C5: 0 | F5: M̄ | G5: 2022T2-2026T1 | H5: Cataluña, municipios | I5: Incasòl (fianzas; no redistribuible), BOE; elaboración propia | J5: C4 | K5: output/v9/F5/hechos.json:V9-D1a-contratos-ruptura
A6: V9-D1a-renta-att | B6: zonas tensionadas (Ley 12/2023): ATT sobre renta media de contratos nuevos (CS) | C6: -5.846 | D6: -8.499 | E6: -3.193 | F6: % | G6: 2022T2-2026T1 | H6: Cataluña, municipios | I6: Incasòl (fianzas; no redistribuible), BOE; elaboración propia | J6: C4 | K6: output/v9/F5/hechos.json:V9-D1a-renta-att
A7: V9-D1a-renta-pholm | B7: zonas tensionadas (Ley 12/2023), log renta media: p ajustado por Holm (familia confirmatoria de V9) | C7: 0 | F7: p-valor | G7: 2022T2-2026T1 | H7: Cataluña, municipios | I7: Incasòl (fianzas; no redistribuible), BOE; elaboración propia | J7: C4 | K7: output/v9/F5/hechos.json:V9-D1a-renta-pholm
A8: V9-D1a-renta-placebo-p | B8: zonas tensionadas (Ley 12/2023), log renta media: p del placebo de fecha (4 trimestres antes) | C8: 0.00701 | F8: p-valor | G8: 2022T2-2026T1 | H8: Cataluña, municipios | I8: Incasòl (fianzas; no redistribuible), BOE; elaboración propia | J8: C4 | K8: output/v9/F5/hechos.json:V9-D1a-renta-placebo-p
A9: V9-D1a-renta-pretend-p | B9: zonas tensionadas (Ley 12/2023), log renta media: p del contraste conjunto de pretendencias | C9: 0.0004 | F9: p-valor | G9: 2022T2-2026T1 | H9: Cataluña, municipios | I9: Incasòl (fianzas; no redistribuible), BOE; elaboración propia | J9: C4 | K9: output/v9/F5/hechos.json:V9-D1a-renta-pretend-p
A10: V9-D1a-renta-ruptura | B10: zonas tensionadas (Ley 12/2023), log renta media: M̄ de ruptura de Honest DiD (magnitudes relativas, simplificado) | C10: 0.2 | F10: M̄ | G10: 2022T2-2026T1 | H10: Cataluña, municipios | I10: Incasòl (fianzas; no redistribuible), BOE; elaboración propia | J10: C4 | K10: output/v9/F5/hechos.json:V9-D1a-renta-ruptura
A11: V9-D1b-contratos-att | B11: Ley catalana 11/2020: ATT sobre contratos de contratos nuevos (CS) | C11: -1.317 | D11: -7.02 | E11: 4.385 | F11: % | G11: 2019T1-2022T1 | H11: Cataluña, municipios | I11: Incasòl (fianzas; no redistribuible), BOE; elaboración propia | J11: C4 | K11: output/v9/F5/hechos.json:V9-D1b-contratos-att
A12: V9-D1b-contratos-placebo-p | B12: Ley catalana 11/2020, log contratos: p del placebo de fecha (4 trimestres antes) | C12: 0.15616 | F12: p-valor | G12: 2019T1-2022T1 | H12: Cataluña, municipios | I12: Incasòl (fianzas; no redistribuible), BOE; elaboración propia | J12: C4 | K12: output/v9/F5/hechos.json:V9-D1b-contratos-placebo-p
A13: V9-D1b-contratos-pretend-p | B13: Ley catalana 11/2020, log contratos: p del contraste conjunto de pretendencias | C13: 0.28015 | F13: p-valor | G13: 2019T1-2022T1 | H13: Cataluña, municipios | I13: Incasòl (fianzas; no redistribuible), BOE; elaboración propia | J13: C4 | K13: output/v9/F5/hechos.json:V9-D1b-contratos-pretend-p
A14: V9-D1b-contratos-ruptura | B14: Ley catalana 11/2020, log contratos: M̄ de ruptura de Honest DiD (magnitudes relativas, simplificado) | C14: 0 | F14: M̄ | G14: 2019T1-2022T1 | H14: Cataluña, municipios | I14: Incasòl (fianzas; no redistribuible), BOE; elaboración propia | J14: C4 | K14: output/v9/F5/hechos.json:V9-D1b-contratos-ruptura
A15: V9-D1b-renta-att | B15: Ley catalana 11/2020: ATT sobre renta media de contratos nuevos (CS) | C15: -5.851 | D15: -7.346 | E15: -4.356 | F15: % | G15: 2019T1-2022T1 | H15: Cataluña, municipios | I15: Incasòl (fianzas; no redistribuible), BOE; elaboración propia | J15: C4 | K15: output/v9/F5/hechos.json:V9-D1b-renta-att
A16: V9-D1b-renta-pholm | B16: Ley catalana 11/2020, log renta media: p ajustado por Holm (familia confirmatoria de V9) | C16: 0 | F16: p-valor | G16: 2019T1-2022T1 | H16: Cataluña, municipios | I16: Incasòl (fianzas; no redistribuible), BOE; elaboración propia | J16: C4 | K16: output/v9/F5/hechos.json:V9-D1b-renta-pholm
A17: V9-D1b-renta-placebo-p | B17: Ley catalana 11/2020, log renta media: p del placebo de fecha (4 trimestres antes) | C17: 0.40841 | F17: p-valor | G17: 2019T1-2022T1 | H17: Cataluña, municipios | I17: Incasòl (fianzas; no redistribuible), BOE; elaboración propia | J17: C4 | K17: output/v9/F5/hechos.json:V9-D1b-renta-placebo-p
A18: V9-D1b-renta-pretend-p | B18: Ley catalana 11/2020, log renta media: p del contraste conjunto de pretendencias | C18: 0.28158 | F18: p-valor | G18: 2019T1-2022T1 | H18: Cataluña, municipios | I18: Incasòl (fianzas; no redistribuible), BOE; elaboración propia | J18: C4 | K18: output/v9/F5/hechos.json:V9-D1b-renta-pretend-p
A19: V9-D1b-renta-ruptura | B19: Ley catalana 11/2020, log renta media: M̄ de ruptura de Honest DiD (magnitudes relativas, simplificado) | C19: 0.8 | F19: M̄ | G19: 2019T1-2022T1 | H19: Cataluña, municipios | I19: Incasòl (fianzas; no redistribuible), BOE; elaboración propia | J19: C4 | K19: output/v9/F5/hechos.json:V9-D1b-renta-ruptura
A20: V9-D1c-renta-att | B20: Zonas tensionadas de Euskadi: ATT exploratorio sobre la renta de fianzas nuevas (EMAL) | C20: -2.484 | D20: -3.519 | E20: -1.449 | F20: % | G20: 2016T1-2025T4 | H20: Euskadi, municipios > 20.000 hab. | I20: Gobierno Vasco EMAL; BOE | J20: C4 | K20: output/v9/F5/hechos.json:V9-D1c-renta-att
A21: V9-D2-renta-covid | B21: Viviendas de uso turístico en 2019 × COVID 2020-2021: variación de la renta de contratos nuevos por 1 DE de dosis | C21: 0.219 | D21: -0.549 | E21: 0.987 | F21: % | G21: 2014-2025 | H21: Cataluña, municipios | I21: Incasòl; IDESCAT; INE padrón | J21: C4 | K21: output/v9/F5/hechos.json:V9-D2-renta-covid
A22: V9-D2-renta-pretend-p | B22: D2, renta: p del contraste conjunto de pretendencias (2014-2018) | C22: 0.00023 | F22: p-valor | G22: 2014-2018 | H22: Cataluña | I22: Incasòl; IDESCAT | J22: C4 | K22: output/v9/F5/hechos.json:V9-D2-renta-pretend-p
A23: V9-D2-renta-reap | B23: Viviendas de uso turístico en 2019 × reapertura 2022-2025: variación de la renta de contratos nuevos por 1 DE de dosis | C23: 1.046 | D23: 0.39 | E23: 1.703 | F23: % | G23: 2014-2025 | H23: Cataluña, municipios | I23: Incasòl; IDESCAT; INE padrón | J23: C4 | K23: output/v9/F5/hechos.json:V9-D2-renta-reap
A24: V9-D3-cuota | B24: Caída del registro VUT (por 1 VUT por 100 viviendas) y variación de la cuota provincial de fianzas 2024→2025 por CP (descriptivo) | C24: 0.00205 | D24: -0.00216 | E24: 0.00625 | F24: puntos de cuota | G24: 2024-2025 | H24: Comunitat Valenciana, códigos postales | I24: GVA (fianzas, registro VUT); INE; elaboración propia | J24: C4 | K24: output/v9/F5/hechos.json:V9-D3-cuota
A25: V9-D3-media | B25: Caída del registro VUT (por 1 VUT por 100 viviendas) y variación de la fianza media 2024→2025 por CP (descriptivo) | C25: -0.195 | D25: -0.413 | E25: 0.024 | F25: % | G25: 2024-2025 | H25: Comunitat Valenciana, códigos postales | I25: GVA (fianzas, registro VUT); INE; elaboración propia | J25: C4 | K25: output/v9/F5/hechos.json:V9-D3-media
A26: V9-D4-ipc-ampliacion | B26: Inmigración (2SLS shift-share), IPC de alquiler: elasticidad por punto de población extranjera (2015-2022) | C26: 1.525 | D26: -1.364 | E26: 4.414 | F26: % por punto de población | G26: 2015-2022 | H26: 50 provincias | I26: INE padrón e IPC; MIVAU valor tasado; elaboración propia | J26: C4 | K26: output/v9/F5/hechos.json:V9-D4-ipc-ampliacion
A27: V9-D4-ipc-ampliacion-F | B27: Inmigración, IPC de alquiler: F efectiva del instrumento | C27: 2.79401 | F27: estadístico F | G27: 2015-2022 | H27: 50 provincias | I27: INE padrón | J27: C4 | K27: output/v9/F5/hechos.json:V9-D4-ipc-ampliacion-F
A28: V9-D4-ipc-replica | B28: Inmigración (2SLS shift-share), IPC de alquiler: elasticidad por punto de población extranjera (2003-2012) | C28: 0.723 | D28: -0.815 | E28: 2.261 | F28: % por punto de población | G28: 2003-2012 | H28: 50 provincias | I28: INE padrón e IPC; MIVAU valor tasado; elaboración propia | J28: C4 | K28: output/v9/F5/hechos.json:V9-D4-ipc-replica
A29: V9-D4-ipc-replica-F | B29: Inmigración, IPC de alquiler: F efectiva del instrumento | C29: 4.55109 | F29: estadístico F | G29: 2003-2012 | H29: 50 provincias | I29: INE padrón | J29: C4 | K29: output/v9/F5/hechos.json:V9-D4-ipc-replica-F
A30: V9-D4-tasado-ampliacion | B30: Inmigración (2SLS shift-share), valor tasado: elasticidad por punto de población extranjera (2015-2022) | C30: 12.877 | D30: -1.452 | E30: 27.207 | F30: % por punto de población | G30: 2015-2022 | H30: 50 provincias | I30: INE padrón e IPC; MIVAU valor tasado; elaboración propia | J30: C4 | K30: output/v9/F5/hechos.json:V9-D4-tasado-ampliacion
A31: V9-D4-tasado-ampliacion-F | B31: Inmigración, valor tasado: F efectiva del instrumento | C31: 3.43812 | F31: estadístico F | G31: 2015-2022 | H31: 50 provincias | I31: INE padrón | J31: C4 | K31: output/v9/F5/hechos.json:V9-D4-tasado-ampliacion-F
A32: V9-D4-tasado-replica | B32: Inmigración (2SLS shift-share), valor tasado: elasticidad por punto de población extranjera (2003-2012) | C32: -0.286 | D32: -2.716 | E32: 2.145 | F32: % por punto de población | G32: 2003-2012 | H32: 50 provincias | I32: INE padrón e IPC; MIVAU valor tasado; elaboración propia | J32: C4 | K32: output/v9/F5/hechos.json:V9-D4-tasado-replica
A33: V9-D4-tasado-replica-F | B33: Inmigración, valor tasado: F efectiva del instrumento | C33: 3.65561 | F33: estadístico F | G33: 2003-2012 | H33: 50 provincias | I33: INE padrón | J33: C4 | K33: output/v9/F5/hechos.json:V9-D4-tasado-replica-F
A34: V9-D5-alq-h4 | B34: Shock monetario del BCE × cuota de hipotecas a tipo variable (1 DE): Δ log alquiler (h = 4) | C34: -11.68 | D34: -17.399 | E34: -5.962 | F34: % | G34: 2008T1-2025T3 | H34: 18 países de la zona euro | I34: BIS; Eurostat; BCE (RAI); Jarociński-Karadi (no redistribuible) | J34: C4 | K34: output/v9/F5/hechos.json:V9-D5-alq-h4
A35: V9-D5-precio-h4 | B35: Shock monetario del BCE × cuota de hipotecas a tipo variable (1 DE): Δ log precio (h = 4) | C35: -5.251 | D35: -15.632 | E35: 5.13 | F35: % | G35: 2008T1-2025T3 | H35: 18 países de la zona euro | I35: BIS; Eurostat; BCE (RAI); Jarociński-Karadi (no redistribuible) | J35: C4 | K35: output/v9/F5/hechos.json:V9-D5-precio-h4
A36: V9-D5-precio-h8 | B36: Shock monetario del BCE × cuota de hipotecas a tipo variable (1 DE): Δ log precio (h = 8) | C36: -4.389 | D36: -17.537 | E36: 8.759 | F36: % | G36: 2008T1-2025T3 | H36: 18 países de la zona euro | I36: BIS; Eurostat; BCE (RAI); Jarociński-Karadi (no redistribuible) | J36: C4 | K36: output/v9/F5/hechos.json:V9-D5-precio-h8
A37: V9-D7-CV-1121-H0 | B37: Hogares al inicio (2011-2021; descomposición D7) | C37: 1986896 | F37: hogares | G37: 2011-2021 | H37: Comunitat Valenciana | I37: INE (censos, ECP, padrón, censo anual) | J37: C4 | K37: output/v9/F5/hechos.json:V9-D7-CV-1121-H0
A38: V9-D7-CV-1121-H1 | B38: Hogares al final (2011-2021; descomposición D7) | C38: 2022501 | F38: hogares | G38: 2011-2021 | H38: Comunitat Valenciana | I38: INE (censos, ECP, padrón, censo anual) | J38: C4 | K38: output/v9/F5/hechos.json:V9-D7-CV-1121-H1
A39: V9-D7-CV-1121-P0 | B39: Población al inicio (2011-2021; descomposición D7) | C39: 5129266 | F39: personas | G39: 2011-2021 | H39: Comunitat Valenciana | I39: INE (censos, ECP, padrón, censo anual) | J39: C4 | K39: output/v9/F5/hechos.json:V9-D7-CV-1121-P0
A40: V9-D7-CV-1121-P1 | B40: Población al final (2011-2021; descomposición D7) | C40: 5097967 | F40: personas | G40: 2011-2021 | H40: Comunitat Valenciana | I40: INE (censos, ECP, padrón, censo anual) | J40: C4 | K40: output/v9/F5/hechos.json:V9-D7-CV-1121-P1
...

Sheet Cálculos
A1: id | B1: valor (enlace) | C1: amplitud del IC 95 % | D1: ¿el IC excluye el 0?
A2: V9-D1a-contratos-att | B2: =Entradas!C2 | C2: =Entradas!E2-Entradas!D2 | D2: =IF(OR(Entradas!D2>0,Entradas!E2<0),"sí","no")
A3: V9-D1a-renta-att | B3: =Entradas!C6 | C3: =Entradas!E6-Entradas!D6 | D3: =IF(OR(Entradas!D6>0,Entradas!E6<0),"sí","no")
A4: V9-D1b-contratos-att | B4: =Entradas!C11 | C4: =Entradas!E11-Entradas!D11 | D4: =IF(OR(Entradas!D11>0,Entradas!E11<0),"sí","no")
A5: V9-D1b-renta-att | B5: =Entradas!C15 | C5: =Entradas!E15-Entradas!D15 | D5: =IF(OR(Entradas!D15>0,Entradas!E15<0),"sí","no")
A6: V9-D1c-renta-att | B6: =Entradas!C20 | C6: =Entradas!E20-Entradas!D20 | D6: =IF(OR(Entradas!D20>0,Entradas!E20<0),"sí","no")
A7: V9-D2-renta-covid | B7: =Entradas!C21 | C7: =Entradas!E21-Entradas!D21 | D7: =IF(OR(Entradas!D21>0,Entradas!E21<0),"sí","no")
A8: V9-D2-renta-reap | B8: =Entradas!C23 | C8: =Entradas!E23-Entradas!D23 | D8: =IF(OR(Entradas!D23>0,Entradas!E23<0),"sí","no")
A9: V9-D3-cuota | B9: =Entradas!C24 | C9: =Entradas!E24-Entradas!D24 | D9: =IF(OR(Entradas!D24>0,Entradas!E24<0),"sí","no")
A10: V9-D3-media | B10: =Entradas!C25 | C10: =Entradas!E25-Entradas!D25 | D10: =IF(OR(Entradas!D25>0,Entradas!E25<0),"sí","no")
A11: V9-D4-ipc-ampliacion | B11: =Entradas!C26 | C11: =Entradas!E26-Entradas!D26 | D11: =IF(OR(Entradas!D26>0,Entradas!E26<0),"sí","no")
A12: V9-D4-ipc-replica | B12: =Entradas!C28 | C12: =Entradas!E28-Entradas!D28 | D12: =IF(OR(Entradas!D28>0,Entradas!E28<0),"sí","no")
A13: V9-D4-tasado-ampliacion | B13: =Entradas!C30 | C13: =Entradas!E30-Entradas!D30 | D13: =IF(OR(Entradas!D30>0,Entradas!E30<0),"sí","no")
A14: V9-D4-tasado-replica | B14: =Entradas!C32 | C14: =Entradas!E32-Entradas!D32 | D14: =IF(OR(Entradas!D32>0,Entradas!E32<0),"sí","no")
A15: V9-D5-alq-h4 | B15: =Entradas!C34 | C15: =Entradas!E34-Entradas!D34 | D15: =IF(OR(Entradas!D34>0,Entradas!E34<0),"sí","no")
A16: V9-D5-precio-h4 | B16: =Entradas!C35 | C16: =Entradas!E35-Entradas!D35 | D16: =IF(OR(Entradas!D35>0,Entradas!E35<0),"sí","no")
A17: V9-D5-precio-h8 | B17: =Entradas!C36 | C17: =Entradas!E36-Entradas!D36 | D17: =IF(OR(Entradas!D36>0,Entradas!E36<0),"sí","no")
A19: Descomposición D7 recalculada (ΔH = h̄·ΔP + P̄·Δh)
A20: zona y periodo | B20: H0 | C20: H1 | D20: P0 | E20: P1 | F20: ΔH | G20: componente población | H20: componente jefatura | I20: % población | J20: control: % población publicado
A21: ES 11-21 | B21: =Entradas!C49 | C21: =Entradas!C50 | D21: =Entradas!C51 | E21: =Entradas!C52 | F21: =C21-B21 | G21: =(B21/D21+C21/E21)/2*(E21-D21) | H21: =(D21+E21)/2*(C21/E21-B21/D21) | I21: =100*G21/F21 | J21: =Entradas!C53
A22: ES 22-25 | B22: =Entradas!C55 | C22: =Entradas!C56 | D22: =Entradas!C57 | E22: =Entradas!C58 | F22: =C22-B22 | G22: =(B22/D22+C22/E22)/2*(E22-D22) | H22: =(D22+E22)/2*(C22/E22-B22/D22) | I22: =100*G22/F22 | J22: =Entradas!C59
A23: CV 11-21 | B23: =Entradas!C37 | C23: =Entradas!C38 | D23: =Entradas!C39 | E23: =Entradas!C40 | F23: =C23-B23 | G23: =(B23/D23+C23/E23)/2*(E23-D23) | H23: =(D23+E23)/2*(C23/E23-B23/D23) | I23: =100*G23/F23 | J23: =Entradas!C41
A24: CV 22-25 | B24: =Entradas!C43 | C24: =Entradas!C44 | D24: =Entradas!C45 | E24: =Entradas!C46 | F24: =C24-B24 | G24: =(B24/D24+C24/E24)/2*(E24-D24) | H24: =(D24+E24)/2*(C24/E24-B24/D24) | I24: =100*G24/F24 | J24: =Entradas!C47

Sheet Resumen
A1: Afirmación evaluada | B1: Cifra principal | C1: Capa | D1: id
A2: Topes Ley 11/2020: renta de contratos nuevos (ATT, %) | B2: =Entradas!C15 | C2: =Entradas!J15 | D2: V9-D1b-renta-att
A3: Zonas tensionadas Cataluña: renta (ATT, %) | B3: =Entradas!C6 | C3: =Entradas!J6 | D3: V9-D1a-renta-att
A4: Turísticos × reapertura: renta (% por DE de dosis) | B4: =Entradas!C23 | C4: =Entradas!J23 | D4: V9-D2-renta-reap
A5: Inmigración: IPC alquiler (% por punto) | B5: =Entradas!C28 | C5: =Entradas!J28 | D5: V9-D4-ipc-replica
A6: Tipos × tipo variable: precio a 4 trimestres (%) | B6: =Entradas!C35 | C6: =Entradas!J35 | D6: V9-D5-precio-h4
A7: Hogares 2022-2025: componente población (%) | B7: =Entradas!C59 | C7: =Entradas!J59 | D7: V9-D7-ES-2225-cuota-pob
A8: Resultados en C3/C3s | B8: =Entradas!C62 | C8: =Entradas!J62 | D8: V9-NC3
