Workbook

Sheet revision
A1: id | B1: enunciado (tal como se publica) | C1: valor | D1: mínimo | E1: máximo | F1: unidad | G1: periodo | H1: capa | I1: fuente(s) | J1: organismo | K1: URL de la fuente | L1: ficha del anexo | M1: amplitud del rango | N1: valor comprobado (revisor) | O1: ¿coincide? (S/N) | P1: comentario (revisor)
A2: V10-ATL-A1 | B2: Sobrecarga del gasto en vivienda (>40 % de la renta), personas en alquiler de mercado: 26,8 % (24,4-29,2 %) (2025; INE ECV (microdatos), cálculo propio; contraste Eurostat ilc_lvho07c; dato de ECV 2025; C1) | C2: 26.7965 | D2: 24.4022 | E2: 29.1907 | F2: % | G2: 2025 | H2: C1 | I2: INE ECV (microdatos), cálculo propio; contraste Eurostat ilc_lvho07c | J2: INE | K2: =IFERROR(INDEX(fuentes!$B$2:$B$7,MATCH(J2,fuentes!$A$2:$A$7,0)),"—") | L2: script de origen: output/v10/atlas/hechos.json:V10-ATL-A1 | M2: =IF(AND(ISNUMBER(D2),ISNUMBER(E2)),E2-D2,"")
A3: A23-P2 | B3: Precio de compra, núcleo MIVAU/Notariado/Registradores 2015-2025: 47,2 % (44,2-56,1 %) (2015-2025 (media anual); MIVAU valor tasado; Notariado CGN; Registradores opendata; dato de 2025 (anual); C1) | C3: 47.2 | D3: 44.2 | E3: 56.1 | F3: % | G3: 2015-2025 (media anual) | H3: C1 | I3: MIVAU valor tasado; Notariado CGN; Registradores opendata | J3: MIVAU | K3: =IFERROR(INDEX(fuentes!$B$2:$B$7,MATCH(J3,fuentes!$A$2:$A$7,0)),"—") | L3: A8 · metodologia/anexo_metodologico.md#a8-a23-p2-precio-de-compra-variación-2015-2025-núcleo-mivau-notariado-y-registradores | M3: =IF(AND(ISNUMBER(D3),ISNUMBER(E3)),E3-D3,"")
A4: V9-D7-c1-dif | B4: Hogares 2021: ECP (1-1-2022) frente a censo 2021 (viviendas principales), diferencia: 1,5 % (2021; INE censo 2021; INE ECP; dato de 2022T1; C1) | C4: 1.54 | F4: % | G4: 2021 | H4: C1 | I4: INE censo 2021; INE ECP | J4: INE | K4: =IFERROR(INDEX(fuentes!$B$2:$B$7,MATCH(J4,fuentes!$A$2:$A$7,0)),"—") | L4: script de origen: output/v9/F5/hechos.json:V9-D7-c1-dif | M4: =IF(AND(ISNUMBER(D4),ISNUMBER(E4)),E4-D4,"")
A5: VER-A23-V2-2 | B5: Municipios de la C. Valenciana con renta de fianzas (GVA) en el análisis: 103 municipios (103-103 municipios) (2020-2025; output/v5/A23/calculos.json:gva_municipios_n; dato de 2025; C1) | C5: 103 | D5: 103 | E5: 103 | F5: municipios | G5: 2020-2025 | H5: C1 | I5: output/v5/A23/calculos.json:gva_municipios_n | J5: GVA | K5: =IFERROR(INDEX(fuentes!$B$2:$B$7,MATCH(J5,fuentes!$A$2:$A$7,0)),"—") | L5: script de origen: output/v6_3/VER/hechos.json:VER-A23-V2-2 | M5: =IF(AND(ISNUMBER(D5),ISNUMBER(E5)),E5-D5,"")
A6: V10-ATL-A2 | B6: Sobrecarga del gasto en vivienda (>40 % de la renta), total de la población: 7,2 % (6,7-7,7 %) (2025; INE ECV (microdatos); contraste Eurostat ilc_lvho07a; dato de ECV 2025; C1) | C6: 7.172 | D6: 6.6701 | E6: 7.6739 | F6: % | G6: 2025 | H6: C1 | I6: INE ECV (microdatos); contraste Eurostat ilc_lvho07a | J6: INE | K6: =IFERROR(INDEX(fuentes!$B$2:$B$7,MATCH(J6,fuentes!$A$2:$A$7,0)),"—") | L6: script de origen: output/v10/atlas/hechos.json:V10-ATL-A2 | M6: =IF(AND(ISNUMBER(D6),ISNUMBER(E6)),E6-D6,"")
A7: E-T7-prod | B7: Viviendas terminadas al año, España con País Vasco y Navarra (mín. y máx. anual): 78.810-100.980 viviendas/año (2019-2024; MIVAU terminadas libres y protegidas; dato de 2024-12-31; C1) | D7: 78810 | E7: 100980 | F7: viviendas/año | G7: 2019-2024 | H7: C1 | I7: MIVAU terminadas libres y protegidas | J7: MIVAU | K7: =IFERROR(INDEX(fuentes!$B$2:$B$7,MATCH(J7,fuentes!$A$2:$A$7,0)),"—") | L7: script de origen: output/v5/E/hechos.json:E-T7-prod | M7: =IF(AND(ISNUMBER(D7),ISNUMBER(E7)),E7-D7,"")
A8: V8-M8-cv-p03-P5-acum-alt | B8: Variación acumulada observada del precio real de compra en provincia de Alicante (03) en P5 con la segunda fuente (Registradores precio/m2 (4 trimestres, deflactado); pp log): 20,3 pp (P5 (2022T3-último dato); M8 descriptivo; Registradores precio/m2 (4 trimestres, deflactado); dato de 2026T2; C1) | C8: 20.30131 | F8: pp | G8: P5 (2022T3-último dato) | H8: C1 | I8: M8 descriptivo; Registradores precio/m2 (4 trimestres, deflactado) | J8: Registradores | K8: =IFERROR(INDEX(fuentes!$B$2:$B$7,MATCH(J8,fuentes!$A$2:$A$7,0)),"—") | L8: script de origen: output/v8/F6/hechos.json:V8-M8-cv-p03-P5-acum-alt | M8: =IF(AND(ISNUMBER(D8),ISNUMBER(E8)),E8-D8,"")
A9: dh_2125 | B9: Aumento del número de hogares: 997.586 hogares (981.823-1.013.350 hogares) (2021-2025; INE ECP y EPA (sin corrección: los dos extremos son posteriores a la ruptura de 2021; ventanas distintas: stock a 1 de enero en la ECP y media anual en la EPA, v7.1 K4b-dh); dato de 2025T1; C1) | C9: 997586.5 | D9: 981823 | E9: 1013350 | F9: hogares | G9: 2021-2025 | H9: C1 | I9: INE ECP y EPA (sin corrección: los dos extremos son posteriores a la ruptura de 2021; ventanas distintas: stock a 1 de enero en la ECP y media anual en la EPA, v7.1 K4b-dh) | J9: INE | K9: =IFERROR(INDEX(fuentes!$B$2:$B$7,MATCH(J9,fuentes!$A$2:$A$7,0)),"—") | L9: A1 · metodologia/anexo_metodologico.md#a1-dh_2125-aumento-del-número-de-hogares-2021-2025 | M9: =IF(AND(ISNUMBER(D9),ISNUMBER(E9)),E9-D9,"")
A10: A23-A9 | B10: Contratos nuevos Cataluña 2021-2024: IPVA nuevo e Incasòl: 16,9 % (16,6-17,2 %) (2021-2024; INE IPVA (AEAT); Incasòl; dato de 2024; C1) | C10: 16.9 | D10: 16.6 | E10: 17.2 | F10: % | G10: 2021-2024 | H10: C1 | I10: INE IPVA (AEAT); Incasòl | J10: INE | K10: =IFERROR(INDEX(fuentes!$B$2:$B$7,MATCH(J10,fuentes!$A$2:$A$7,0)),"—") | L10: script de origen: output/v5/A23/hechos.json:A23-A9 | M10: =IF(AND(ISNUMBER(D10),ISNUMBER(E10)),E10-D10,"")
A11: V8-M8-cv-p12-P5-acum-alt | B11: Variación acumulada observada del precio real de compra en provincia de Castellón (12) en P5 con la segunda fuente (Registradores precio/m2 (4 trimestres, deflactado); pp log): 10,9 pp (P5 (2022T3-último dato); M8 descriptivo; Registradores precio/m2 (4 trimestres, deflactado); dato de 2026T2; C1) | C11: 10.885294 | F11: pp | G11: P5 (2022T3-último dato) | H11: C1 | I11: M8 descriptivo; Registradores precio/m2 (4 trimestres, deflactado) | J11: Registradores | K11: =IFERROR(INDEX(fuentes!$B$2:$B$7,MATCH(J11,fuentes!$A$2:$A$7,0)),"—") | L11: script de origen: output/v8/F6/hechos.json:V8-M8-cv-p12-P5-acum-alt | M11: =IF(AND(ISNUMBER(D11),ISNUMBER(E11)),E11-D11,"")
A12: B1-H4 | B12: Crecimiento de hogares proyectado (INE, 10 años): 1.720.537 hogares (1.308.531-1.772.410 hogares) (2026-2035; INE Proyección de Hogares 54562; INE Proyecciones de Población 36726; dato de 2026-10-10 (descarga); INE proyecciones 2026-06; Censo 2021-11; MIVAU/Catastro hasta 2025; C2) | C12: 1720537 | D12: 1308531.1 | E12: 1772410.4 | F12: hogares | G12: 2026-2035 | H12: C2 | I12: INE Proyección de Hogares 54562; INE Proyecciones de Población 36726 | J12: INE | K12: =IFERROR(INDEX(fuentes!$B$2:$B$7,MATCH(J12,fuentes!$A$2:$A$7,0)),"—") | L12: A13-A14 · metodologia/anexo_metodologico.md#a13-a14-b1-h4-y-e-b1-f-crecimiento-de-hogares-proyectado-2026-2035 | M12: =IF(AND(ISNUMBER(D12),ISNUMBER(E12)),E12-D12,"")
A13: L3-DEF-2124-SENS | B13: Sensibilidad: déficit 2021-2024 sin bajas sin las dos variantes que conservan el salto de la EPA (a y d1): 653.456 viviendas (596.371-710.542 viviendas) (2021-2024; ídem, sin variantes a y d1; dato de 2024T4; C2) | C13: 653456 | D13: 596371 | E13: 710542 | F13: viviendas | G13: 2021-2024 | H13: C2 | I13: ídem, sin variantes a y d1 | J13: propio (elaboración del proyecto) | K13: =IFERROR(INDEX(fuentes!$B$2:$B$7,MATCH(J13,fuentes!$A$2:$A$7,0)),"—") | L13: script de origen: output/v6_2/L3/hechos.json:L3-DEF-2124-SENS | M13: =IF(AND(ISNUMBER(D13),ISNUMBER(E13)),E13-D13,"")
A14: VER-B4-V1-1 | B14: Aumento de la población extranjera 2014-2019 (denominador de la cota de cantidad): 174.410 personas (174.410-174.410 personas) (2014-2019; output/v4/M2/hechos.json:magnitud[2014-2019].delta_poblacion_extranjera; dato de 2019; C2) | C14: 174410 | D14: 174410 | E14: 174410 | F14: personas | G14: 2014-2019 | H14: C2 | I14: output/v4/M2/hechos.json:magnitud[2014-2019].delta_poblacion_extranjera | J14: propio (elaboración del proyecto) | K14: =IFERROR(INDEX(fuentes!$B$2:$B$7,MATCH(J14,fuentes!$A$2:$A$7,0)),"—") | L14: script de origen: output/v6_3/VER/hechos.json:VER-B4-V1-1 | M14: =IF(AND(ISNUMBER(D14),ISNUMBER(E14)),E14-D14,"")
A15: VER-B4-V2-1 | B15: Cota C2 de viviendas de alquiler absorbidas por turismo, sustitución 1:1: 81.771 viviendas (81.771-81.771 viviendas) (2020M08-2024M08; output/v3/PB/cotas.json:B1-nac-cantidad-viviendas; dato de 2024-08; C2) | C15: 81771 | D15: 81771 | E15: 81771 | F15: viviendas | G15: 2020M08-2024M08 | H15: C2 | I15: output/v3/PB/cotas.json:B1-nac-cantidad-viviendas | J15: propio (elaboración del proyecto) | K15: =IFERROR(INDEX(fuentes!$B$2:$B$7,MATCH(J15,fuentes!$A$2:$A$7,0)),"—") | L15: script de origen: output/v6_3/VER/hechos.json:VER-B4-V2-1 | M15: =IF(AND(ISNUMBER(D15),ISNUMBER(E15)),E15-D15,"")
A16: L3-DEF-2124-SINBAJAS | B16: Déficit acumulado 2021-2024 sin bajas (todas las variantes de corrección EPA y de terminadas): 549.952 viviendas (389.361-710.542 viviendas) (2021-2024; hogares: EPA (varias correcciones) y ECP; terminadas: MIVAU y Catastro; dato de 2024T4; C2) | C16: 549952 | D16: 389361 | E16: 710542 | F16: viviendas | G16: 2021-2024 | H16: C2 | I16: hogares: EPA (varias correcciones) y ECP; terminadas: MIVAU y Catastro | J16: MIVAU | K16: =IFERROR(INDEX(fuentes!$B$2:$B$7,MATCH(J16,fuentes!$A$2:$A$7,0)),"—") | L16: A5 · metodologia/anexo_metodologico.md#a5-l3-def-2124-sinbajas-déficit-2021-2024-sin-bajas-todas-las-variantes-v62 | M16: =IF(AND(ISNUMBER(D16),ISNUMBER(E16)),E16-D16,"")
A17: T4-H3 | B17: Dirección nacional del déficit 2025-2030 en toda la rejilla (empeora); provincias que empeoran / mejoran / indeterminadas: 15 provincias (0-37 provincias) (2025-2030; B2; T1; T2; INE 54562; MIVAU; dato de 2025 (ECP y MIVAU); proyecciones INE 54562 y 36726 de 2026-06-17; C2) | C17: 15 | D17: 0 | E17: 37 | F17: provincias | G17: 2025-2030 | H17: C2 | I17: B2; T1; T2; INE 54562; MIVAU | J17: INE | K17: =IFERROR(INDEX(fuentes!$B$2:$B$7,MATCH(J17,fuentes!$A$2:$A$7,0)),"—") | L17: script de origen: output/v5_1/T4/hechos.json:T4-H3 | M17: =IF(AND(ISNUMBER(D17),ISNUMBER(E17)),E17-D17,"")
A18: B2-H3 | B18: Crecimiento de hogares proyectado INE 2026-2030: 1.024.156 hogares (819.421-1.060.364 hogares) (1-ene-2026 a 1-ene-2031; INE 54562; INE 36726; dato de INE 2026-06-17; C2) | C18: 1024156 | D18: 819421 | E18: 1060364 | F18: hogares | G18: 1-ene-2026 a 1-ene-2031 | H18: C2 | I18: INE 54562; INE 36726 | J18: INE | K18: =IFERROR(INDEX(fuentes!$B$2:$B$7,MATCH(J18,fuentes!$A$2:$A$7,0)),"—") | L18: script de origen: output/v5/B2/hechos.json:B2-H3 | M18: =IF(AND(ISNUMBER(D18),ISNUMBER(E18)),E18-D18,"")
A19: B4-v3-vut-cantidad | B19: Máximo de stock de alquiler desplazado por viviendas turísticas: 2,7 % del stock de alquiler (2,4-2,7 % del stock de alquiler) (2020M08-2024M08; v3 PB (INE VUT, Censo 2021); dato de 2024-08; C2) | C19: 2.746 | D19: 2.423 | E19: 2.746 | F19: % del stock de alquiler | G19: 2020M08-2024M08 | H19: C2 | I19: v3 PB (INE VUT, Censo 2021) | J19: INE | K19: =IFERROR(INDEX(fuentes!$B$2:$B$7,MATCH(J19,fuentes!$A$2:$A$7,0)),"—") | L19: A11 · metodologia/anexo_metodologico.md#a11-b4-v3-vut-cantidad-máximo-de-stock-de-alquiler-desplazado-por-viviendas-turísticas | M19: =IF(AND(ISNUMBER(D19),ISNUMBER(E19)),E19-D19,"")
A20: latente_convivencia | B20: Demanda latente de jóvenes por convivencia con los padres (frente a 2008): 188.000-506.000 hogares (2008-2025; INE EPA y ECV (tasa de convivencia con los padres); dato de 2025; C2) | D20: 188000 | E20: 506000 | F20: hogares | G20: 2008-2025 | H20: C2 | I20: INE EPA y ECV (tasa de convivencia con los padres) | J20: INE | K20: =IFERROR(INDEX(fuentes!$B$2:$B$7,MATCH(J20,fuentes!$A$2:$A$7,0)),"—") | L20: A12 · metodologia/anexo_metodologico.md#a12-latente_convivencia-demanda-latente-de-jóvenes-por-convivencia-con-los-padres | M20: =IF(AND(ISNUMBER(D20),ISNUMBER(E20)),E20-D20,"")
A21: V8-SVAR-a-P2-demanda_vivienda-media | B21: Contribución de demanda específica de vivienda (shock de M2, no pre-registrado como factor) a la variación de alquiler real en P2 (media posterior; banda del 68 %; pp log×100; condicionado a las restricciones de signo y de cero de M2): -0,32 pp (-2,3 a 1,8 pp) (P2 (2008T3-2013T4); M2 SVAR bayesiano con restricciones de signo y de cero (descomposición histórica); nacional_q_v8; dato de 2026T1; C3s) | C21: -0.322677 | D21: -2.31858 | E21: 1.84846 | F21: pp | G21: P2 (2008T3-2013T4) | H21: C3s | I21: M2 SVAR bayesiano con restricciones de signo y de cero (descomposición histórica); nacional_q_v8 | J21: propio (elaboración del proyecto) | K21: =IFERROR(INDEX(fuentes!$B$2:$B$7,MATCH(J21,fuentes!$A$2:$A$7,0)),"—") | L21: script de origen: output/v8/F6/hechos.json:V8-SVAR-a-P2-demanda_vivienda-media | M21: =IF(AND(ISNUMBER(D21),ISNUMBER(E21)),E21-D21,"")
A22: V8-SVAR-c-P2-oferta-mediana | B22: Contribución de oferta a la variación de precio real de compra en P2 (mediana posterior; banda del 68 %; pp log×100; condicionado a las restricciones de signo y de cero de M2): -2,1 pp (-13,3 a 2,5 pp) (P2 (2008T3-2013T4); M2 SVAR bayesiano con restricciones de signo y de cero (descomposición histórica); nacional_q_v8; dato de 2026T1; C3s) | C22: -2.0535 | D22: -13.2992 | E22: 2.48894 | F22: pp | G22: P2 (2008T3-2013T4) | H22: C3s | I22: M2 SVAR bayesiano con restricciones de signo y de cero (descomposición histórica); nacional_q_v8 | J22: propio (elaboración del proyecto) | K22: =IFERROR(INDEX(fuentes!$B$2:$B$7,MATCH(J22,fuentes!$A$2:$A$7,0)),"—") | L22: script de origen: output/v8/F6/hechos.json:V8-SVAR-c-P2-oferta-mediana | M22: =IF(AND(ISNUMBER(D22),ISNUMBER(E22)),E22-D22,"")
A23: V8-SVAR-c-P3-demanda_vivienda-mediana | B23: Contribución de demanda específica de vivienda (shock de M2, no pre-registrado como factor) a la variación de precio real de compra en P3 (mediana posterior; banda del 68 %; pp log×100; condicionado a las restricciones de signo y de cero de M2): 0,53 pp (-7,2 a 9,0 pp) (P3 (2014T1-2019T4); M2 SVAR bayesiano con restricciones de signo y de cero (descomposición histórica); nacional_q_v8; dato de 2026T1; C3s) | C23: 0.532209 | D23: -7.20665 | E23: 8.99381 | F23: pp | G23: P3 (2014T1-2019T4) | H23: C3s | I23: M2 SVAR bayesiano con restricciones de signo y de cero (descomposición histórica); nacional_q_v8 | J23: propio (elaboración del proyecto) | K23: =IFERROR(INDEX(fuentes!$B$2:$B$7,MATCH(J23,fuentes!$A$2:$A$7,0)),"—") | L23: script de origen: output/v8/F6/hechos.json:V8-SVAR-c-P3-demanda_vivienda-mediana | M23: =IF(AND(ISNUMBER(D23),ISNUMBER(E23)),E23-D23,"")
A24: V8-QNA-pp-c-P4 | B24: Cuota no atribuida de precio real de compra en P4 en puntos (banda del 68 %; condicionado a las restricciones de signo y de cero de M2): -0,75 pp (-16,1 a 12,0 pp) (P4 (2020T2-2022T2); F5 (regla del §9 sobre M2, M6, M5, M4, M7); nacional_q_v8; dato de 2026T1; C3s) | C24: -0.752543 | D24: -16.0794 | E24: 11.9989 | F24: pp | G24: P4 (2020T2-2022T2) | H24: C3s | I24: F5 (regla del §9 sobre M2, M6, M5, M4, M7); nacional_q_v8 | J24: propio (elaboración del proyecto) | K24: =IFERROR(INDEX(fuentes!$B$2:$B$7,MATCH(J24,fuentes!$A$2:$A$7,0)),"—") | L24: script de origen: output/v8/F6/hechos.json:V8-QNA-pp-c-P4 | M24: =IF(AND(ISNUMBER(D24),ISNUMBER(E24)),E24-D24,"")
A25: V8-PFSTAR-c-P4 | B25: Probabilidad posterior de que empleo y renta sea el factor de mayor contribución en precio real de compra en P4 (P(f*); condicionado a las restricciones de signo y de cero de M2): 25,9 % (P4 (2020T2-2022T2); F5 (regla del §9 sobre M2, M6, M5, M4, M7); nacional_q_v8; dato de 2026T1; C3s) | C25: 25.9322 | F25: % | G25: P4 (2020T2-2022T2) | H25: C3s | I25: F5 (regla del §9 sobre M2, M6, M5, M4, M7); nacional_q_v8 | J25: propio (elaboración del proyecto) | K25: =IFERROR(INDEX(fuentes!$B$2:$B$7,MATCH(J25,fuentes!$A$2:$A$7,0)),"—") | L25: script de origen: output/v8/F6/hechos.json:V8-PFSTAR-c-P4 | M25: =IF(AND(ISNUMBER(D25),ISNUMBER(E25)),E25-D25,"")
A26: V8-SVAR-a-P2-demografia-mediana | B26: Contribución de demografía a la variación de alquiler real en P2 (mediana posterior; banda del 68 %; pp log×100; condicionado a las restricciones de signo y de cero de M2): 0,22 pp (-1,9 a 2,7 pp) (P2 (2008T3-2013T4); M2 SVAR bayesiano con restricciones de signo y de cero (descomposición histórica); nacional_q_v8; dato de 2026T1; C3s) | C26: 0.223717 | D26: -1.85844 | E26: 2.70734 | F26: pp | G26: P2 (2008T3-2013T4) | H26: C3s | I26: M2 SVAR bayesiano con restricciones de signo y de cero (descomposición histórica); nacional_q_v8 | J26: propio (elaboración del proyecto) | K26: =IFERROR(INDEX(fuentes!$B$2:$B$7,MATCH(J26,fuentes!$A$2:$A$7,0)),"—") | L26: script de origen: output/v8/F6/hechos.json:V8-SVAR-a-P2-demografia-mediana | M26: =IF(AND(ISNUMBER(D26),ISNUMBER(E26)),E26-D26,"")
A27: V8-QNA-pp-a-P3 | B27: Cuota no atribuida de alquiler real en P3 en puntos (banda del 68 %; condicionado a las restricciones de signo y de cero de M2): -4,6 pp (-11,6 a 2,9 pp) (P3 (2014T1-2019T4); F5 (regla del §9 sobre M2, M6, M5, M4, M7); nacional_q_v8; dato de 2026T1; C3s) | C27: -4.56136 | D27: -11.564 | E27: 2.85465 | F27: pp | G27: P3 (2014T1-2019T4) | H27: C3s | I27: F5 (regla del §9 sobre M2, M6, M5, M4, M7); nacional_q_v8 | J27: propio (elaboración del proyecto) | K27: =IFERROR(INDEX(fuentes!$B$2:$B$7,MATCH(J27,fuentes!$A$2:$A$7,0)),"—") | L27: script de origen: output/v8/F6/hechos.json:V8-QNA-pp-a-P3 | M27: =IF(AND(ISNUMBER(D27),ISNUMBER(E27)),E27-D27,"")
A28: V8-SVAR-c-P3-demografia-mediana | B28: Contribución de demografía a la variación de precio real de compra en P3 (mediana posterior; banda del 68 %; pp log×100; condicionado a las restricciones de signo y de cero de M2): -0,18 pp (-6,6 a 6,8 pp) (P3 (2014T1-2019T4); M2 SVAR bayesiano con restricciones de signo y de cero (descomposición histórica); nacional_q_v8; dato de 2026T1; C3s) | C28: -0.177369 | D28: -6.57831 | E28: 6.81486 | F28: pp | G28: P3 (2014T1-2019T4) | H28: C3s | I28: M2 SVAR bayesiano con restricciones de signo y de cero (descomposición histórica); nacional_q_v8 | J28: propio (elaboración del proyecto) | K28: =IFERROR(INDEX(fuentes!$B$2:$B$7,MATCH(J28,fuentes!$A$2:$A$7,0)),"—") | L28: script de origen: output/v8/F6/hechos.json:V8-SVAR-c-P3-demografia-mediana | M28: =IF(AND(ISNUMBER(D28),ISNUMBER(E28)),E28-D28,"")
A29: V8-H8-4-est | B29: H8-4: En P2, la contribucion conjunta de credito y tipos y de actividad y renta al precio real de compra es negativa (contribución acumulada del periodo, intervalo al 95 %; condicionado a las restricciones de signo y de cero de M2): -19,2 pp (-57,3 a 9,9 pp) (P2 (2008T3-2013T4); M2 SVAR con restricciones de signo y de cero; dato de 2026T1; C3s) | C29: -19.231804 | D29: -57.256675 | E29: 9.8780019 | F29: pp | G29: P2 (2008T3-2013T4) | H29: C3s | I29: M2 SVAR con restricciones de signo y de cero | J29: propio (elaboración del proyecto) | K29: =IFERROR(INDEX(fuentes!$B$2:$B$7,MATCH(J29,fuentes!$A$2:$A$7,0)),"—") | L29: script de origen: output/v8/F6/hechos.json:V8-H8-4-est | M29: =IF(AND(ISNUMBER(D29),ISNUMBER(E29)),E29-D29,"")
A30: V8-SVAR-a-P3-credito_tipos-mediana | B30: Contribución de crédito y tipos a la variación de alquiler real en P3 (mediana posterior; banda del 68 %; pp log×100; condicionado a las restricciones de signo y de cero de M2): 0,16 pp (-1,7 a 2,7 pp) (P3 (2014T1-2019T4); M2 SVAR bayesiano con restricciones de signo y de cero (descomposición histórica); nacional_q_v8; dato de 2026T1; C3s) | C30: 0.161881 | D30: -1.73676 | E30: 2.67511 | F30: pp | G30: P3 (2014T1-2019T4) | H30: C3s | I30: M2 SVAR bayesiano con restricciones de signo y de cero (descomposición histórica); nacional_q_v8 | J30: propio (elaboración del proyecto) | K30: =IFERROR(INDEX(fuentes!$B$2:$B$7,MATCH(J30,fuentes!$A$2:$A$7,0)),"—") | L30: script de origen: output/v8/F6/hechos.json:V8-SVAR-a-P3-credito_tipos-mediana | M30: =IF(AND(ISNUMBER(D30),ISNUMBER(E30)),E30-D30,"")
A31: V8-M7-var-c-P5-bis_hpi_xm_real-bh | B31: Multiverso por variable: % de especificaciones significativas tras BH (q = 0,10), precio real de la vivienda de otros países (BIS) (factor europeo), precio real de compra, P5 (2022T3-último dato); signo orientado positivo (más de la variable, más presión al alza); asociación, sin lectura causal: 58,9 % (P5 (2022T3-último dato); M7 multiverso estructurado (lectura por variable); dato de 2026T2; C4) | C31: 58.854167 | F31: % | G31: P5 (2022T3-último dato) | H31: C4 | I31: M7 multiverso estructurado (lectura por variable) | J31: propio (elaboración del proyecto) | K31: =IFERROR(INDEX(fuentes!$B$2:$B$7,MATCH(J31,fuentes!$A$2:$A$7,0)),"—") | L31: script de origen: output/v8/F6/hechos.json:V8-M7-var-c-P5-bis_hpi_xm_real-bh | M31: =IF(AND(ISNUMBER(D31),ISNUMBER(E31)),E31-D31,"")
A32: E-E1-B2-D2030-c | B32: Déficit nacional a fin de 2030, escenario (c) de terminadas (central): 1.276.238 viviendas (1-ene-2026 a 31-dic-2030; B2; dato de 2026-10-10; C4) | C32: 1276238 | F32: viviendas | G32: 1-ene-2026 a 31-dic-2030 | H32: C4 | I32: B2 | J32: propio (elaboración del proyecto) | K32: =IFERROR(INDEX(fuentes!$B$2:$B$7,MATCH(J32,fuentes!$A$2:$A$7,0)),"—") | L32: script de origen: output/v5/E/hechos.json:E-E1-B2-D2030-c | M32: =IF(AND(ISNUMBER(D32),ISNUMBER(E32)),E32-D32,"")
A33: D1-H02 | B33: Instrumentos con 'No evaluable' en el signo: 18 instrumentos (2026-10; output/v5/D1/matriz_instrumentos.csv; dato de 2026-10-10; C4) | C33: 18 | F33: instrumentos | G33: 2026-10 | H33: C4 | I33: output/v5/D1/matriz_instrumentos.csv | J33: propio (elaboración del proyecto) | K33: =IFERROR(INDEX(fuentes!$B$2:$B$7,MATCH(J33,fuentes!$A$2:$A$7,0)),"—") | L33: script de origen: output/v5/D1/hechos.json:D1-H02 | M33: =IF(AND(ISNUMBER(D33),ISNUMBER(E33)),E33-D33,"")
A34: V8-M9-shap-a-P4-turismo | B34: Sensibilidad no principal (NaN nativos), media de las 6 CCAA con datos de turismo; no comparable con la variación nacional: Contribución SHAP media de turismo a la variación de alquiler real en P4 en el panel de CCAA (banda del 68 % por bootstrap de bloques; contraste del modelo de aprendizaje automático, no es un efecto): 0,11 pp (-0,53 a 0,30 pp) (P4 (2020T2-2022T2); M9 aprendizaje automático interpretable (LightGBM, GAM); contraste, no causal; dato de 2026T2; C4) | C34: 0.10863515 | D34: -0.53102437 | E34: 0.29951276 | F34: pp | G34: P4 (2020T2-2022T2) | H34: C4 | I34: M9 aprendizaje automático interpretable (LightGBM, GAM); contraste, no causal | J34: propio (elaboración del proyecto) | K34: =IFERROR(INDEX(fuentes!$B$2:$B$7,MATCH(J34,fuentes!$A$2:$A$7,0)),"—") | L34: script de origen: output/v8/F6/hechos.json:V8-M9-shap-a-P4-turismo | M34: =IF(AND(ISNUMBER(D34),ISNUMBER(E34)),E34-D34,"")
A35: A4-prov-2021-2025-c2-robustas | B35: Provincias en clase 2 con clase estable en todo el rango de costes, márgenes y holguras (diagnóstico): 3 provincias (2021-2025; output/v5/A4; dato de 2025; C4) | C35: 3 | F35: provincias | G35: 2021-2025 | H35: C4 | I35: output/v5/A4 | J35: propio (elaboración del proyecto) | K35: =IFERROR(INDEX(fuentes!$B$2:$B$7,MATCH(J35,fuentes!$A$2:$A$7,0)),"—") | L35: script de origen: output/v5/A4/hechos.json:A4-prov-2021-2025-c2-robustas | M35: =IF(AND(ISNUMBER(D35),ISNUMBER(E35)),E35-D35,"")
A36: V8-M6-colpob-P5-corr | B36: Correlación entre el crecimiento interanual de la población total y el de la población extranjera (INE), P5 (2022T3-último dato) (n = 16 trimestres; diagnóstico descriptivo): 0,78 (P5 (2022T3-último dato); nacional_q_v8 (d4_ln_pob_total, d4_ln_pob_extranj_ine); dato de 2026T2; C4) | C36: 0.77862358 | F36: proporción | G36: P5 (2022T3-último dato) | H36: C4 | I36: nacional_q_v8 (d4_ln_pob_total, d4_ln_pob_extranj_ine) | J36: INE | K36: =IFERROR(INDEX(fuentes!$B$2:$B$7,MATCH(J36,fuentes!$A$2:$A$7,0)),"—") | L36: script de origen: output/v8/F6/hechos.json:V8-M6-colpob-P5-corr | M36: =IF(AND(ISNUMBER(D36),ISNUMBER(E36)),E36-D36,"")
A37: V8-M8-cv-p46-P1-total | B37: Variación observada del precio real de compra en provincia de València (46) en P1 (pp, log×100; media interanual × T/4: aproximación, no es el acumulado observado): 85,9 pp (P1 (1995T1-2007T4); M8 regional (provincias de la Comunitat Valenciana y València ciudad; cruce por código INE); dato de 2026T2; C4) | C37: 85.891855 | F37: pp | G37: P1 (1995T1-2007T4) | H37: C4 | I37: M8 regional (provincias de la Comunitat Valenciana y València ciudad; cruce por código INE) | J37: INE | K37: =IFERROR(INDEX(fuentes!$B$2:$B$7,MATCH(J37,fuentes!$A$2:$A$7,0)),"—") | L37: script de origen: output/v8/F6/hechos.json:V8-M8-cv-p46-P1-total | M37: =IF(AND(ISNUMBER(D37),ISNUMBER(E37)),E37-D37,"")
A38: E-v3-H3-1 | B38: VUT por 100 viviendas y alquiler SERPAVI (FE sección, nacional), coeficiente v3: 0,26 milésimas de log-punto por VUT/100 viv. (-0,74 a 1,3 milésimas de log-punto por VUT/100 viv.) (2021-2024; INE VUT; SERPAVI; dato de 2024; C4) | C38: 0.25986793 | D38: -0.74415675 | E38: 1.2638926 | F38: milésimas de log-punto por VUT/100 viv. | G38: 2021-2024 | H38: C4 | I38: INE VUT; SERPAVI | J38: INE | K38: =IFERROR(INDEX(fuentes!$B$2:$B$7,MATCH(J38,fuentes!$A$2:$A$7,0)),"—") | L38: script de origen: output/v5/E/hechos.json:E-v3-H3-1 | M38: =IF(AND(ISNUMBER(D38),ISNUMBER(E38)),E38-D38,"")
A39: D2-H09 | B39: Necesidad anual de vivienda, provincias de clase A4 9 (T3 sin X, v6.3): 726,0 viviendas/año (293,0-919,0 viviendas/año) (2026-2035; output/v5_1/T3; output/v5/A4; dato de 2026-10-10; C4) | C39: 726 | D39: 293 | E39: 919 | F39: viviendas/año | G39: 2026-2035 | H39: C4 | I39: output/v5_1/T3; output/v5/A4 | J39: propio (elaboración del proyecto) | K39: =IFERROR(INDEX(fuentes!$B$2:$B$7,MATCH(J39,fuentes!$A$2:$A$7,0)),"—") | L39: script de origen: output/v5/D2/hechos.json:D2-H09 | M39: =IF(AND(ISNUMBER(D39),ISNUMBER(E39)),E39-D39,"")
A40: CA-CR-saldo-pico | B40: Saldo de crédito a construcción + actividades inmobiliarias: máximo 2005-2025: 471,8 miles de millones de euros (2008Q3; BdE be0418; dato de 2026-06-01; C4) | C40: 471.807 | F40: miles de millones de euros | G40: 2008Q3 | H40: C4 | I40: BdE be0418 | J40: BdE | K40: =IFERROR(INDEX(fuentes!$B$2:$B$7,MATCH(J40,fuentes!$A$2:$A$7,0)),"—") | L40: script de origen: output/v5/CA/hechos.json:CA-CR-saldo-pico | M40: =IF(AND(ISNUMBER(D40),ISNUMBER(E40)),E40-D40,"")
...

Sheet fuentes
A1: organismo | B1: url
A2: BdE | B2: https://www.bde.es/webbe/es/estadisticas/
A3: GVA | B3: https://dadesobertes.gva.es
A4: INE | B4: https://www.ine.es
A5: MIVAU | B5: https://www.mivau.gob.es/el-ministerio/informacion-estadistica
A6: Registradores | B6: https://www.registradores.org/actualidad/portal-estadistico-registral
A7: propio (elaboración del proyecto) | B7: —

Sheet leeme
A1: Hoja para la revisión externa (versión pública del proyecto «Vivienda en España: base de evidencia reproducible»).
A2: Una fila por cifra de la muestra (40 cifras de output/v5/cifras_clave.csv, estratificadas por capa, SEED=20261010).
A3: Colores: azul = dato fijo copiado de cifras_clave (fuente en la columna «fuente(s)»); negro = cálculo; verde = viene de otra pestaña.
A4: Rellene solo las tres últimas columnas de «revision». Guía: revision_externa/guia.md.
