Workbook

Sheet Resumen
A1: CCAA | B1: Variación IPV 2022T3-último | C1: Variación IPC alquiler 2022T3-último | D1: Mejor modelo compra (RMSE×100) | E1: Mejor modelo alquiler (RMSE×100)
A2: Andalucía | B2: ='01_Andalucia'!G6 | C2: ='01_Andalucia'!G9 | D2: ='01_Andalucia'!B13 | E2: ='01_Andalucia'!B12
A3: Aragón | B3: ='02_Aragon'!G6 | C3: ='02_Aragon'!G9 | D3: ='02_Aragon'!B13 | E3: ='02_Aragon'!B12
A4: Asturias | B4: ='03_Asturias'!G6 | C4: ='03_Asturias'!G9 | D4: ='03_Asturias'!B13 | E4: ='03_Asturias'!B12
A5: Illes Balears | B5: ='04_Illes_Balears'!G6 | C5: ='04_Illes_Balears'!G9 | D5: ='04_Illes_Balears'!B13 | E5: ='04_Illes_Balears'!B12
A6: Canarias | B6: ='05_Canarias'!G6 | C6: ='05_Canarias'!G9 | D6: ='05_Canarias'!B13 | E6: ='05_Canarias'!B12
A7: Cantabria | B7: ='06_Cantabria'!G6 | C7: ='06_Cantabria'!G9 | D7: ='06_Cantabria'!B13 | E7: ='06_Cantabria'!B12
A8: Castilla y León | B8: ='07_Castilla_y_Leon'!G6 | C8: ='07_Castilla_y_Leon'!G9 | D8: ='07_Castilla_y_Leon'!B13 | E8: ='07_Castilla_y_Leon'!B12
A9: Castilla-La Mancha | B9: ='08_Castilla_La_Mancha'!G6 | C9: ='08_Castilla_La_Mancha'!G9 | D9: ='08_Castilla_La_Mancha'!B13 | E9: ='08_Castilla_La_Mancha'!B12
A10: Cataluña | B10: ='09_Cataluna'!G6 | C10: ='09_Cataluna'!G9 | D10: ='09_Cataluna'!B13 | E10: ='09_Cataluna'!B12
A11: Comunitat Valenciana | B11: ='10_Comunitat_Valenciana'!G6 | C11: ='10_Comunitat_Valenciana'!G9 | D11: ='10_Comunitat_Valenciana'!B13 | E11: ='10_Comunitat_Valenciana'!B12
A12: Extremadura | B12: ='11_Extremadura'!G6 | C12: ='11_Extremadura'!G9 | D12: ='11_Extremadura'!B13 | E12: ='11_Extremadura'!B12
A13: Galicia | B13: ='12_Galicia'!G6 | C13: ='12_Galicia'!G9 | D13: ='12_Galicia'!B13 | E13: ='12_Galicia'!B12
A14: Comunidad de Madrid | B14: ='13_Comunidad_de_Madrid'!G6 | C14: ='13_Comunidad_de_Madrid'!G9 | D14: ='13_Comunidad_de_Madrid'!B13 | E14: ='13_Comunidad_de_Madrid'!B12
A15: Región de Murcia | B15: ='14_Region_de_Murcia'!G6 | C15: ='14_Region_de_Murcia'!G9 | D15: ='14_Region_de_Murcia'!B13 | E15: ='14_Region_de_Murcia'!B12
A16: Comunidad Foral de Navarra | B16: ='15_Comunidad_Foral_de_Navarra'!G6 | C16: ='15_Comunidad_Foral_de_Navarra'!G9 | D16: ='15_Comunidad_Foral_de_Navarra'!B13 | E16: ='15_Comunidad_Foral_de_Navarra'!B12
A17: País Vasco | B17: ='16_Pais_Vasco'!G6 | C17: ='16_Pais_Vasco'!G9 | D17: ='16_Pais_Vasco'!B13 | E17: ='16_Pais_Vasco'!B12
A18: La Rioja | B18: ='17_La_Rioja'!G6 | C18: ='17_La_Rioja'!G9 | D18: ='17_La_Rioja'!B13 | E18: ='17_La_Rioja'!B12
A19: Media simple de las 17 CCAA | B19: =AVERAGE(B2:B18) | C19: =AVERAGE(C2:C18)
A21: Enlaces en verde a cada hoja; la media es un cálculo de esta hoja. Fuente de las series: panel_ccaa_q_v7.csv (INE). informativo, muestra ya vista en v1

Sheet 01_Andalucia
A1: Andalucía (01): informativo, muestra ya vista en v1; C4; asociación
A3: Serie | B3: Periodo | C3: Inicio | D3: Valor inicio | E3: Fin | F3: Valor fin | G3: Variación | H3: Fuente
A4: IPV (INE) | B4: 2014T1-2019T4 | C4: 2014Q1 | D4: 53.316 | E4: 2019Q4 | F4: 66.17 | G4: =F4/D4-1 | H4: panel_ccaa_q_v7.csv, INE, hasta 2026Q2
A5: IPV (INE) | B5: 2020T1-2022T2 | C5: 2020Q1 | D5: 66.665 | E5: 2022Q2 | F5: 76.202 | G5: =F5/D5-1 | H5: panel_ccaa_q_v7.csv, INE, hasta 2026Q2
A6: IPV (INE) | B6: 2022T3-último | C6: 2022Q3 | D6: 77.432 | E6: 2026Q2 | F6: 110.903 | G6: =F6/D6-1 | H6: panel_ccaa_q_v7.csv, INE, hasta 2026Q2
A7: IPC alquiler (INE) | B7: 2014T1-2019T4 | C7: 2014Q1 | D7: 88.395 | E7: 2019Q4 | F7: 90.442 | G7: =F7/D7-1 | H7: panel_ccaa_q_v7.csv, INE, hasta 2026Q2
A8: IPC alquiler (INE) | B8: 2020T1-2022T2 | C8: 2020Q1 | D8: 90.660333 | E8: 2022Q2 | F8: 92.447667 | G8: =F8/D8-1 | H8: panel_ccaa_q_v7.csv, INE, hasta 2026Q2
A9: IPC alquiler (INE) | B9: 2022T3-último | C9: 2022Q3 | D9: 92.860667 | E9: 2026Q2 | F9: 102.28433 | G9: =F9/D9-1 | H9: panel_ccaa_q_v7.csv, INE, hasta 2026Q2
A11: Mercado | B11: Mejor modelo | C11: RMSE mejor ×100 | D11: RMSE base exigente ×100 | E11: Diferencia | F11: ¿Bate? | G11: Fuente
A12: alquiler | B12: gbm | C12: 0.40493616 | D12: 0.40029169 | E12: =D12-C12 | F12: =IF(E12>0,"sí","no") | G12: output/v7/R5/mejor_por_region.csv; informativo, muestra ya vista en v1
A13: compra | B13: ar4 | C13: 2.8633209 | D13: 2.7017662 | E13: =D13-C13 | F13: =IF(E13>0,"sí","no") | G13: output/v7/R5/mejor_por_region.csv; informativo, muestra ya vista en v1
A15: Mercado | B15: Spec | C15: φ (sin inferencia válida) | D15: Semivida (trim.) | E15: Fuente
A16: alquiler | B16: A | C16: 0.017087166 | D16: =IF(AND(C16<0,C16>-1),LN(0.5)/LN(1+C16),"NA") | E16: output/v7/R4/alquiler/velocidad_ajuste_region.csv
A17: alquiler | B17: B | C17: -0.033816071 | D17: =IF(AND(C17<0,C17>-1),LN(0.5)/LN(1+C17),"NA") | E17: output/v7/R4/alquiler/velocidad_ajuste_region.csv
A18: compra | B18: A | C18: -0.0083091968 | D18: =IF(AND(C18<0,C18>-1),LN(0.5)/LN(1+C18),"NA") | E18: output/v7/R4/compra/velocidad_ajuste_region.csv
A19: compra | B19: B | C19: -0.052744394 | D19: =IF(AND(C19<0,C19>-1),LN(0.5)/LN(1+C19),"NA") | E19: output/v7/R4/compra/velocidad_ajuste_region.csv

Sheet 02_Aragon
A1: Aragón (02): informativo, muestra ya vista en v1; C4; asociación
A3: Serie | B3: Periodo | C3: Inicio | D3: Valor inicio | E3: Fin | F3: Valor fin | G3: Variación | H3: Fuente
A4: IPV (INE) | B4: 2014T1-2019T4 | C4: 2014Q1 | D4: 57.002 | E4: 2019Q4 | F4: 68.594 | G4: =F4/D4-1 | H4: panel_ccaa_q_v7.csv, INE, hasta 2026Q2
A5: IPV (INE) | B5: 2020T1-2022T2 | C5: 2020Q1 | D5: 68.856 | E5: 2022Q2 | F5: 76.634 | G5: =F5/D5-1 | H5: panel_ccaa_q_v7.csv, INE, hasta 2026Q2
A6: IPV (INE) | B6: 2022T3-último | C6: 2022Q3 | D6: 77.47 | E6: 2026Q2 | F6: 113.472 | G6: =F6/D6-1 | H6: panel_ccaa_q_v7.csv, INE, hasta 2026Q2
A7: IPC alquiler (INE) | B7: 2014T1-2019T4 | C7: 2014Q1 | D7: 88.853667 | E7: 2019Q4 | F7: 90.847333 | G7: =F7/D7-1 | H7: panel_ccaa_q_v7.csv, INE, hasta 2026Q2
A8: IPC alquiler (INE) | B8: 2020T1-2022T2 | C8: 2020Q1 | D8: 91.211 | E8: 2022Q2 | F8: 93.299667 | G8: =F8/D8-1 | H8: panel_ccaa_q_v7.csv, INE, hasta 2026Q2
A9: IPC alquiler (INE) | B9: 2022T3-último | C9: 2022Q3 | D9: 93.648667 | E9: 2026Q2 | F9: 102.43967 | G9: =F9/D9-1 | H9: panel_ccaa_q_v7.csv, INE, hasta 2026Q2
A11: Mercado | B11: Mejor modelo | C11: RMSE mejor ×100 | D11: RMSE base exigente ×100 | E11: Diferencia | F11: ¿Bate? | G11: Fuente
A12: alquiler | B12: gbm | C12: 0.3902828 | D12: 0.35791855 | E12: =D12-C12 | F12: =IF(E12>0,"sí","no") | G12: output/v7/R5/mejor_por_region.csv; informativo, muestra ya vista en v1
A13: compra | B13: ar4 | C13: 2.7953331 | D13: 2.5633747 | E13: =D13-C13 | F13: =IF(E13>0,"sí","no") | G13: output/v7/R5/mejor_por_region.csv; informativo, muestra ya vista en v1
A15: Mercado | B15: Spec | C15: φ (sin inferencia válida) | D15: Semivida (trim.) | E15: Fuente
A16: alquiler | B16: A | C16: -0.10426318 | D16: =IF(AND(C16<0,C16>-1),LN(0.5)/LN(1+C16),"NA") | E16: output/v7/R4/alquiler/velocidad_ajuste_region.csv
A17: alquiler | B17: B | C17: -0.13428835 | D17: =IF(AND(C17<0,C17>-1),LN(0.5)/LN(1+C17),"NA") | E17: output/v7/R4/alquiler/velocidad_ajuste_region.csv
A18: compra | B18: A | C18: -0.21079545 | D18: =IF(AND(C18<0,C18>-1),LN(0.5)/LN(1+C18),"NA") | E18: output/v7/R4/compra/velocidad_ajuste_region.csv
A19: compra | B19: B | C19: -0.070111098 | D19: =IF(AND(C19<0,C19>-1),LN(0.5)/LN(1+C19),"NA") | E19: output/v7/R4/compra/velocidad_ajuste_region.csv

Sheet 03_Asturias
A1: Asturias (03): informativo, muestra ya vista en v1; C4; asociación
A3: Serie | B3: Periodo | C3: Inicio | D3: Valor inicio | E3: Fin | F3: Valor fin | G3: Variación | H3: Fuente
A4: IPV (INE) | B4: 2014T1-2019T4 | C4: 2014Q1 | D4: 60.686 | E4: 2019Q4 | F4: 70.069 | G4: =F4/D4-1 | H4: panel_ccaa_q_v7.csv, INE, hasta 2026Q2
A5: IPV (INE) | B5: 2020T1-2022T2 | C5: 2020Q1 | D5: 70.43 | E5: 2022Q2 | F5: 79.104 | G5: =F5/D5-1 | H5: panel_ccaa_q_v7.csv, INE, hasta 2026Q2
A6: IPV (INE) | B6: 2022T3-último | C6: 2022Q3 | D6: 79.578 | E6: 2026Q2 | F6: 114.014 | G6: =F6/D6-1 | H6: panel_ccaa_q_v7.csv, INE, hasta 2026Q2
A7: IPC alquiler (INE) | B7: 2014T1-2019T4 | C7: 2014Q1 | D7: 91.287667 | E7: 2019Q4 | F7: 93.312 | G7: =F7/D7-1 | H7: panel_ccaa_q_v7.csv, INE, hasta 2026Q2
A8: IPC alquiler (INE) | B8: 2020T1-2022T2 | C8: 2020Q1 | D8: 93.362 | E8: 2022Q2 | F8: 94.873 | G8: =F8/D8-1 | H8: panel_ccaa_q_v7.csv, INE, hasta 2026Q2
A9: IPC alquiler (INE) | B9: 2022T3-último | C9: 2022Q3 | D9: 95.296667 | E9: 2026Q2 | F9: 102.73867 | G9: =F9/D9-1 | H9: panel_ccaa_q_v7.csv, INE, hasta 2026Q2
A11: Mercado | B11: Mejor modelo | C11: RMSE mejor ×100 | D11: RMSE base exigente ×100 | E11: Diferencia | F11: ¿Bate? | G11: Fuente
A12: alquiler | B12: gbm | C12: 0.36822882 | D12: 0.34081573 | E12: =D12-C12 | F12: =IF(E12>0,"sí","no") | G12: output/v7/R5/mejor_por_region.csv; informativo, muestra ya vista en v1
A13: compra | B13: gbm | C13: 2.5943653 | D13: 2.3194484 | E13: =D13-C13 | F13: =IF(E13>0,"sí","no") | G13: output/v7/R5/mejor_por_region.csv; informativo, muestra ya vista en v1
A15: Mercado | B15: Spec | C15: φ (sin inferencia válida) | D15: Semivida (trim.) | E15: Fuente
A16: alquiler | B16: A | C16: 0.022297903 | D16: =IF(AND(C16<0,C16>-1),LN(0.5)/LN(1+C16),"NA") | E16: output/v7/R4/alquiler/velocidad_ajuste_region.csv
A17: alquiler | B17: B | C17: -0.013387567 | D17: =IF(AND(C17<0,C17>-1),LN(0.5)/LN(1+C17),"NA") | E17: output/v7/R4/alquiler/velocidad_ajuste_region.csv
A18: compra | B18: A | C18: -0.2348129 | D18: =IF(AND(C18<0,C18>-1),LN(0.5)/LN(1+C18),"NA") | E18: output/v7/R4/compra/velocidad_ajuste_region.csv
A19: compra | B19: B | C19: -0.079468924 | D19: =IF(AND(C19<0,C19>-1),LN(0.5)/LN(1+C19),"NA") | E19: output/v7/R4/compra/velocidad_ajuste_region.csv

Sheet 04_Illes_Balears
A1: Illes Balears (04): informativo, muestra ya vista en v1; C4; asociación
A3: Serie | B3: Periodo | C3: Inicio | D3: Valor inicio | E3: Fin | F3: Valor fin | G3: Variación | H3: Fuente
A4: IPV (INE) | B4: 2014T1-2019T4 | C4: 2014Q1 | D4: 47.581 | E4: 2019Q4 | F4: 68.234 | G4: =F4/D4-1 | H4: panel_ccaa_q_v7.csv, INE, hasta 2026Q2
A5: IPV (INE) | B5: 2020T1-2022T2 | C5: 2020Q1 | D5: 69.048 | E5: 2022Q2 | F5: 80.513 | G5: =F5/D5-1 | H5: panel_ccaa_q_v7.csv, INE, hasta 2026Q2
A6: IPV (INE) | B6: 2022T3-último | C6: 2022Q3 | D6: 82.058 | E6: 2026Q2 | F6: 112.048 | G6: =F6/D6-1 | H6: panel_ccaa_q_v7.csv, INE, hasta 2026Q2
A7: IPC alquiler (INE) | B7: 2014T1-2019T4 | C7: 2014Q1 | D7: 84.620333 | E7: 2019Q4 | F7: 90.030333 | G7: =F7/D7-1 | H7: panel_ccaa_q_v7.csv, INE, hasta 2026Q2
A8: IPC alquiler (INE) | B8: 2020T1-2022T2 | C8: 2020Q1 | D8: 90.331 | E8: 2022Q2 | F8: 92.05 | G8: =F8/D8-1 | H8: panel_ccaa_q_v7.csv, INE, hasta 2026Q2
A9: IPC alquiler (INE) | B9: 2022T3-último | C9: 2022Q3 | D9: 92.347667 | E9: 2026Q2 | F9: 103.04467 | G9: =F9/D9-1 | H9: panel_ccaa_q_v7.csv, INE, hasta 2026Q2
A11: Mercado | B11: Mejor modelo | C11: RMSE mejor ×100 | D11: RMSE base exigente ×100 | E11: Diferencia | F11: ¿Bate? | G11: Fuente
A12: alquiler | B12: mixto | C12: 0.68414236 | D12: 0.67910274 | E12: =D12-C12 | F12: =IF(E12>0,"sí","no") | G12: output/v7/R5/mejor_por_region.csv; informativo, muestra ya vista en v1
A13: compra | B13: ar4 | C13: 3.0472605 | D13: 3.0579841 | E13: =D13-C13 | F13: =IF(E13>0,"sí","no") | G13: output/v7/R5/mejor_por_region.csv; informativo, muestra ya vista en v1
A15: Mercado | B15: Spec | C15: φ (sin inferencia válida) | D15: Semivida (trim.) | E15: Fuente
A16: alquiler | B16: A | C16: -0.086963831 | D16: =IF(AND(C16<0,C16>-1),LN(0.5)/LN(1+C16),"NA") | E16: output/v7/R4/alquiler/velocidad_ajuste_region.csv
A17: alquiler | B17: B | C17: 0.011218826 | D17: =IF(AND(C17<0,C17>-1),LN(0.5)/LN(1+C17),"NA") | E17: output/v7/R4/alquiler/velocidad_ajuste_region.csv
A18: compra | B18: A | C18: -0.011778042 | D18: =IF(AND(C18<0,C18>-1),LN(0.5)/LN(1+C18),"NA") | E18: output/v7/R4/compra/velocidad_ajuste_region.csv
A19: compra | B19: B | C19: -0.016724246 | D19: =IF(AND(C19<0,C19>-1),LN(0.5)/LN(1+C19),"NA") | E19: output/v7/R4/compra/velocidad_ajuste_region.csv

Sheet 05_Canarias
A1: Canarias (05): informativo, muestra ya vista en v1; C4; asociación
A3: Serie | B3: Periodo | C3: Inicio | D3: Valor inicio | E3: Fin | F3: Valor fin | G3: Variación | H3: Fuente
A4: IPV (INE) | B4: 2014T1-2019T4 | C4: 2014Q1 | D4: 54.539 | E4: 2019Q4 | F4: 67.811 | G4: =F4/D4-1 | H4: panel_ccaa_q_v7.csv, INE, hasta 2026Q2
A5: IPV (INE) | B5: 2020T1-2022T2 | C5: 2020Q1 | D5: 68.192 | E5: 2022Q2 | F5: 78.534 | G5: =F5/D5-1 | H5: panel_ccaa_q_v7.csv, INE, hasta 2026Q2
A6: IPV (INE) | B6: 2022T3-último | C6: 2022Q3 | D6: 79.323 | E6: 2026Q2 | F6: 110.44 | G6: =F6/D6-1 | H6: panel_ccaa_q_v7.csv, INE, hasta 2026Q2
A7: IPC alquiler (INE) | B7: 2014T1-2019T4 | C7: 2014Q1 | D7: 88.586 | E7: 2019Q4 | F7: 91.056667 | G7: =F7/D7-1 | H7: panel_ccaa_q_v7.csv, INE, hasta 2026Q2
A8: IPC alquiler (INE) | B8: 2020T1-2022T2 | C8: 2020Q1 | D8: 91.512 | E8: 2022Q2 | F8: 93.123667 | G8: =F8/D8-1 | H8: panel_ccaa_q_v7.csv, INE, hasta 2026Q2
A9: IPC alquiler (INE) | B9: 2022T3-último | C9: 2022Q3 | D9: 93.628667 | E9: 2026Q2 | F9: 101.86733 | G9: =F9/D9-1 | H9: panel_ccaa_q_v7.csv, INE, hasta 2026Q2
A11: Mercado | B11: Mejor modelo | C11: RMSE mejor ×100 | D11: RMSE base exigente ×100 | E11: Diferencia | F11: ¿Bate? | G11: Fuente
A12: alquiler | B12: gbm | C12: 0.41092544 | D12: 0.41813164 | E12: =D12-C12 | F12: =IF(E12>0,"sí","no") | G12: output/v7/R5/mejor_por_region.csv; informativo, muestra ya vista en v1
A13: compra | B13: ar4 | C13: 2.6457183 | D13: 2.5612716 | E13: =D13-C13 | F13: =IF(E13>0,"sí","no") | G13: output/v7/R5/mejor_por_region.csv; informativo, muestra ya vista en v1
A15: Mercado | B15: Spec | C15: φ (sin inferencia válida) | D15: Semivida (trim.) | E15: Fuente
A16: alquiler | B16: A | C16: -0.14021288 | D16: =IF(AND(C16<0,C16>-1),LN(0.5)/LN(1+C16),"NA") | E16: output/v7/R4/alquiler/velocidad_ajuste_region.csv
A17: alquiler | B17: B | C17: -0.10520453 | D17: =IF(AND(C17<0,C17>-1),LN(0.5)/LN(1+C17),"NA") | E17: output/v7/R4/alquiler/velocidad_ajuste_region.csv
A18: compra | B18: A | C18: -0.31752405 | D18: =IF(AND(C18<0,C18>-1),LN(0.5)/LN(1+C18),"NA") | E18: output/v7/R4/compra/velocidad_ajuste_region.csv
A19: compra | B19: B | C19: -0.10169991 | D19: =IF(AND(C19<0,C19>-1),LN(0.5)/LN(1+C19),"NA") | E19: output/v7/R4/compra/velocidad_ajuste_region.csv

Sheet 06_Cantabria
A1: Cantabria (06): informativo, muestra ya vista en v1; C4; asociación
A3: Serie | B3: Periodo | C3: Inicio | D3: Valor inicio | E3: Fin | F3: Valor fin | G3: Variación | H3: Fuente
A4: IPV (INE) | B4: 2014T1-2019T4 | C4: 2014Q1 | D4: 55.077 | E4: 2019Q4 | F4: 66.941 | G4: =F4/D4-1 | H4: panel_ccaa_q_v7.csv, INE, hasta 2026Q2
A5: IPV (INE) | B5: 2020T1-2022T2 | C5: 2020Q1 | D5: 67.06 | E5: 2022Q2 | F5: 77.797 | G5: =F5/D5-1 | H5: panel_ccaa_q_v7.csv, INE, hasta 2026Q2
A6: IPV (INE) | B6: 2022T3-último | C6: 2022Q3 | D6: 79.005 | E6: 2026Q2 | F6: 111.313 | G6: =F6/D6-1 | H6: panel_ccaa_q_v7.csv, INE, hasta 2026Q2
A7: IPC alquiler (INE) | B7: 2014T1-2019T4 | C7: 2014Q1 | D7: 90.617 | E7: 2019Q4 | F7: 92.122 | G7: =F7/D7-1 | H7: panel_ccaa_q_v7.csv, INE, hasta 2026Q2
A8: IPC alquiler (INE) | B8: 2020T1-2022T2 | C8: 2020Q1 | D8: 92.326333 | E8: 2022Q2 | F8: 93.682667 | G8: =F8/D8-1 | H8: panel_ccaa_q_v7.csv, INE, hasta 2026Q2
A9: IPC alquiler (INE) | B9: 2022T3-último | C9: 2022Q3 | D9: 93.983667 | E9: 2026Q2 | F9: 102.542 | G9: =F9/D9-1 | H9: panel_ccaa_q_v7.csv, INE, hasta 2026Q2
A11: Mercado | B11: Mejor modelo | C11: RMSE mejor ×100 | D11: RMSE base exigente ×100 | E11: Diferencia | F11: ¿Bate? | G11: Fuente
A12: alquiler | B12: gbm | C12: 0.451345 | D12: 0.42789652 | E12: =D12-C12 | F12: =IF(E12>0,"sí","no") | G12: output/v7/R5/mejor_por_region.csv; informativo, muestra ya vista en v1
A13: compra | B13: ar4 | C13: 2.8778285 | D13: 2.6403446 | E13: =D13-C13 | F13: =IF(E13>0,"sí","no") | G13: output/v7/R5/mejor_por_region.csv; informativo, muestra ya vista en v1
A15: Mercado | B15: Spec | C15: φ (sin inferencia válida) | D15: Semivida (trim.) | E15: Fuente
A16: alquiler | B16: A | C16: -0.099107216 | D16: =IF(AND(C16<0,C16>-1),LN(0.5)/LN(1+C16),"NA") | E16: output/v7/R4/alquiler/velocidad_ajuste_region.csv
A17: alquiler | B17: B | C17: -0.12431635 | D17: =IF(AND(C17<0,C17>-1),LN(0.5)/LN(1+C17),"NA") | E17: output/v7/R4/alquiler/velocidad_ajuste_region.csv
A18: compra | B18: A | C18: -0.089550196 | D18: =IF(AND(C18<0,C18>-1),LN(0.5)/LN(1+C18),"NA") | E18: output/v7/R4/compra/velocidad_ajuste_region.csv
A19: compra | B19: B | C19: -0.14910747 | D19: =IF(AND(C19<0,C19>-1),LN(0.5)/LN(1+C19),"NA") | E19: output/v7/R4/compra/velocidad_ajuste_region.csv

Sheet 07_Castilla_y_Leon
A1: Castilla y León (07): informativo, muestra ya vista en v1; C4; asociación
A3: Serie | B3: Periodo | C3: Inicio | D3: Valor inicio | E3: Fin | F3: Valor fin | G3: Variación | H3: Fuente
A4: IPV (INE) | B4: 2014T1-2019T4 | C4: 2014Q1 | D4: 61.37 | E4: 2019Q4 | F4: 71.386 | G4: =F4/D4-1 | H4: panel_ccaa_q_v7.csv, INE, hasta 2026Q2
A5: IPV (INE) | B5: 2020T1-2022T2 | C5: 2020Q1 | D5: 70.949 | E5: 2022Q2 | F5: 79.21 | G5: =F5/D5-1 | H5: panel_ccaa_q_v7.csv, INE, hasta 2026Q2
A6: IPV (INE) | B6: 2022T3-último | C6: 2022Q3 | D6: 80.393 | E6: 2026Q2 | F6: 113.551 | G6: =F6/D6-1 | H6: panel_ccaa_q_v7.csv, INE, hasta 2026Q2
A7: IPC alquiler (INE) | B7: 2014T1-2019T4 | C7: 2014Q1 | D7: 90.980667 | E7: 2019Q4 | F7: 92.103667 | G7: =F7/D7-1 | H7: panel_ccaa_q_v7.csv, INE, hasta 2026Q2
A8: IPC alquiler (INE) | B8: 2020T1-2022T2 | C8: 2020Q1 | D8: 92.251 | E8: 2022Q2 | F8: 94.109 | G8: =F8/D8-1 | H8: panel_ccaa_q_v7.csv, INE, hasta 2026Q2
A9: IPC alquiler (INE) | B9: 2022T3-último | C9: 2022Q3 | D9: 94.521333 | E9: 2026Q2 | F9: 102.17867 | G9: =F9/D9-1 | H9: panel_ccaa_q_v7.csv, INE, hasta 2026Q2
A11: Mercado | B11: Mejor modelo | C11: RMSE mejor ×100 | D11: RMSE base exigente ×100 | E11: Diferencia | F11: ¿Bate? | G11: Fuente
A12: alquiler | B12: gbm | C12: 0.33665405 | D12: 0.34604711 | E12: =D12-C12 | F12: =IF(E12>0,"sí","no") | G12: output/v7/R5/mejor_por_region.csv; informativo, muestra ya vista en v1
A13: compra | B13: gbm | C13: 2.6539847 | D13: 2.3210737 | E13: =D13-C13 | F13: =IF(E13>0,"sí","no") | G13: output/v7/R5/mejor_por_region.csv; informativo, muestra ya vista en v1
A15: Mercado | B15: Spec | C15: φ (sin inferencia válida) | D15: Semivida (trim.) | E15: Fuente
A16: alquiler | B16: A | C16: -0.0067313321 | D16: =IF(AND(C16<0,C16>-1),LN(0.5)/LN(1+C16),"NA") | E16: output/v7/R4/alquiler/velocidad_ajuste_region.csv
A17: alquiler | B17: B | C17: -0.028879698 | D17: =IF(AND(C17<0,C17>-1),LN(0.5)/LN(1+C17),"NA") | E17: output/v7/R4/alquiler/velocidad_ajuste_region.csv
A18: compra | B18: A | C18: -0.36816456 | D18: =IF(AND(C18<0,C18>-1),LN(0.5)/LN(1+C18),"NA") | E18: output/v7/R4/compra/velocidad_ajuste_region.csv
A19: compra | B19: B | C19: -0.17408216 | D19: =IF(AND(C19<0,C19>-1),LN(0.5)/LN(1+C19),"NA") | E19: output/v7/R4/compra/velocidad_ajuste_region.csv

Sheet 08_Castilla_La_Mancha
A1: Castilla-La Mancha (08): informativo, muestra ya vista en v1; C4; asociación
A3: Serie | B3: Periodo | C3: Inicio | D3: Valor inicio | E3: Fin | F3: Valor fin | G3: Variación | H3: Fuente
A4: IPV (INE) | B4: 2014T1-2019T4 | C4: 2014Q1 | D4: 67.831 | E4: 2019Q4 | F4: 75.798 | G4: =F4/D4-1 | H4: panel_ccaa_q_v7.csv, INE, hasta 2026Q2
A5: IPV (INE) | B5: 2020T1-2022T2 | C5: 2020Q1 | D5: 75.411 | E5: 2022Q2 | F5: 83.044 | G5: =F5/D5-1 | H5: panel_ccaa_q_v7.csv, INE, hasta 2026Q2
A6: IPV (INE) | B6: 2022T3-último | C6: 2022Q3 | D6: 84.289 | E6: 2026Q2 | F6: 110.864 | G6: =F6/D6-1 | H6: panel_ccaa_q_v7.csv, INE, hasta 2026Q2
A7: IPC alquiler (INE) | B7: 2014T1-2019T4 | C7: 2014Q1 | D7: 90.966667 | E7: 2019Q4 | F7: 91.354333 | G7: =F7/D7-1 | H7: panel_ccaa_q_v7.csv, INE, hasta 2026Q2
A8: IPC alquiler (INE) | B8: 2020T1-2022T2 | C8: 2020Q1 | D8: 91.477667 | E8: 2022Q2 | F8: 93.035667 | G8: =F8/D8-1 | H8: panel_ccaa_q_v7.csv, INE, hasta 2026Q2
A9: IPC alquiler (INE) | B9: 2022T3-último | C9: 2022Q3 | D9: 93.561667 | E9: 2026Q2 | F9: 102.40567 | G9: =F9/D9-1 | H9: panel_ccaa_q_v7.csv, INE, hasta 2026Q2
A11: Mercado | B11: Mejor modelo | C11: RMSE mejor ×100 | D11: RMSE base exigente ×100 | E11: Diferencia | F11: ¿Bate? | G11: Fuente
A12: alquiler | B12: gbm | C12: 0.40972048 | D12: 0.35072723 | E12: =D12-C12 | F12: =IF(E12>0,"sí","no") | G12: output/v7/R5/mejor_por_region.csv; informativo, muestra ya vista en v1
A13: compra | B13: pmg | C13: 2.2146576 | D13: 2.3414997 | E13: =D13-C13 | F13: =IF(E13>0,"sí","no") | G13: output/v7/R5/mejor_por_region.csv; informativo, muestra ya vista en v1
A15: Mercado | B15: Spec | C15: φ (sin inferencia válida) | D15: Semivida (trim.) | E15: Fuente
A16: alquiler | B16: A | C16: -0.13195931 | D16: =IF(AND(C16<0,C16>-1),LN(0.5)/LN(1+C16),"NA") | E16: output/v7/R4/alquiler/velocidad_ajuste_region.csv
A17: alquiler | B17: B | C17: -0.02069711 | D17: =IF(AND(C17<0,C17>-1),LN(0.5)/LN(1+C17),"NA") | E17: output/v7/R4/alquiler/velocidad_ajuste_region.csv
A18: compra | B18: A | C18: -0.044716609 | D18: =IF(AND(C18<0,C18>-1),LN(0.5)/LN(1+C18),"NA") | E18: output/v7/R4/compra/velocidad_ajuste_region.csv
A19: compra | B19: B | C19: 0.0059901408 | D19: =IF(AND(C19<0,C19>-1),LN(0.5)/LN(1+C19),"NA") | E19: output/v7/R4/compra/velocidad_ajuste_region.csv

Sheet 09_Cataluna
A1: Cataluña (09): informativo, muestra ya vista en v1; C4; asociación
A3: Serie | B3: Periodo | C3: Inicio | D3: Valor inicio | E3: Fin | F3: Valor fin | G3: Variación | H3: Fuente
A4: IPV (INE) | B4: 2014T1-2019T4 | C4: 2014Q1 | D4: 49.99 | E4: 2019Q4 | F4: 71.981 | G4: =F4/D4-1 | H4: panel_ccaa_q_v7.csv, INE, hasta 2026Q2
A5: IPV (INE) | B5: 2020T1-2022T2 | C5: 2020Q1 | D5: 72.464 | E5: 2022Q2 | F5: 80.612 | G5: =F5/D5-1 | H5: panel_ccaa_q_v7.csv, INE, hasta 2026Q2
A6: IPV (INE) | B6: 2022T3-último | C6: 2022Q3 | D6: 82.337 | E6: 2026Q2 | F6: 109.046 | G6: =F6/D6-1 | H6: panel_ccaa_q_v7.csv, INE, hasta 2026Q2
A7: IPC alquiler (INE) | B7: 2014T1-2019T4 | C7: 2014Q1 | D7: 88.667 | E7: 2019Q4 | F7: 92.486667 | G7: =F7/D7-1 | H7: panel_ccaa_q_v7.csv, INE, hasta 2026Q2
A8: IPC alquiler (INE) | B8: 2020T1-2022T2 | C8: 2020Q1 | D8: 92.775 | E8: 2022Q2 | F8: 95.087 | G8: =F8/D8-1 | H8: panel_ccaa_q_v7.csv, INE, hasta 2026Q2
A9: IPC alquiler (INE) | B9: 2022T3-último | C9: 2022Q3 | D9: 95.441667 | E9: 2026Q2 | F9: 101.70267 | G9: =F9/D9-1 | H9: panel_ccaa_q_v7.csv, INE, hasta 2026Q2
A11: Mercado | B11: Mejor modelo | C11: RMSE mejor ×100 | D11: RMSE base exigente ×100 | E11: Diferencia | F11: ¿Bate? | G11: Fuente
A12: alquiler | B12: pmg | C12: 0.2917161 | D12: 0.27639732 | E12: =D12-C12 | F12: =IF(E12>0,"sí","no") | G12: output/v7/R5/mejor_por_region.csv; informativo, muestra ya vista en v1
A13: compra | B13: ar4 | C13: 2.5421173 | D13: 2.8406828 | E13: =D13-C13 | F13: =IF(E13>0,"sí","no") | G13: output/v7/R5/mejor_por_region.csv; informativo, muestra ya vista en v1
A15: Mercado | B15: Spec | C15: φ (sin inferencia válida) | D15: Semivida (trim.) | E15: Fuente
A16: alquiler | B16: A | C16: 0.0088063472 | D16: =IF(AND(C16<0,C16>-1),LN(0.5)/LN(1+C16),"NA") | E16: output/v7/R4/alquiler/velocidad_ajuste_region.csv
A17: alquiler | B17: B | C17: 0.011754009 | D17: =IF(AND(C17<0,C17>-1),LN(0.5)/LN(1+C17),"NA") | E17: output/v7/R4/alquiler/velocidad_ajuste_region.csv
A18: compra | B18: A | C18: -0.11083752 | D18: =IF(AND(C18<0,C18>-1),LN(0.5)/LN(1+C18),"NA") | E18: output/v7/R4/compra/velocidad_ajuste_region.csv
A19: compra | B19: B | C19: -0.060600437 | D19: =IF(AND(C19<0,C19>-1),LN(0.5)/LN(1+C19),"NA") | E19: output/v7/R4/compra/velocidad_ajuste_region.csv

Sheet 10_Comunitat_Valenciana
A1: Comunitat Valenciana (10): informativo, muestra ya vista en v1; C4; asociación
A3: Serie | B3: Periodo | C3: Inicio | D3: Valor inicio | E3: Fin | F3: Valor fin | G3: Variación | H3: Fuente
A4: IPV (INE) | B4: 2014T1-2019T4 | C4: 2014Q1 | D4: 57.024 | E4: 2019Q4 | F4: 69.038 | G4: =F4/D4-1 | H4: panel_ccaa_q_v7.csv, INE, hasta 2026Q2
A5: IPV (INE) | B5: 2020T1-2022T2 | C5: 2020Q1 | D5: 69.334 | E5: 2022Q2 | F5: 78.108 | G5: =F5/D5-1 | H5: panel_ccaa_q_v7.csv, INE, hasta 2026Q2
A6: IPV (INE) | B6: 2022T3-último | C6: 2022Q3 | D6: 78.892 | E6: 2026Q2 | F6: 111.696 | G6: =F6/D6-1 | H6: panel_ccaa_q_v7.csv, INE, hasta 2026Q2
A7: IPC alquiler (INE) | B7: 2014T1-2019T4 | C7: 2014Q1 | D7: 85.949 | E7: 2019Q4 | F7: 88.129 | G7: =F7/D7-1 | H7: panel_ccaa_q_v7.csv, INE, hasta 2026Q2
A8: IPC alquiler (INE) | B8: 2020T1-2022T2 | C8: 2020Q1 | D8: 88.684 | E8: 2022Q2 | F8: 91.081 | G8: =F8/D8-1 | H8: panel_ccaa_q_v7.csv, INE, hasta 2026Q2
A9: IPC alquiler (INE) | B9: 2022T3-último | C9: 2022Q3 | D9: 91.479 | E9: 2026Q2 | F9: 103.282 | G9: =F9/D9-1 | H9: panel_ccaa_q_v7.csv, INE, hasta 2026Q2
A11: Mercado | B11: Mejor modelo | C11: RMSE mejor ×100 | D11: RMSE base exigente ×100 | E11: Diferencia | F11: ¿Bate? | G11: Fuente
A12: alquiler | B12: gbm | C12: 0.56526211 | D12: 0.65843058 | E12: =D12-C12 | F12: =IF(E12>0,"sí","no") | G12: output/v7/R5/mejor_por_region.csv; informativo, muestra ya vista en v1
A13: compra | B13: pmg | C13: 2.1966587 | D13: 2.3699144 | E13: =D13-C13 | F13: =IF(E13>0,"sí","no") | G13: output/v7/R5/mejor_por_region.csv; informativo, muestra ya vista en v1
A15: Mercado | B15: Spec | C15: φ (sin inferencia válida) | D15: Semivida (trim.) | E15: Fuente
A16: alquiler | B16: A | C16: -0.14702904 | D16: =IF(AND(C16<0,C16>-1),LN(0.5)/LN(1+C16),"NA") | E16: output/v7/R4/alquiler/velocidad_ajuste_region.csv
A17: alquiler | B17: B | C17: 0.019137007 | D17: =IF(AND(C17<0,C17>-1),LN(0.5)/LN(1+C17),"NA") | E17: output/v7/R4/alquiler/velocidad_ajuste_region.csv
A18: compra | B18: A | C18: -0.18817965 | D18: =IF(AND(C18<0,C18>-1),LN(0.5)/LN(1+C18),"NA") | E18: output/v7/R4/compra/velocidad_ajuste_region.csv
A19: compra | B19: B | C19: -0.1725986 | D19: =IF(AND(C19<0,C19>-1),LN(0.5)/LN(1+C19),"NA") | E19: output/v7/R4/compra/velocidad_ajuste_region.csv

Sheet 11_Extremadura
A1: Extremadura (11): informativo, muestra ya vista en v1; C4; asociación
A3: Serie | B3: Periodo | C3: Inicio | D3: Valor inicio | E3: Fin | F3: Valor fin | G3: Variación | H3: Fuente
A4: IPV (INE) | B4: 2014T1-2019T4 | C4: 2014Q1 | D4: 70.205 | E4: 2019Q4 | F4: 75.627 | G4: =F4/D4-1 | H4: panel_ccaa_q_v7.csv, INE, hasta 2026Q2
A5: IPV (INE) | B5: 2020T1-2022T2 | C5: 2020Q1 | D5: 75.048 | E5: 2022Q2 | F5: 81.921 | G5: =F5/D5-1 | H5: panel_ccaa_q_v7.csv, INE, hasta 2026Q2
A6: IPV (INE) | B6: 2022T3-último | C6: 2022Q3 | D6: 83.021 | E6: 2026Q2 | F6: 111.963 | G6: =F6/D6-1 | H6: panel_ccaa_q_v7.csv, INE, hasta 2026Q2
A7: IPC alquiler (INE) | B7: 2014T1-2019T4 | C7: 2014Q1 | D7: 92.334667 | E7: 2019Q4 | F7: 92.053667 | G7: =F7/D7-1 | H7: panel_ccaa_q_v7.csv, INE, hasta 2026Q2
A8: IPC alquiler (INE) | B8: 2020T1-2022T2 | C8: 2020Q1 | D8: 92.274333 | E8: 2022Q2 | F8: 93.956667 | G8: =F8/D8-1 | H8: panel_ccaa_q_v7.csv, INE, hasta 2026Q2
A9: IPC alquiler (INE) | B9: 2022T3-último | C9: 2022Q3 | D9: 94.262 | E9: 2026Q2 | F9: 101.66467 | G9: =F9/D9-1 | H9: panel_ccaa_q_v7.csv, INE, hasta 2026Q2
A11: Mercado | B11: Mejor modelo | C11: RMSE mejor ×100 | D11: RMSE base exigente ×100 | E11: Diferencia | F11: ¿Bate? | G11: Fuente
A12: alquiler | B12: ecm_v1 | C12: 0.49719949 | D12: 0.49590629 | E12: =D12-C12 | F12: =IF(E12>0,"sí","no") | G12: output/v7/R5/mejor_por_region.csv; informativo, muestra ya vista en v1
A13: compra | B13: gbm | C13: 2.691525 | D13: 2.6520569 | E13: =D13-C13 | F13: =IF(E13>0,"sí","no") | G13: output/v7/R5/mejor_por_region.csv; informativo, muestra ya vista en v1
A15: Mercado | B15: Spec | C15: φ (sin inferencia válida) | D15: Semivida (trim.) | E15: Fuente
A16: alquiler | B16: A | C16: -0.044134415 | D16: =IF(AND(C16<0,C16>-1),LN(0.5)/LN(1+C16),"NA") | E16: output/v7/R4/alquiler/velocidad_ajuste_region.csv
A17: alquiler | B17: B | C17: -0.0044112887 | D17: =IF(AND(C17<0,C17>-1),LN(0.5)/LN(1+C17),"NA") | E17: output/v7/R4/alquiler/velocidad_ajuste_region.csv
A18: compra | B18: A | C18: -0.15628937 | D18: =IF(AND(C18<0,C18>-1),LN(0.5)/LN(1+C18),"NA") | E18: output/v7/R4/compra/velocidad_ajuste_region.csv
A19: compra | B19: B | C19: -0.0013138872 | D19: =IF(AND(C19<0,C19>-1),LN(0.5)/LN(1+C19),"NA") | E19: output/v7/R4/compra/velocidad_ajuste_region.csv

Sheet 12_Galicia
A1: Galicia (12): informativo, muestra ya vista en v1; C4; asociación
A3: Serie | B3: Periodo | C3: Inicio | D3: Valor inicio | E3: Fin | F3: Valor fin | G3: Variación | H3: Fuente
A4: IPV (INE) | B4: 2014T1-2019T4 | C4: 2014Q1 | D4: 60.862 | E4: 2019Q4 | F4: 70.736 | G4: =F4/D4-1 | H4: panel_ccaa_q_v7.csv, INE, hasta 2026Q2
A5: IPV (INE) | B5: 2020T1-2022T2 | C5: 2020Q1 | D5: 70.674 | E5: 2022Q2 | F5: 79.813 | G5: =F5/D5-1 | H5: panel_ccaa_q_v7.csv, INE, hasta 2026Q2
A6: IPV (INE) | B6: 2022T3-último | C6: 2022Q3 | D6: 80.336 | E6: 2026Q2 | F6: 111.825 | G6: =F6/D6-1 | H6: panel_ccaa_q_v7.csv, INE, hasta 2026Q2
A7: IPC alquiler (INE) | B7: 2014T1-2019T4 | C7: 2014Q1 | D7: 88.700667 | E7: 2019Q4 | F7: 91.504667 | G7: =F7/D7-1 | H7: panel_ccaa_q_v7.csv, INE, hasta 2026Q2
A8: IPC alquiler (INE) | B8: 2020T1-2022T2 | C8: 2020Q1 | D8: 91.733333 | E8: 2022Q2 | F8: 93.882333 | G8: =F8/D8-1 | H8: panel_ccaa_q_v7.csv, INE, hasta 2026Q2
A9: IPC alquiler (INE) | B9: 2022T3-último | C9: 2022Q3 | D9: 94.372 | E9: 2026Q2 | F9: 102.47833 | G9: =F9/D9-1 | H9: panel_ccaa_q_v7.csv, INE, hasta 2026Q2
A11: Mercado | B11: Mejor modelo | C11: RMSE mejor ×100 | D11: RMSE base exigente ×100 | E11: Diferencia | F11: ¿Bate? | G11: Fuente
A12: alquiler | B12: gbm | C12: 0.43446004 | D12: 0.42111448 | E12: =D12-C12 | F12: =IF(E12>0,"sí","no") | G12: output/v7/R5/mejor_por_region.csv; informativo, muestra ya vista en v1
A13: compra | B13: gbm | C13: 2.4899293 | D13: 2.2721321 | E13: =D13-C13 | F13: =IF(E13>0,"sí","no") | G13: output/v7/R5/mejor_por_region.csv; informativo, muestra ya vista en v1
A15: Mercado | B15: Spec | C15: φ (sin inferencia válida) | D15: Semivida (trim.) | E15: Fuente
A16: alquiler | B16: A | C16: 0.013768775 | D16: =IF(AND(C16<0,C16>-1),LN(0.5)/LN(1+C16),"NA") | E16: output/v7/R4/alquiler/velocidad_ajuste_region.csv
A17: alquiler | B17: B | C17: 0.030546117 | D17: =IF(AND(C17<0,C17>-1),LN(0.5)/LN(1+C17),"NA") | E17: output/v7/R4/alquiler/velocidad_ajuste_region.csv
A18: compra | B18: A | C18: -0.21922759 | D18: =IF(AND(C18<0,C18>-1),LN(0.5)/LN(1+C18),"NA") | E18: output/v7/R4/compra/velocidad_ajuste_region.csv
A19: compra | B19: B | C19: -0.17253869 | D19: =IF(AND(C19<0,C19>-1),LN(0.5)/LN(1+C19),"NA") | E19: output/v7/R4/compra/velocidad_ajuste_region.csv

Sheet 13_Comunidad_de_Madrid
A1: Comunidad de Madrid (13): informativo, muestra ya vista en v1; C4; asociación
A3: Serie | B3: Periodo | C3: Inicio | D3: Valor inicio | E3: Fin | F3: Valor fin | G3: Variación | H3: Fuente
A4: IPV (INE) | B4: 2014T1-2019T4 | C4: 2014Q1 | D4: 46.897 | E4: 2019Q4 | F4: 70.425 | G4: =F4/D4-1 | H4: panel_ccaa_q_v7.csv, INE, hasta 2026Q2
A5: IPV (INE) | B5: 2020T1-2022T2 | C5: 2020Q1 | D5: 72.18 | E5: 2022Q2 | F5: 78.442 | G5: =F5/D5-1 | H5: panel_ccaa_q_v7.csv, INE, hasta 2026Q2
A6: IPV (INE) | B6: 2022T3-último | C6: 2022Q3 | D6: 80.228 | E6: 2026Q2 | F6: 111.85 | G6: =F6/D6-1 | H6: panel_ccaa_q_v7.csv, INE, hasta 2026Q2
A7: IPC alquiler (INE) | B7: 2014T1-2019T4 | C7: 2014Q1 | D7: 88.164667 | E7: 2019Q4 | F7: 90.65 | G7: =F7/D7-1 | H7: panel_ccaa_q_v7.csv, INE, hasta 2026Q2
A8: IPC alquiler (INE) | B8: 2020T1-2022T2 | C8: 2020Q1 | D8: 91.02 | E8: 2022Q2 | F8: 92.375333 | G8: =F8/D8-1 | H8: panel_ccaa_q_v7.csv, INE, hasta 2026Q2
A9: IPC alquiler (INE) | B9: 2022T3-último | C9: 2022Q3 | D9: 92.744333 | E9: 2026Q2 | F9: 102.546 | G9: =F9/D9-1 | H9: panel_ccaa_q_v7.csv, INE, hasta 2026Q2
A11: Mercado | B11: Mejor modelo | C11: RMSE mejor ×100 | D11: RMSE base exigente ×100 | E11: Diferencia | F11: ¿Bate? | G11: Fuente
A12: alquiler | B12: gbm | C12: 0.53633936 | D12: 0.61214978 | E12: =D12-C12 | F12: =IF(E12>0,"sí","no") | G12: output/v7/R5/mejor_por_region.csv; informativo, muestra ya vista en v1
A13: compra | B13: ar4 | C13: 3.0598092 | D13: 3.2810374 | E13: =D13-C13 | F13: =IF(E13>0,"sí","no") | G13: output/v7/R5/mejor_por_region.csv; informativo, muestra ya vista en v1
A15: Mercado | B15: Spec | C15: φ (sin inferencia válida) | D15: Semivida (trim.) | E15: Fuente
A16: alquiler | B16: A | C16: 0.052714714 | D16: =IF(AND(C16<0,C16>-1),LN(0.5)/LN(1+C16),"NA") | E16: output/v7/R4/alquiler/velocidad_ajuste_region.csv
A17: alquiler | B17: B | C17: -0.015922455 | D17: =IF(AND(C17<0,C17>-1),LN(0.5)/LN(1+C17),"NA") | E17: output/v7/R4/alquiler/velocidad_ajuste_region.csv
A18: compra | B18: A | C18: -0.080429387 | D18: =IF(AND(C18<0,C18>-1),LN(0.5)/LN(1+C18),"NA") | E18: output/v7/R4/compra/velocidad_ajuste_region.csv
A19: compra | B19: B | C19: -0.087602335 | D19: =IF(AND(C19<0,C19>-1),LN(0.5)/LN(1+C19),"NA") | E19: output/v7/R4/compra/velocidad_ajuste_region.csv

Sheet 14_Region_de_Murcia
A1: Región de Murcia (14): informativo, muestra ya vista en v1; C4; asociación
A3: Serie | B3: Periodo | C3: Inicio | D3: Valor inicio | E3: Fin | F3: Valor fin | G3: Variación | H3: Fuente
A4: IPV (INE) | B4: 2014T1-2019T4 | C4: 2014Q1 | D4: 58.678 | E4: 2019Q4 | F4: 68.452 | G4: =F4/D4-1 | H4: panel_ccaa_q_v7.csv, INE, hasta 2026Q2
A5: IPV (INE) | B5: 2020T1-2022T2 | C5: 2020Q1 | D5: 68.351 | E5: 2022Q2 | F5: 79.256 | G5: =F5/D5-1 | H5: panel_ccaa_q_v7.csv, INE, hasta 2026Q2
A6: IPV (INE) | B6: 2022T3-último | C6: 2022Q3 | D6: 79.708 | E6: 2026Q2 | F6: 113.192 | G6: =F6/D6-1 | H6: panel_ccaa_q_v7.csv, INE, hasta 2026Q2
A7: IPC alquiler (INE) | B7: 2014T1-2019T4 | C7: 2014Q1 | D7: 93.474333 | E7: 2019Q4 | F7: 93.746667 | G7: =F7/D7-1 | H7: panel_ccaa_q_v7.csv, INE, hasta 2026Q2
A8: IPC alquiler (INE) | B8: 2020T1-2022T2 | C8: 2020Q1 | D8: 94.171333 | E8: 2022Q2 | F8: 95.823333 | G8: =F8/D8-1 | H8: panel_ccaa_q_v7.csv, INE, hasta 2026Q2
A9: IPC alquiler (INE) | B9: 2022T3-último | C9: 2022Q3 | D9: 96.041667 | E9: 2026Q2 | F9: 103.01367 | G9: =F9/D9-1 | H9: panel_ccaa_q_v7.csv, INE, hasta 2026Q2
A11: Mercado | B11: Mejor modelo | C11: RMSE mejor ×100 | D11: RMSE base exigente ×100 | E11: Diferencia | F11: ¿Bate? | G11: Fuente
A12: alquiler | B12: gbm | C12: 0.44645067 | D12: 0.43256419 | E12: =D12-C12 | F12: =IF(E12>0,"sí","no") | G12: output/v7/R5/mejor_por_region.csv; informativo, muestra ya vista en v1
A13: compra | B13: pmg | C13: 2.9167992 | D13: 2.6325107 | E13: =D13-C13 | F13: =IF(E13>0,"sí","no") | G13: output/v7/R5/mejor_por_region.csv; informativo, muestra ya vista en v1
A15: Mercado | B15: Spec | C15: φ (sin inferencia válida) | D15: Semivida (trim.) | E15: Fuente
A16: alquiler | B16: A | C16: -0.04129637 | D16: =IF(AND(C16<0,C16>-1),LN(0.5)/LN(1+C16),"NA") | E16: output/v7/R4/alquiler/velocidad_ajuste_region.csv
A17: alquiler | B17: B | C17: -0.0056763252 | D17: =IF(AND(C17<0,C17>-1),LN(0.5)/LN(1+C17),"NA") | E17: output/v7/R4/alquiler/velocidad_ajuste_region.csv
A18: compra | B18: A | C18: -0.067540851 | D18: =IF(AND(C18<0,C18>-1),LN(0.5)/LN(1+C18),"NA") | E18: output/v7/R4/compra/velocidad_ajuste_region.csv
A19: compra | B19: B | C19: -0.071786331 | D19: =IF(AND(C19<0,C19>-1),LN(0.5)/LN(1+C19),"NA") | E19: output/v7/R4/compra/velocidad_ajuste_region.csv

Sheet 15_Comunidad_Foral_de_Navarra
A1: Comunidad Foral de Navarra (15): informativo, muestra ya vista en v1; C4; asociación
A3: Serie | B3: Periodo | C3: Inicio | D3: Valor inicio | E3: Fin | F3: Valor fin | G3: Variación | H3: Fuente
A4: IPV (INE) | B4: 2014T1-2019T4 | C4: 2014Q1 | D4: 60.946 | E4: 2019Q4 | F4: 68.6 | G4: =F4/D4-1 | H4: panel_ccaa_q_v7.csv, INE, hasta 2026Q2
A5: IPV (INE) | B5: 2020T1-2022T2 | C5: 2020Q1 | D5: 69.84 | E5: 2022Q2 | F5: 76.371 | G5: =F5/D5-1 | H5: panel_ccaa_q_v7.csv, INE, hasta 2026Q2
A6: IPV (INE) | B6: 2022T3-último | C6: 2022Q3 | D6: 77.299 | E6: 2026Q2 | F6: 109.174 | G6: =F6/D6-1 | H6: panel_ccaa_q_v7.csv, INE, hasta 2026Q2
A7: IPC alquiler (INE) | B7: 2014T1-2019T4 | C7: 2014Q1 | D7: 89.325667 | E7: 2019Q4 | F7: 91.494 | G7: =F7/D7-1 | H7: panel_ccaa_q_v7.csv, INE, hasta 2026Q2
A8: IPC alquiler (INE) | B8: 2020T1-2022T2 | C8: 2020Q1 | D8: 92.111 | E8: 2022Q2 | F8: 94.43 | G8: =F8/D8-1 | H8: panel_ccaa_q_v7.csv, INE, hasta 2026Q2
A9: IPC alquiler (INE) | B9: 2022T3-último | C9: 2022Q3 | D9: 94.898 | E9: 2026Q2 | F9: 101.47767 | G9: =F9/D9-1 | H9: panel_ccaa_q_v7.csv, INE, hasta 2026Q2
A11: Mercado | B11: Mejor modelo | C11: RMSE mejor ×100 | D11: RMSE base exigente ×100 | E11: Diferencia | F11: ¿Bate? | G11: Fuente
A12: alquiler | B12: gbm | C12: 0.36772801 | D12: 0.42078763 | E12: =D12-C12 | F12: =IF(E12>0,"sí","no") | G12: output/v7/R5/mejor_por_region.csv; informativo, muestra ya vista en v1
A13: compra | B13: ar4 | C13: 2.6387365 | D13: 2.5476866 | E13: =D13-C13 | F13: =IF(E13>0,"sí","no") | G13: output/v7/R5/mejor_por_region.csv; informativo, muestra ya vista en v1
A15: Mercado | B15: Spec | C15: φ (sin inferencia válida) | D15: Semivida (trim.) | E15: Fuente
A16: alquiler | B16: A | C16: -0.032431382 | D16: =IF(AND(C16<0,C16>-1),LN(0.5)/LN(1+C16),"NA") | E16: output/v7/R4/alquiler/velocidad_ajuste_region.csv
A17: alquiler | B17: B | C17: -0.03902515 | D17: =IF(AND(C17<0,C17>-1),LN(0.5)/LN(1+C17),"NA") | E17: output/v7/R4/alquiler/velocidad_ajuste_region.csv
A18: compra | B18: A | C18: -0.27143298 | D18: =IF(AND(C18<0,C18>-1),LN(0.5)/LN(1+C18),"NA") | E18: output/v7/R4/compra/velocidad_ajuste_region.csv
A19: compra | B19: B | C19: -0.065336603 | D19: =IF(AND(C19<0,C19>-1),LN(0.5)/LN(1+C19),"NA") | E19: output/v7/R4/compra/velocidad_ajuste_region.csv

Sheet 16_Pais_Vasco
A1: País Vasco (16): informativo, muestra ya vista en v1; C4; asociación
A3: Serie | B3: Periodo | C3: Inicio | D3: Valor inicio | E3: Fin | F3: Valor fin | G3: Variación | H3: Fuente
A4: IPV (INE) | B4: 2014T1-2019T4 | C4: 2014Q1 | D4: 59.814 | E4: 2019Q4 | F4: 71.28 | G4: =F4/D4-1 | H4: panel_ccaa_q_v7.csv, INE, hasta 2026Q2
A5: IPV (INE) | B5: 2020T1-2022T2 | C5: 2020Q1 | D5: 73.235 | E5: 2022Q2 | F5: 79.161 | G5: =F5/D5-1 | H5: panel_ccaa_q_v7.csv, INE, hasta 2026Q2
A6: IPV (INE) | B6: 2022T3-último | C6: 2022Q3 | D6: 80.889 | E6: 2026Q2 | F6: 109.329 | G6: =F6/D6-1 | H6: panel_ccaa_q_v7.csv, INE, hasta 2026Q2
A7: IPC alquiler (INE) | B7: 2014T1-2019T4 | C7: 2014Q1 | D7: 91.983 | E7: 2019Q4 | F7: 92.65 | G7: =F7/D7-1 | H7: panel_ccaa_q_v7.csv, INE, hasta 2026Q2
A8: IPC alquiler (INE) | B8: 2020T1-2022T2 | C8: 2020Q1 | D8: 92.828667 | E8: 2022Q2 | F8: 95.169 | G8: =F8/D8-1 | H8: panel_ccaa_q_v7.csv, INE, hasta 2026Q2
A9: IPC alquiler (INE) | B9: 2022T3-último | C9: 2022Q3 | D9: 95.498333 | E9: 2026Q2 | F9: 101.26667 | G9: =F9/D9-1 | H9: panel_ccaa_q_v7.csv, INE, hasta 2026Q2
A11: Mercado | B11: Mejor modelo | C11: RMSE mejor ×100 | D11: RMSE base exigente ×100 | E11: Diferencia | F11: ¿Bate? | G11: Fuente
A12: alquiler | B12: mixto | C12: 0.37027692 | D12: 0.38799846 | E12: =D12-C12 | F12: =IF(E12>0,"sí","no") | G12: output/v7/R5/mejor_por_region.csv; informativo, muestra ya vista en v1
A13: compra | B13: gbm | C13: 3.0177846 | D13: 2.5341222 | E13: =D13-C13 | F13: =IF(E13>0,"sí","no") | G13: output/v7/R5/mejor_por_region.csv; informativo, muestra ya vista en v1
A15: Mercado | B15: Spec | C15: φ (sin inferencia válida) | D15: Semivida (trim.) | E15: Fuente
A16: alquiler | B16: A | C16: 0.0045177937 | D16: =IF(AND(C16<0,C16>-1),LN(0.5)/LN(1+C16),"NA") | E16: output/v7/R4/alquiler/velocidad_ajuste_region.csv
A17: alquiler | B17: B | C17: -0.027542704 | D17: =IF(AND(C17<0,C17>-1),LN(0.5)/LN(1+C17),"NA") | E17: output/v7/R4/alquiler/velocidad_ajuste_region.csv
A18: compra | B18: A | C18: -0.27221438 | D18: =IF(AND(C18<0,C18>-1),LN(0.5)/LN(1+C18),"NA") | E18: output/v7/R4/compra/velocidad_ajuste_region.csv
A19: compra | B19: B | C19: -0.1340314 | D19: =IF(AND(C19<0,C19>-1),LN(0.5)/LN(1+C19),"NA") | E19: output/v7/R4/compra/velocidad_ajuste_region.csv

Sheet 17_La_Rioja
A1: La Rioja (17): informativo, muestra ya vista en v1; C4; asociación
A3: Serie | B3: Periodo | C3: Inicio | D3: Valor inicio | E3: Fin | F3: Valor fin | G3: Variación | H3: Fuente
A4: IPV (INE) | B4: 2014T1-2019T4 | C4: 2014Q1 | D4: 59.449 | E4: 2019Q4 | F4: 69.86 | G4: =F4/D4-1 | H4: panel_ccaa_q_v7.csv, INE, hasta 2026Q2
A5: IPV (INE) | B5: 2020T1-2022T2 | C5: 2020Q1 | D5: 70.211 | E5: 2022Q2 | F5: 78.132 | G5: =F5/D5-1 | H5: panel_ccaa_q_v7.csv, INE, hasta 2026Q2
A6: IPV (INE) | B6: 2022T3-último | C6: 2022Q3 | D6: 79.856 | E6: 2026Q2 | F6: 113.309 | G6: =F6/D6-1 | H6: panel_ccaa_q_v7.csv, INE, hasta 2026Q2
A7: IPC alquiler (INE) | B7: 2014T1-2019T4 | C7: 2014Q1 | D7: 93.741667 | E7: 2019Q4 | F7: 91.688667 | G7: =F7/D7-1 | H7: panel_ccaa_q_v7.csv, INE, hasta 2026Q2
A8: IPC alquiler (INE) | B8: 2020T1-2022T2 | C8: 2020Q1 | D8: 92.148 | E8: 2022Q2 | F8: 94.567 | G8: =F8/D8-1 | H8: panel_ccaa_q_v7.csv, INE, hasta 2026Q2
A9: IPC alquiler (INE) | B9: 2022T3-último | C9: 2022Q3 | D9: 95.15 | E9: 2026Q2 | F9: 102.759 | G9: =F9/D9-1 | H9: panel_ccaa_q_v7.csv, INE, hasta 2026Q2
A11: Mercado | B11: Mejor modelo | C11: RMSE mejor ×100 | D11: RMSE base exigente ×100 | E11: Diferencia | F11: ¿Bate? | G11: Fuente
A12: alquiler | B12: gbm | C12: 0.41654259 | D12: 0.39913337 | E12: =D12-C12 | F12: =IF(E12>0,"sí","no") | G12: output/v7/R5/mejor_por_region.csv; informativo, muestra ya vista en v1
A13: compra | B13: ar4 | C13: 3.2000998 | D13: 2.4888805 | E13: =D13-C13 | F13: =IF(E13>0,"sí","no") | G13: output/v7/R5/mejor_por_region.csv; informativo, muestra ya vista en v1
A15: Mercado | B15: Spec | C15: φ (sin inferencia válida) | D15: Semivida (trim.) | E15: Fuente
A16: alquiler | B16: A | C16: -0.099223924 | D16: =IF(AND(C16<0,C16>-1),LN(0.5)/LN(1+C16),"NA") | E16: output/v7/R4/alquiler/velocidad_ajuste_region.csv
A17: alquiler | B17: B | C17: -0.013677494 | D17: =IF(AND(C17<0,C17>-1),LN(0.5)/LN(1+C17),"NA") | E17: output/v7/R4/alquiler/velocidad_ajuste_region.csv
A18: compra | B18: A | C18: -0.17851114 | D18: =IF(AND(C18<0,C18>-1),LN(0.5)/LN(1+C18),"NA") | E18: output/v7/R4/compra/velocidad_ajuste_region.csv
A19: compra | B19: B | C19: -0.06643463 | D19: =IF(AND(C19<0,C19>-1),LN(0.5)/LN(1+C19),"NA") | E19: output/v7/R4/compra/velocidad_ajuste_region.csv

Sheet DC_datos
A1: Dosis y coste a 10 años por CCAA (v7.1, C4). Datos de entrada en azul; fuente en la nota de B2 y en la fila final.
A2: CCAA (código INE) | B2: CCAA | C2: Instrumento | D2: Mercado | E2: Dosis (viviendas) | F2: Δ precio de mercado (%) | G2: Δ precio neto (%) | H2: Coste anual (M€) mediana | I2: p5 | J2: p95 | K2: Efecto por 10.000 viv. (pp) | L2: Efecto por 100 M€/año (pp) | M2: Coste por punto (M€/año) | N2: Estado del coste
A3: 01 | B3: Andalucía | C3: construcción adicional | D3: alquiler | E3: 0 | F3: 0 | G3: 0 | N3: coste no estimable: no hay coste unitario por vivienda (suelo, obra, financiación pública) verificado ni versionado; el escenario no fija quién paga
A4: 01 | B4: Andalucía | C4: construcción adicional | D4: compra | E4: 0 | F4: 0 | G4: 0 | N4: coste no estimable: no hay coste unitario por vivienda (suelo, obra, financiación pública) verificado ni versionado; el escenario no fija quién paga
A5: 01 | B5: Andalucía | C5: movilización de vacías | D5: alquiler | E5: 104104.65 | F5: -3.1603 | G5: -3.1603 | K5: -0.3059 | N5: coste no estimable: no hay coste unitario verificado de movilización (incentivo, rehabilitación, recargo del IBI) ni reparto entre recaudación y gasto
A6: 01 | B6: Andalucía | C6: movilización de vacías | D6: compra | E6: 104104.65 | F6: -1.1241 | G6: -1.1241 | K6: -0.108 | N6: coste no estimable: no hay coste unitario verificado de movilización (incentivo, rehabilitación, recargo del IBI) ni reparto entre recaudación y gasto
A7: 01 | B7: Andalucía | C7: vivienda pública o asequible | D7: alquiler | E7: 52944.317 | F7: -2.9615 | G7: -2.9615 | K7: -0.5598 | N7: coste no estimable: no hay coste unitario verificado por vivienda pública (v5 D1: «coste unitario sin dato verificado»)
A8: 01 | B8: Andalucía | C8: vivienda pública o asequible | D8: compra | E8: 52944.317 | F8: -0.574 | G8: -0.574 | K8: -0.108 | N8: coste no estimable: no hay coste unitario verificado por vivienda pública (v5 D1: «coste unitario sin dato verificado»)
A9: 01 | B9: Andalucía | C9: regulación local de turísticos | D9: alquiler | E9: 15773.294 | F9: -0.9661 | G9: -0.9661 | K9: -0.6201 | N9: coste no estimable: regulación sin coste fiscal directo verificable (inspección y compensaciones sin base)
A10: 01 | B10: Andalucía | C10: regulación local de turísticos | D10: compra | E10: 15773.294 | F10: -0.1715 | G10: -0.1715 | K10: -0.108 | N10: coste no estimable: regulación sin coste fiscal directo verificable (inspección y compensaciones sin base)
A11: 01 | B11: Andalucía | C11: ayudas a la demanda | D11: alquiler | E11: 142848 | F11: 4.3654 | G11: -5.3683 | N11: coste no estimable: el panel v7 no tiene renta media del alquiler en euros por CCAA ni número de hogares beneficiarios
A12: 01 | B12: Andalucía | C12: ayudas a la demanda | D12: compra | E12: 142848 | F12: 4.3654 | G12: -5.3683 | H12: 2405.2777 | I12: 1317.508 | J12: 3440.7783 | L12: 0.1919 | M12: 431.3037 | N12: estimado (C4)
A13: 01 | B13: Andalucía | C13: rebaja de ITP/IVA (vivienda nueva) | D13: compra | E13: 142848 | F13: 1.057 | G13: -1.2082 | H13: 595.9775 | I13: 271.7094 | J13: 917.3905 | L13: 0.1919 | M13: 459.7137 | N13: estimado (C4)
A14: 01 | B14: Andalucía | C14: rebaja de impuestos y costes de construcción | D14: alquiler | E14: 27454 | F14: -1.0317 | G14: -1.0317 | N14: coste anual igual al de compra (la rebaja es una sola); el efecto en alquiler es indirecto
A15: 01 | B15: Andalucía | C15: rebaja de impuestos y costes de construcción | D15: compra | E15: 27454 | F15: -1.0317 | G15: -1.0317 | H15: 97.7047 | I15: 51.7154 | J15: 160.8072 | L15: -1.1071 | M15: 90.323 | N15: estimado (C4)
A16: 02 | B16: Aragón | C16: construcción adicional | D16: alquiler | E16: 0 | F16: 0 | G16: 0 | N16: coste no estimable: no hay coste unitario por vivienda (suelo, obra, financiación pública) verificado ni versionado; el escenario no fija quién paga
A17: 02 | B17: Aragón | C17: construcción adicional | D17: compra | E17: 0 | F17: 0 | G17: 0 | N17: coste no estimable: no hay coste unitario por vivienda (suelo, obra, financiación pública) verificado ni versionado; el escenario no fija quién paga
A18: 02 | B18: Aragón | C18: movilización de vacías | D18: alquiler | E18: 23336.377 | F18: -4.0332 | G18: -4.0332 | K18: -1.7636 | N18: coste no estimable: no hay coste unitario verificado de movilización (incentivo, rehabilitación, recargo del IBI) ni reparto entre recaudación y gasto
A19: 02 | B19: Aragón | C19: movilización de vacías | D19: compra | E19: 23336.377 | F19: -1.4377 | G19: -1.4377 | K19: -0.6144 | N19: coste no estimable: no hay coste unitario verificado de movilización (incentivo, rehabilitación, recargo del IBI) ni reparto entre recaudación y gasto
A20: 02 | B20: Aragón | C20: vivienda pública o asequible | D20: alquiler | E20: 7085.0853 | F20: -2.2711 | G20: -2.2711 | K20: -3.1688 | N20: coste no estimable: no hay coste unitario verificado por vivienda pública (v5 D1: «coste unitario sin dato verificado»)
A21: 02 | B21: Aragón | C21: vivienda pública o asequible | D21: compra | E21: 7085.0853 | F21: -0.4428 | G21: -0.4428 | K21: -0.6144 | N21: coste no estimable: no hay coste unitario verificado por vivienda pública (v5 D1: «coste unitario sin dato verificado»)
A22: 02 | B22: Aragón | C22: regulación local de turísticos | D22: alquiler | E22: 649.8093 | F22: -0.2263 | G22: -0.2263 | K22: -3.5385 | N22: coste no estimable: regulación sin coste fiscal directo verificable (inspección y compensaciones sin base)
A23: 02 | B23: Aragón | C23: regulación local de turísticos | D23: compra | E23: 649.8093 | F23: -0.0396 | G23: -0.0396 | K23: -0.6144 | N23: coste no estimable: regulación sin coste fiscal directo verificable (inspección y compensaciones sin base)
A24: 02 | B24: Aragón | C24: ayudas a la demanda | D24: alquiler | E24: 18973 | F24: 4.3692 | G24: -5.2532 | N24: coste no estimable: el panel v7 no tiene renta media del alquiler en euros por CCAA ni número de hogares beneficiarios
A25: 02 | B25: Aragón | C25: ayudas a la demanda | D25: compra | E25: 18973 | F25: 4.3692 | G25: -5.2532 | H25: 280.7918 | I25: 155.1709 | J25: 406.868 | L25: 1.6499 | M25: 51.3424 | N25: estimado (C4)
A26: 02 | B26: Aragón | C26: rebaja de ITP/IVA (vivienda nueva) | D26: compra | E26: 18973 | F26: 1.0723 | G26: -1.2119 | H26: 70.1221 | I26: 32.3265 | J26: 108.3033 | L26: 1.6499 | M26: 54.7333 | N26: estimado (C4)
A27: 02 | B27: Aragón | C27: rebaja de impuestos y costes de construcción | D27: alquiler | E27: 4031 | F27: -1.0456 | G27: -1.0456 | N27: coste anual igual al de compra (la rebaja es una sola); el efecto en alquiler es indirecto
A28: 02 | B28: Aragón | C28: rebaja de impuestos y costes de construcción | D28: compra | E28: 4031 | F28: -1.0456 | G28: -1.0456 | H28: 12.9301 | I28: 6.8055 | J28: 21.0536 | L28: -8.4066 | M28: 11.8955 | N28: estimado (C4)
A29: 03 | B29: Asturias | C29: construcción adicional | D29: alquiler | E29: 0 | F29: 0 | G29: 0 | N29: coste no estimable: no hay coste unitario por vivienda (suelo, obra, financiación pública) verificado ni versionado; el escenario no fija quién paga
A30: 03 | B30: Asturias | C30: construcción adicional | D30: compra | E30: 0 | F30: 0 | G30: 0 | N30: coste no estimable: no hay coste unitario por vivienda (suelo, obra, financiación pública) verificado ni versionado; el escenario no fija quién paga
A31: 03 | B31: Asturias | C31: movilización de vacías | D31: alquiler | E31: 18269.324 | F31: -3.7759 | G31: -3.7759 | K31: -2.1087 | N31: coste no estimable: no hay coste unitario verificado de movilización (incentivo, rehabilitación, recargo del IBI) ni reparto entre recaudación y gasto
A32: 03 | B32: Asturias | C32: movilización de vacías | D32: compra | E32: 18269.324 | F32: -1.3406 | G32: -1.3406 | K32: -0.7372 | N32: coste no estimable: no hay coste unitario verificado de movilización (incentivo, rehabilitación, recargo del IBI) ni reparto entre recaudación y gasto
A33: 03 | B33: Asturias | C33: vivienda pública o asequible | D33: alquiler | E33: 2090.4314 | F33: -0.809 | G33: -0.809 | K33: -3.8136 | N33: coste no estimable: no hay coste unitario verificado por vivienda pública (v5 D1: «coste unitario sin dato verificado»)
A34: 03 | B34: Asturias | C34: vivienda pública o asequible | D34: compra | E34: 2090.4314 | F34: -0.1573 | G34: -0.1573 | K34: -0.7372 | N34: coste no estimable: no hay coste unitario verificado por vivienda pública (v5 D1: «coste unitario sin dato verificado»)
A35: 03 | B35: Asturias | C35: regulación local de turísticos | D35: alquiler | E35: 2125.348 | F35: -0.8936 | G35: -0.8936 | K35: -4.2476 | N35: coste no estimable: regulación sin coste fiscal directo verificable (inspección y compensaciones sin base)
A36: 03 | B36: Asturias | C36: regulación local de turísticos | D36: compra | E36: 2125.348 | F36: -0.1574 | G36: -0.1574 | K36: -0.7372 | N36: coste no estimable: regulación sin coste fiscal directo verificable (inspección y compensaciones sin base)
A37: 03 | B37: Asturias | C37: ayudas a la demanda | D37: alquiler | E37: 15638 | F37: 4.1407 | G37: -5.3871 | N37: coste no estimable: el panel v7 no tiene renta media del alquiler en euros por CCAA ni número de hogares beneficiarios
A38: 03 | B38: Asturias | C38: ayudas a la demanda | D38: compra | E38: 15638 | F38: 4.1407 | G38: -5.3871 | H38: 232.6676 | I38: 128.851 | J38: 341.0733 | L38: 1.8896 | M38: 41.422 | N38: estimado (C4)
A39: 03 | B39: Asturias | C39: rebaja de ITP/IVA (vivienda nueva) | D39: compra | E39: 15638 | F39: 1.0107 | G39: -1.2468 | H39: 58.1955 | I39: 27.4788 | J39: 90.2953 | L39: 1.8896 | M39: 43.9904 | N39: estimado (C4)
A40: 03 | B40: Asturias | C40: rebaja de impuestos y costes de construcción | D40: alquiler | E40: 3096 | F40: -1.076 | G40: -1.076 | N40: coste anual igual al de compra (la rebaja es una sola); el efecto en alquiler es indirecto
...

Sheet DC_calculos
A1: Cálculos de esta hoja (negro) a partir de DC_datos (enlaces en verde).
A2: CCAA | B2: Instrumento | C2: Mercado | D2: Coste anual (M€) | E2: Coste a 10 años (M€) | F2: Δ precio de mercado (%) | G2: Cociente de medianas: pp por 100 M€ anuales | H2: Nota
A3: =DC_datos!B3 | B3: =DC_datos!C3 | C3: =DC_datos!D3 | D3: =DC_datos!H3 | E3: =IF(ISNUMBER(D3),10*D3,"no estimable") | F3: =DC_datos!F3 | G3: =IF(ISNUMBER(D3),F3*100/D3,"—") | H3: cociente de medianas (difiere algo de la mediana del cociente de DC_datos)
A4: =DC_datos!B4 | B4: =DC_datos!C4 | C4: =DC_datos!D4 | D4: =DC_datos!H4 | E4: =IF(ISNUMBER(D4),10*D4,"no estimable") | F4: =DC_datos!F4 | G4: =IF(ISNUMBER(D4),F4*100/D4,"—") | H4: cociente de medianas (difiere algo de la mediana del cociente de DC_datos)
A5: =DC_datos!B5 | B5: =DC_datos!C5 | C5: =DC_datos!D5 | D5: =DC_datos!H5 | E5: =IF(ISNUMBER(D5),10*D5,"no estimable") | F5: =DC_datos!F5 | G5: =IF(ISNUMBER(D5),F5*100/D5,"—") | H5: cociente de medianas (difiere algo de la mediana del cociente de DC_datos)
A6: =DC_datos!B6 | B6: =DC_datos!C6 | C6: =DC_datos!D6 | D6: =DC_datos!H6 | E6: =IF(ISNUMBER(D6),10*D6,"no estimable") | F6: =DC_datos!F6 | G6: =IF(ISNUMBER(D6),F6*100/D6,"—") | H6: cociente de medianas (difiere algo de la mediana del cociente de DC_datos)
A7: =DC_datos!B7 | B7: =DC_datos!C7 | C7: =DC_datos!D7 | D7: =DC_datos!H7 | E7: =IF(ISNUMBER(D7),10*D7,"no estimable") | F7: =DC_datos!F7 | G7: =IF(ISNUMBER(D7),F7*100/D7,"—") | H7: cociente de medianas (difiere algo de la mediana del cociente de DC_datos)
A8: =DC_datos!B8 | B8: =DC_datos!C8 | C8: =DC_datos!D8 | D8: =DC_datos!H8 | E8: =IF(ISNUMBER(D8),10*D8,"no estimable") | F8: =DC_datos!F8 | G8: =IF(ISNUMBER(D8),F8*100/D8,"—") | H8: cociente de medianas (difiere algo de la mediana del cociente de DC_datos)
A9: =DC_datos!B9 | B9: =DC_datos!C9 | C9: =DC_datos!D9 | D9: =DC_datos!H9 | E9: =IF(ISNUMBER(D9),10*D9,"no estimable") | F9: =DC_datos!F9 | G9: =IF(ISNUMBER(D9),F9*100/D9,"—") | H9: cociente de medianas (difiere algo de la mediana del cociente de DC_datos)
A10: =DC_datos!B10 | B10: =DC_datos!C10 | C10: =DC_datos!D10 | D10: =DC_datos!H10 | E10: =IF(ISNUMBER(D10),10*D10,"no estimable") | F10: =DC_datos!F10 | G10: =IF(ISNUMBER(D10),F10*100/D10,"—") | H10: cociente de medianas (difiere algo de la mediana del cociente de DC_datos)
A11: =DC_datos!B11 | B11: =DC_datos!C11 | C11: =DC_datos!D11 | D11: =DC_datos!H11 | E11: =IF(ISNUMBER(D11),10*D11,"no estimable") | F11: =DC_datos!F11 | G11: =IF(ISNUMBER(D11),F11*100/D11,"—") | H11: cociente de medianas (difiere algo de la mediana del cociente de DC_datos)
A12: =DC_datos!B12 | B12: =DC_datos!C12 | C12: =DC_datos!D12 | D12: =DC_datos!H12 | E12: =IF(ISNUMBER(D12),10*D12,"no estimable") | F12: =DC_datos!F12 | G12: =IF(ISNUMBER(D12),F12*100/D12,"—") | H12: cociente de medianas (difiere algo de la mediana del cociente de DC_datos)
A13: =DC_datos!B13 | B13: =DC_datos!C13 | C13: =DC_datos!D13 | D13: =DC_datos!H13 | E13: =IF(ISNUMBER(D13),10*D13,"no estimable") | F13: =DC_datos!F13 | G13: =IF(ISNUMBER(D13),F13*100/D13,"—") | H13: cociente de medianas (difiere algo de la mediana del cociente de DC_datos)
A14: =DC_datos!B14 | B14: =DC_datos!C14 | C14: =DC_datos!D14 | D14: =DC_datos!H14 | E14: =IF(ISNUMBER(D14),10*D14,"no estimable") | F14: =DC_datos!F14 | G14: =IF(ISNUMBER(D14),F14*100/D14,"—") | H14: cociente de medianas (difiere algo de la mediana del cociente de DC_datos)
... A223: =DC_datos!B223 | B223: =DC_datos!C223 | C223: =DC_datos!D223 | D223: =DC_datos!H223 | E223: =IF(ISNUMBER(D223),10*D223,"no estimable") | F223: =DC_datos!F223 | G223: =IF(ISNUMBER(D223),F223*100/D223,"—") | H223: cociente de medianas (difiere algo de la mediana del cociente de DC_datos)

Sheet DC_resumen
A1: Resumen nacional a 10 años: mediana entre CCAA (cálculo en negro sobre enlaces a DC_datos).
A2: Instrumento | B2: Mercado | C2: Dosis mediana | D2: Δ precio de mercado mediano (%) | E2: Coste anual mediano (M€) | F2: Efecto por 10.000 viv. (pp) | G2: Efecto por 100 M€/año (pp)
A3: movilización de vacías | B3: compra | C3: {=IFERROR(MEDIAN(IF((DC_datos!C3:C223="movilización de vacías")*(DC_datos!D3:D223="compra")*ISNUMBER(DC_datos!E3:E223),DC_datos!E3:E223)),"—")} | D3: {=IFERROR(MEDIAN(IF((DC_datos!C3:C223="movilización de vacías")*(DC_datos!D3:D223="compra")*ISNUMBER(DC_datos!F3:F223),DC_datos!F3:F223)),"—")} | E3: {=IFERROR(MEDIAN(IF((DC_datos!C3:C223="movilización de vacías")*(DC_datos!D3:D223="compra")*ISNUMBER(DC_datos!H3:H223),DC_datos!H3:H223)),"—")} | F3: {=IFERROR(MEDIAN(IF((DC_datos!C3:C223="movilización de vacías")*(DC_datos!D3:D223="compra")*ISNUMBER(DC_datos!K3:K223),DC_datos!K3:K223)),"—")} | G3: {=IFERROR(MEDIAN(IF((DC_datos!C3:C223="movilización de vacías")*(DC_datos!D3:D223="compra")*ISNUMBER(DC_datos!L3:L223),DC_datos!L3:L223)),"—")}
A4: movilización de vacías | B4: alquiler | C4: {=IFERROR(MEDIAN(IF((DC_datos!C3:C223="movilización de vacías")*(DC_datos!D3:D223="alquiler")*ISNUMBER(DC_datos!E3:E223),DC_datos!E3:E223)),"—")} | D4: {=IFERROR(MEDIAN(IF((DC_datos!C3:C223="movilización de vacías")*(DC_datos!D3:D223="alquiler")*ISNUMBER(DC_datos!F3:F223),DC_datos!F3:F223)),"—")} | E4: {=IFERROR(MEDIAN(IF((DC_datos!C3:C223="movilización de vacías")*(DC_datos!D3:D223="alquiler")*ISNUMBER(DC_datos!H3:H223),DC_datos!H3:H223)),"—")} | F4: {=IFERROR(MEDIAN(IF((DC_datos!C3:C223="movilización de vacías")*(DC_datos!D3:D223="alquiler")*ISNUMBER(DC_datos!K3:K223),DC_datos!K3:K223)),"—")} | G4: {=IFERROR(MEDIAN(IF((DC_datos!C3:C223="movilización de vacías")*(DC_datos!D3:D223="alquiler")*ISNUMBER(DC_datos!L3:L223),DC_datos!L3:L223)),"—")}
A5: vivienda pública o asequible | B5: compra | C5: {=IFERROR(MEDIAN(IF((DC_datos!C3:C223="vivienda pública o asequible")*(DC_datos!D3:D223="compra")*ISNUMBER(DC_datos!E3:E223),DC_datos!E3:E223)),"—")} | D5: {=IFERROR(MEDIAN(IF((DC_datos!C3:C223="vivienda pública o asequible")*(DC_datos!D3:D223="compra")*ISNUMBER(DC_datos!F3:F223),DC_datos!F3:F223)),"—")} | E5: {=IFERROR(MEDIAN(IF((DC_datos!C3:C223="vivienda pública o asequible")*(DC_datos!D3:D223="compra")*ISNUMBER(DC_datos!H3:H223),DC_datos!H3:H223)),"—")} | F5: {=IFERROR(MEDIAN(IF((DC_datos!C3:C223="vivienda pública o asequible")*(DC_datos!D3:D223="compra")*ISNUMBER(DC_datos!K3:K223),DC_datos!K3:K223)),"—")} | G5: {=IFERROR(MEDIAN(IF((DC_datos!C3:C223="vivienda pública o asequible")*(DC_datos!D3:D223="compra")*ISNUMBER(DC_datos!L3:L223),DC_datos!L3:L223)),"—")}
A6: vivienda pública o asequible | B6: alquiler | C6: {=IFERROR(MEDIAN(IF((DC_datos!C3:C223="vivienda pública o asequible")*(DC_datos!D3:D223="alquiler")*ISNUMBER(DC_datos!E3:E223),DC_datos!E3:E223)),"—")} | D6: {=IFERROR(MEDIAN(IF((DC_datos!C3:C223="vivienda pública o asequible")*(DC_datos!D3:D223="alquiler")*ISNUMBER(DC_datos!F3:F223),DC_datos!F3:F223)),"—")} | E6: {=IFERROR(MEDIAN(IF((DC_datos!C3:C223="vivienda pública o asequible")*(DC_datos!D3:D223="alquiler")*ISNUMBER(DC_datos!H3:H223),DC_datos!H3:H223)),"—")} | F6: {=IFERROR(MEDIAN(IF((DC_datos!C3:C223="vivienda pública o asequible")*(DC_datos!D3:D223="alquiler")*ISNUMBER(DC_datos!K3:K223),DC_datos!K3:K223)),"—")} | G6: {=IFERROR(MEDIAN(IF((DC_datos!C3:C223="vivienda pública o asequible")*(DC_datos!D3:D223="alquiler")*ISNUMBER(DC_datos!L3:L223),DC_datos!L3:L223)),"—")}
