Workbook

Sheet Resumen
A1: Resumen V12 (vínculos a las hojas de cálculo)
A2: Celdas en verde: vínculos a otras hojas. Descriptivo (C4).
A4: Crecimiento de la población, último periodo | B4: ='B1_poblacion'!D8
A5: Saldo con el extranjero, último periodo | B5: ='B1_poblacion'!F8
A6: Saldo vegetativo, último periodo | B6: ='B1_poblacion'!E8
A7: Hogares nuevos 2021-2024 (provincias) | B7: =SUM('B4_oferta'!B4:B55)
A8: Obra nueva neta Catastro 2021-2024 (provincias con dato) | B8: =SUM('B4_oferta'!C4:C55)
A9: Viviendas de titulares con > 10 (España, %) | B9: ='B5_titularidad'!H4
A10: Viviendas de personas jurídicas (España, %) | B10: ='B5_titularidad'!J4
A11: Crecimiento de hogares 2011-2021 (suma de provincias) | B11: =SUM('B3_hogares'!G4:G55)

Sheet B1_poblacion
A1: B1_poblacion
A2: Fuente de las entradas (azul): INE: padrón y censo anual, MNP, EVR/EMCR (output/v12/b1). Cálculos en negro (fórmulas).
A3: periodo | B3: anios | C3: poblacion_inicio | D3: crecimiento | E3: vegetativo | F3: saldo_exterior | G3: saldo_interior | H3: residuo | I3: saldo_exterior_por_mil_anual | J3: vegetativo_por_mil_anual
A4: 2003-2007 | B4: 5 | C4: 42717064 | D4: 3440758 | E4: 441232 | F4: 3154542 | G4: 0 | H4: =D4-E4-F4-G4 | I4: =1000*F4/C4/B4 | J4: =1000*E4/C4/B4
A5: 2008-2013 | B5: 6 | C5: 46157822 | D5: 613519 | E5: 522433 | F5: 691833 | G5: 0 | H5: =D5-E5-F5-G5 | I5: =1000*F5/C5/B5 | J5: =1000*E5/C5/B5
A6: 2014-2019 | B6: 6 | C6: 46771341 | D6: 679454 | E6: -111584 | F6: 1272915 | G6: 0 | H6: =D6-E6-F6-G6 | I6: =1000*F6/C6/B6 | J6: =1000*E6/C6/B6
A7: 2020-2021 | B7: 2 | C7: 47450795 | D7: 24625 | E7: -264138 | F7: 443487 | G7: 0 | H7: =D7-E7-F7-G7 | I7: =1000*F7/C7/B7 | J7: =1000*E7/C7/B7
A8: 2022-2024 | B8: 3 | C8: 47486727 | D8: 1641570 | E8: -362896 | F8: 1995569 | G8: 0 | H8: =D8-E8-F8-G8 | I8: =1000*F8/C8/B8 | J8: =1000*E8/C8/B8

Sheet B3_hogares
A1: B3_hogares
A2: Fuente de las entradas (azul): INE, Censos 2011 y 2021 (microdatos); output/v12/b3. Cálculos en negro (fórmulas).
A3: cpro | B3: hogares_2011 | C3: hogares_2021 | D3: poblacion_A | E3: estructura_A | F3: jefatura_A | G3: crecimiento | H3: control_suma_A | I3: pct_jefatura_A
A4: 01 | B4: 135107.19 | C4: 140218 | D4: 5206.189 | E4: 3018.1948 | F4: -3113.5703 | G4: =C4-B4 | H4: =D4+E4+F4-(C4-B4) | I4: =100*F4/ABS(C4-B4)
A5: 02 | B5: 149373.21 | C5: 151262 | D5: -5878.8032 | E5: 10380.996 | F5: -2613.4079 | G5: =C5-B5 | H5: =D5+E5+F5-(C5-B5) | I5: =100*F5/ABS(C5-B5)
A6: 03 | B6: 738366.54 | C6: 754099 | D6: 11614.876 | E6: 36957.896 | F6: -32840.315 | G6: =C6-B6 | H6: =D6+E6+F6-(C6-B6) | I6: =100*F6/ABS(C6-B6)
A7: 04 | B7: 249308.77 | C7: 275726 | D7: 14426.849 | E7: 17374.635 | F7: -5384.2491 | G7: =C7-B7 | H7: =D7+E7+F7-(C7-B7) | I7: =100*F7/ABS(C7-B7)
A8: 05 | B8: 69316.103 | C8: 69768 | D8: -5286.5853 | E8: 3547.7427 | F8: 2190.7395 | G8: =C8-B8 | H8: =D8+E8+F8-(C8-B8) | I8: =100*F8/ABS(C8-B8)
A9: 06 | B9: 259955.1 | C9: 266157 | D9: -7644.0284 | E9: 17960.635 | F9: -4114.7069 | G9: =C9-B9 | H9: =D9+E9+F9-(C9-B9) | I9: =100*F9/ABS(C9-B9)
A10: 07 | B10: 429737.02 | C10: 441536 | D10: 32219.519 | E10: 21584.802 | F10: -42005.336 | G10: =C10-B10 | H10: =D10+E10+F10-(C10-B10) | I10: =100*F10/ABS(C10-B10)
A11: 08 | B11: 2168607.1 | C11: 2197826 | D11: 62289.149 | E11: 77450.084 | F11: -110520.35 | G11: =C11-B11 | H11: =D11+E11+F11-(C11-B11) | I11: =100*F11/ABS(C11-B11)
A12: 09 | B12: 151831.33 | C12: 152331 | D12: -7580.2851 | E12: 7148.6015 | F12: 931.35819 | G12: =C12-B12 | H12: =D12+E12+F12-(C12-B12) | I12: =100*F12/ABS(C12-B12)
A13: 10 | B13: 165024.86 | C13: 168207 | D13: -8833.6031 | E13: 12692.858 | F13: -677.11321 | G13: =C13-B13 | H13: =D13+E13+F13-(C13-B13) | I13: =100*F13/ABS(C13-B13)
A14: 11 | B14: 447974.74 | C14: 468478 | D14: 2152.7978 | E14: 41318.888 | F14: -22968.423 | G14: =C14-B14 | H14: =D14+E14+F14-(C14-B14) | I14: =100*F14/ABS(C14-B14)
A15: 12 | B15: 233871.16 | C15: 238331 | D15: -2216.0066 | E15: 12289.149 | F15: -5613.3036 | G15: =C15-B15 | H15: =D15+E15+F15-(C15-B15) | I15: =100*F15/ABS(C15-B15)
... A55: 52 | B55: 24666.011 | C55: 25578 | D55: 1495.5115 | E55: 1570.6932 | F55: -2154.2155 | G55: =C55-B55 | H55: =D55+E55+F55-(C55-B55) | I55: =100*F55/ABS(C55-B55)

Sheet B4_oferta
A1: B4_oferta
A2: Fuente de las entradas (azul): INE ECP (hogares); Catastro URBANA; MIVAU (output/v12/b4). Cálculos en negro (fórmulas).
A3: cpro | B3: hogares_nuevos_ecp | C3: obra_neta_catastro | D3: terminadas_mivau | E3: ratio_catastro_hogares | F3: ratio_mivau_hogares | G3: diferencia_catastro_mivau_pct
A4: 01 | B4: 5562 | D4: 2930 | E4: =IF(AND(ISNUMBER(C4),B4>0),C4/B4,"") | F4: =IF(AND(ISNUMBER(D4),B4>0),D4/B4,"") | G4: =IF(AND(ISNUMBER(C4),ISNUMBER(D4),D4>0),100*(C4/D4-1),"")
A5: 02 | B5: 5944 | C5: 2103 | D5: 3042 | E5: =IF(AND(ISNUMBER(C5),B5>0),C5/B5,"") | F5: =IF(AND(ISNUMBER(D5),B5>0),D5/B5,"") | G5: =IF(AND(ISNUMBER(C5),ISNUMBER(D5),D5>0),100*(C5/D5-1),"")
A6: 03 | B6: 64333 | C6: 21022 | D6: 18551 | E6: =IF(AND(ISNUMBER(C6),B6>0),C6/B6,"") | F6: =IF(AND(ISNUMBER(D6),B6>0),D6/B6,"") | G6: =IF(AND(ISNUMBER(C6),ISNUMBER(D6),D6>0),100*(C6/D6-1),"")
A7: 04 | B7: 19868 | C7: 4100 | D7: 4278 | E7: =IF(AND(ISNUMBER(C7),B7>0),C7/B7,"") | F7: =IF(AND(ISNUMBER(D7),B7>0),D7/B7,"") | G7: =IF(AND(ISNUMBER(C7),ISNUMBER(D7),D7>0),100*(C7/D7-1),"")
A8: 05 | B8: 2103 | C8: 1154 | D8: 1022 | E8: =IF(AND(ISNUMBER(C8),B8>0),C8/B8,"") | F8: =IF(AND(ISNUMBER(D8),B8>0),D8/B8,"") | G8: =IF(AND(ISNUMBER(C8),ISNUMBER(D8),D8>0),100*(C8/D8-1),"")
A9: 06 | B9: 7901 | C9: 5467 | D9: 2959 | E9: =IF(AND(ISNUMBER(C9),B9>0),C9/B9,"") | F9: =IF(AND(ISNUMBER(D9),B9>0),D9/B9,"") | G9: =IF(AND(ISNUMBER(C9),ISNUMBER(D9),D9>0),100*(C9/D9-1),"")
A10: 07 | B10: 24612 | C10: 10623 | D10: 12047 | E10: =IF(AND(ISNUMBER(C10),B10>0),C10/B10,"") | F10: =IF(AND(ISNUMBER(D10),B10>0),D10/B10,"") | G10: =IF(AND(ISNUMBER(C10),ISNUMBER(D10),D10>0),100*(C10/D10-1),"")
A11: 08 | B11: 115006 | C11: 42483 | D11: 37533 | E11: =IF(AND(ISNUMBER(C11),B11>0),C11/B11,"") | F11: =IF(AND(ISNUMBER(D11),B11>0),D11/B11,"") | G11: =IF(AND(ISNUMBER(C11),ISNUMBER(D11),D11>0),100*(C11/D11-1),"")
A12: 09 | B12: 6067 | C12: 3162 | D12: 3309 | E12: =IF(AND(ISNUMBER(C12),B12>0),C12/B12,"") | F12: =IF(AND(ISNUMBER(D12),B12>0),D12/B12,"") | G12: =IF(AND(ISNUMBER(C12),ISNUMBER(D12),D12>0),100*(C12/D12-1),"")
A13: 10 | B13: 3730 | C13: 2963 | D13: 3516 | E13: =IF(AND(ISNUMBER(C13),B13>0),C13/B13,"") | F13: =IF(AND(ISNUMBER(D13),B13>0),D13/B13,"") | G13: =IF(AND(ISNUMBER(C13),ISNUMBER(D13),D13>0),100*(C13/D13-1),"")
A14: 11 | B14: 21193 | C14: 11017 | D14: 8254 | E14: =IF(AND(ISNUMBER(C14),B14>0),C14/B14,"") | F14: =IF(AND(ISNUMBER(D14),B14>0),D14/B14,"") | G14: =IF(AND(ISNUMBER(C14),ISNUMBER(D14),D14>0),100*(C14/D14-1),"")
A15: 12 | B15: 17873 | C15: 3968 | D15: 3076 | E15: =IF(AND(ISNUMBER(C15),B15>0),C15/B15,"") | F15: =IF(AND(ISNUMBER(D15),B15>0),D15/B15,"") | G15: =IF(AND(ISNUMBER(C15),ISNUMBER(D15),D15>0),100*(C15/D15-1),"")
A16: 13 | B16: 6677 | C16: 1626 | D16: 3781 | E16: =IF(AND(ISNUMBER(C16),B16>0),C16/B16,"") | F16: =IF(AND(ISNUMBER(D16),B16>0),D16/B16,"") | G16: =IF(AND(ISNUMBER(C16),ISNUMBER(D16),D16>0),100*(C16/D16-1),"")
... A22: 19 | B22: 8252 | C22: 2652 | D22: 4353 | E22: =IF(AND(ISNUMBER(C22),B22>0),C22/B22,"") | F22: =IF(AND(ISNUMBER(D22),B22>0),D22/B22,"") | G22: =IF(AND(ISNUMBER(C22),ISNUMBER(D22),D22>0),100*(C22/D22-1),"")
A23: 20 | B23: 8777 | D23: 6495 | E23: =IF(AND(ISNUMBER(C23),B23>0),C23/B23,"") | F23: =IF(AND(ISNUMBER(D23),B23>0),D23/B23,"") | G23: =IF(AND(ISNUMBER(C23),ISNUMBER(D23),D23>0),100*(C23/D23-1),"")
A24: 21 | B24: 8537 | C24: 3981 | D24: 3241 | E24: =IF(AND(ISNUMBER(C24),B24>0),C24/B24,"") | F24: =IF(AND(ISNUMBER(D24),B24>0),D24/B24,"") | G24: =IF(AND(ISNUMBER(C24),ISNUMBER(D24),D24>0),100*(C24/D24-1),"")
A25: 22 | B25: 3978 | C25: 1373 | D25: 1886 | E25: =IF(AND(ISNUMBER(C25),B25>0),C25/B25,"") | F25: =IF(AND(ISNUMBER(D25),B25>0),D25/B25,"") | G25: =IF(AND(ISNUMBER(C25),ISNUMBER(D25),D25>0),100*(C25/D25-1),"")
A26: 23 | B26: 5999 | C26: 2348 | D26: 2511 | E26: =IF(AND(ISNUMBER(C26),B26>0),C26/B26,"") | F26: =IF(AND(ISNUMBER(D26),B26>0),D26/B26,"") | G26: =IF(AND(ISNUMBER(C26),ISNUMBER(D26),D26>0),100*(C26/D26-1),"")
A27: 24 | B27: 4236 | C27: 2094 | D27: 1768 | E27: =IF(AND(ISNUMBER(C27),B27>0),C27/B27,"") | F27: =IF(AND(ISNUMBER(D27),B27>0),D27/B27,"") | G27: =IF(AND(ISNUMBER(C27),ISNUMBER(D27),D27>0),100*(C27/D27-1),"")
A28: 25 | B28: 9011 | C28: 2675 | D28: 2298 | E28: =IF(AND(ISNUMBER(C28),B28>0),C28/B28,"") | F28: =IF(AND(ISNUMBER(D28),B28>0),D28/B28,"") | G28: =IF(AND(ISNUMBER(C28),ISNUMBER(D28),D28>0),100*(C28/D28-1),"")
A29: 26 | B29: 5779 | C29: 1898 | D29: 3614 | E29: =IF(AND(ISNUMBER(C29),B29>0),C29/B29,"") | F29: =IF(AND(ISNUMBER(D29),B29>0),D29/B29,"") | G29: =IF(AND(ISNUMBER(C29),ISNUMBER(D29),D29>0),100*(C29/D29-1),"")
A30: 27 | B30: 3566 | C30: 85 | D30: 889 | E30: =IF(AND(ISNUMBER(C30),B30>0),C30/B30,"") | F30: =IF(AND(ISNUMBER(D30),B30>0),D30/B30,"") | G30: =IF(AND(ISNUMBER(C30),ISNUMBER(D30),D30>0),100*(C30/D30-1),"")
A31: 28 | B31: 161957 | C31: 73931 | D31: 79010 | E31: =IF(AND(ISNUMBER(C31),B31>0),C31/B31,"") | F31: =IF(AND(ISNUMBER(D31),B31>0),D31/B31,"") | G31: =IF(AND(ISNUMBER(C31),ISNUMBER(D31),D31>0),100*(C31/D31-1),"")
A32: 29 | B32: 46567 | C32: 22451 | D32: 23057 | E32: =IF(AND(ISNUMBER(C32),B32>0),C32/B32,"") | F32: =IF(AND(ISNUMBER(D32),B32>0),D32/B32,"") | G32: =IF(AND(ISNUMBER(C32),ISNUMBER(D32),D32>0),100*(C32/D32-1),"")
A33: 30 | B33: 39233 | C33: 7683 | D33: 9090 | E33: =IF(AND(ISNUMBER(C33),B33>0),C33/B33,"") | F33: =IF(AND(ISNUMBER(D33),B33>0),D33/B33,"") | G33: =IF(AND(ISNUMBER(C33),ISNUMBER(D33),D33>0),100*(C33/D33-1),"")
A34: 31 | B34: 13534 | D34: 9383 | E34: =IF(AND(ISNUMBER(C34),B34>0),C34/B34,"") | F34: =IF(AND(ISNUMBER(D34),B34>0),D34/B34,"") | G34: =IF(AND(ISNUMBER(C34),ISNUMBER(D34),D34>0),100*(C34/D34-1),"")
A35: 32 | B35: 3113 | C35: 89 | D35: 788 | E35: =IF(AND(ISNUMBER(C35),B35>0),C35/B35,"") | F35: =IF(AND(ISNUMBER(D35),B35>0),D35/B35,"") | G35: =IF(AND(ISNUMBER(C35),ISNUMBER(D35),D35>0),100*(C35/D35-1),"")
A36: 33 | B36: 10768 | C36: 8014 | D36: 7488 | E36: =IF(AND(ISNUMBER(C36),B36>0),C36/B36,"") | F36: =IF(AND(ISNUMBER(D36),B36>0),D36/B36,"") | G36: =IF(AND(ISNUMBER(C36),ISNUMBER(D36),D36>0),100*(C36/D36-1),"")
A37: 34 | B37: 1474 | C37: -155 | D37: 1107 | E37: =IF(AND(ISNUMBER(C37),B37>0),C37/B37,"") | F37: =IF(AND(ISNUMBER(D37),B37>0),D37/B37,"") | G37: =IF(AND(ISNUMBER(C37),ISNUMBER(D37),D37>0),100*(C37/D37-1),"")
A38: 35 | B38: 22015 | C38: 11110 | D38: 5845 | E38: =IF(AND(ISNUMBER(C38),B38>0),C38/B38,"") | F38: =IF(AND(ISNUMBER(D38),B38>0),D38/B38,"") | G38: =IF(AND(ISNUMBER(C38),ISNUMBER(D38),D38>0),100*(C38/D38-1),"")
A39: 36 | B39: 11029 | C39: 5963 | D39: 4250 | E39: =IF(AND(ISNUMBER(C39),B39>0),C39/B39,"") | F39: =IF(AND(ISNUMBER(D39),B39>0),D39/B39,"") | G39: =IF(AND(ISNUMBER(C39),ISNUMBER(D39),D39>0),100*(C39/D39-1),"")
A40: 37 | B40: 4749 | C40: 1575 | D40: 1656 | E40: =IF(AND(ISNUMBER(C40),B40>0),C40/B40,"") | F40: =IF(AND(ISNUMBER(D40),B40>0),D40/B40,"") | G40: =IF(AND(ISNUMBER(C40),ISNUMBER(D40),D40>0),100*(C40/D40-1),"")
A41: 38 | B41: 19734 | C41: 7367 | D41: 4944 | E41: =IF(AND(ISNUMBER(C41),B41>0),C41/B41,"") | F41: =IF(AND(ISNUMBER(D41),B41>0),D41/B41,"") | G41: =IF(AND(ISNUMBER(C41),ISNUMBER(D41),D41>0),100*(C41/D41-1),"")
A42: 39 | B42: 8914 | C42: 2830 | D42: 3629 | E42: =IF(AND(ISNUMBER(C42),B42>0),C42/B42,"") | F42: =IF(AND(ISNUMBER(D42),B42>0),D42/B42,"") | G42: =IF(AND(ISNUMBER(C42),ISNUMBER(D42),D42>0),100*(C42/D42-1),"")
A43: 40 | B43: 3098 | C43: 1291 | D43: 1332 | E43: =IF(AND(ISNUMBER(C43),B43>0),C43/B43,"") | F43: =IF(AND(ISNUMBER(D43),B43>0),D43/B43,"") | G43: =IF(AND(ISNUMBER(C43),ISNUMBER(D43),D43>0),100*(C43/D43-1),"")
A44: 41 | B44: 32819 | C44: 17080 | D44: 18191 | E44: =IF(AND(ISNUMBER(C44),B44>0),C44/B44,"") | F44: =IF(AND(ISNUMBER(D44),B44>0),D44/B44,"") | G44: =IF(AND(ISNUMBER(C44),ISNUMBER(D44),D44>0),100*(C44/D44-1),"")
A45: 42 | B45: 1415 | C45: 759 | D45: 1952 | E45: =IF(AND(ISNUMBER(C45),B45>0),C45/B45,"") | F45: =IF(AND(ISNUMBER(D45),B45>0),D45/B45,"") | G45: =IF(AND(ISNUMBER(C45),ISNUMBER(D45),D45>0),100*(C45/D45-1),"")
...

Sheet B5_titularidad
A1: B5_titularidad
A2: Fuente de las entradas (azul): Catastro, titularidad (uso residencial; tramos dentro del ámbito); output/v12/b5. Cálculos en negro (fórmulas).
A3: nivel | B3: cod_territorio | C3: viviendas | D3: viv_mas10 | E3: viv_mas100 | F3: viv_PJ | G3: viv_PE | H3: pct_mas10 | I3: pct_mas100 | J3: pct_PJ | K3: pct_PE
A4: nacional | B4: 00 | C4: 24332088 | D4: 1013400 | E4: 500981 | F4: 1115198 | G4: 262394 | H4: =100*D4/C4 | I4: =100*E4/C4 | J4: =100*F4/C4 | K4: =100*G4/C4
A5: provincia | B5: 04 | C5: 411323 | D5: 20381 | E5: 9595 | F5: 26046 | G5: 4845 | H5: =100*D5/C5 | I5: =100*E5/C5 | J5: =100*F5/C5 | K5: =100*G5/C5
A6: provincia | B6: 11 | C6: 613368 | D6: 29531 | E6: 21972 | F6: 25423 | G6: 16047 | H6: =100*D6/C6 | I6: =100*E6/C6 | J6: =100*F6/C6 | K6: =100*G6/C6
A7: provincia | B7: 14 | C7: 405341 | D7: 12593 | E7: 8320 | F7: 10981 | G7: 7374 | H7: =100*D7/C7 | I7: =100*E7/C7 | J7: =100*F7/C7 | K7: =100*G7/C7
A8: provincia | B8: 18 | C8: 548390 | D8: 19380 | E8: 8622 | F8: 20893 | G8: 5983 | H8: =100*D8/C8 | I8: =100*E8/C8 | J8: =100*F8/C8 | K8: =100*G8/C8
A9: provincia | B9: 21 | C9: 312108 | D9: 13980 | E9: 9340 | F9: 11520 | G9: 8191 | H9: =100*D9/C9 | I9: =100*E9/C9 | J9: =100*F9/C9 | K9: =100*G9/C9
A10: provincia | B10: 23 | C10: 354778 | D10: 10852 | E10: 7175 | F10: 6154 | G10: 6402 | H10: =100*D10/C10 | I10: =100*E10/C10 | J10: =100*F10/C10 | K10: =100*G10/C10
A11: provincia | B11: 29 | C11: 968034 | D11: 31352 | E11: 12746 | F11: 59167 | G11: 9032 | H11: =100*D11/C11 | I11: =100*E11/C11 | J11: =100*F11/C11 | K11: =100*G11/C11
A12: provincia | B12: 41 | C12: 891520 | D12: 39286 | E12: 26037 | F12: 36890 | G12: 16855 | H12: =100*D12/C12 | I12: =100*E12/C12 | J12: =100*F12/C12 | K12: =100*G12/C12
A13: provincia | B13: 22 | C13: 165869 | D13: 3559 | E13: 313 | F13: 6266 | G13: 1474 | H13: =100*D13/C13 | I13: =100*E13/C13 | J13: =100*F13/C13 | K13: =100*G13/C13
A14: provincia | B14: 44 | C14: 121422 | D14: 2072 | E14: 706 | F14: 3064 | G14: 1666 | H14: =100*D14/C14 | I14: =100*E14/C14 | J14: =100*F14/C14 | K14: =100*G14/C14
A15: provincia | B15: 50 | C15: 531947 | D15: 14577 | E15: 5106 | F15: 18778 | G15: 2691 | H15: =100*D15/C15 | I15: =100*E15/C15 | J15: =100*F15/C15 | K15: =100*G15/C15
... A52: provincia | B52: 26 | C52: 205158 | D52: 3231 | E52: 730 | F52: 5139 | G52: 919 | H52: =100*D52/C52 | I52: =100*E52/C52 | J52: =100*F52/C52 | K52: =100*G52/C52

Sheet B6_condiciones
A1: B6_condiciones
A2: Fuente de las entradas (azul): INE, ECV (microdatos); bootstrap por hogar (output/v12/b6). Cálculos en negro (fórmulas).
A3: indicador | B3: extranjera | C3: espanola_cruda | D3: espanola_misma_edad_y_renta | E3: ic95_inf | F3: ic95_sup | G3: diferencia_cruda | H3: diferencia_misma_edad_renta
A4: propiedad | B4: 33.39 | C4: 81.62 | D4: 73.5 | E4: -41.99 | F4: -38.07 | G4: =B4-C4 | H4: =B4-D4
A5: tenencia_3 | B5: 56.07 | C5: 10.22 | D5: 14.25 | E5: 39.96 | F5: 43.84 | G5: =B5-C5 | H5: =B5-D5
A6: sobrecarga_30 | B6: 38.59 | C6: 8.6 | D6: 18.01 | E6: 18.67 | F6: 22.25 | G6: =B6-C6 | H6: =B6-D6
A7: sobrecarga_40 | B7: 25.66 | C7: 4.71 | D7: 11 | E7: 13.27 | F7: 16.31 | G7: =B7-C7 | H7: =B7-D7
A8: esfuerzo_alquiler_30 | B8: 36.13 | C8: 26.31 | D8: 36.98 | E8: -3.2 | F8: 1.84 | G8: =B8-C8 | H8: =B8-D8
A9: esfuerzo_alquiler_40 | B9: 21.91 | C9: 13.64 | D9: 22.01 | E9: -2.33 | F9: 2.23 | G9: =B9-C9 | H9: =B9-D9
A10: hacinamiento | B10: 17.12 | C10: 5.91 | D10: 8.97 | E10: 6.36 | F10: 9.9 | G10: =B10-C10 | H10: =B10-D10

Sheet B7_turismo
A1: B7_turismo
A2: Fuente de las entradas (azul): INE (viviendas turísticas, experimental); registro GVA (output/v12/b7). Cálculos en negro (fórmulas).
A3: cod_municipio | B3: vut_ine_2026-05 | C3: registro_gva_2026-10-14 | D3: parque_ine | E3: ratio_registro_ine | F3: pct_ine_parque
A4: 03001 | B4: 26 | C4: 26 | D4: 598.00359 | E4: =IF(AND(ISNUMBER(B4),ISNUMBER(C4),B4>0),C4/B4,"") | F4: =IF(AND(ISNUMBER(B4),ISNUMBER(D4),D4>0),100*B4/D4,"")
A5: 03002 | B5: 15 | C5: 8 | D5: 2936.4722 | E5: =IF(AND(ISNUMBER(B5),ISNUMBER(C5),B5>0),C5/B5,"") | F5: =IF(AND(ISNUMBER(B5),ISNUMBER(D5),D5>0),100*B5/D5,"")
A6: 03003 | B6: 4 | C6: 7 | D6: 633.01155 | E6: =IF(AND(ISNUMBER(B6),ISNUMBER(C6),B6>0),C6/B6,"") | F6: =IF(AND(ISNUMBER(B6),ISNUMBER(D6),D6>0),100*B6/D6,"")
A7: 03004 | B7: 17 | C7: 32 | D7: 930.99671 | E7: =IF(AND(ISNUMBER(B7),ISNUMBER(C7),B7>0),C7/B7,"") | F7: =IF(AND(ISNUMBER(B7),ISNUMBER(D7),D7>0),100*B7/D7,"")
A8: 03005 | B8: 8 | C8: 3 | D8: 3028.2582 | E8: =IF(AND(ISNUMBER(B8),ISNUMBER(C8),B8>0),C8/B8,"") | F8: =IF(AND(ISNUMBER(B8),ISNUMBER(D8),D8>0),100*B8/D8,"")
A9: 03006 | B9: 24 | C9: 53 | D9: 1093.9922 | E9: =IF(AND(ISNUMBER(B9),ISNUMBER(C9),B9>0),C9/B9,"") | F9: =IF(AND(ISNUMBER(B9),ISNUMBER(D9),D9>0),100*B9/D9,"")
A10: 03007 | B10: 1 | C10: 2 | D10: 224.01434 | E10: =IF(AND(ISNUMBER(B10),ISNUMBER(C10),B10>0),C10/B10,"") | F10: =IF(AND(ISNUMBER(B10),ISNUMBER(D10),D10>0),100*B10/D10,"")
A11: 03008 | B11: 6 | C11: 1 | D11: 255.99454 | E11: =IF(AND(ISNUMBER(B11),ISNUMBER(C11),B11>0),C11/B11,"") | F11: =IF(AND(ISNUMBER(B11),ISNUMBER(D11),D11>0),100*B11/D11,"")
A12: 03009 | B12: 61 | C12: 34 | D12: 15798.902 | E12: =IF(AND(ISNUMBER(B12),ISNUMBER(C12),B12>0),C12/B12,"") | F12: =IF(AND(ISNUMBER(B12),ISNUMBER(D12),D12>0),100*B12/D12,"")
A13: 03010 | B13: 4 | C13: 3 | D13: 343.99725 | E13: =IF(AND(ISNUMBER(B13),ISNUMBER(C13),B13>0),C13/B13,"") | F13: =IF(AND(ISNUMBER(B13),ISNUMBER(D13),D13>0),100*B13/D13,"")
A14: 03011 | B14: 494 | C14: 1017 | D14: 12269.16 | E14: =IF(AND(ISNUMBER(B14),ISNUMBER(C14),B14>0),C14/B14,"") | F14: =IF(AND(ISNUMBER(B14),ISNUMBER(D14),D14>0),100*B14/D14,"")
A15: 03012 | B15: 36 | C15: 23 | D15: 4239.7833 | E15: =IF(AND(ISNUMBER(B15),ISNUMBER(C15),B15>0),C15/B15,"") | F15: =IF(AND(ISNUMBER(B15),ISNUMBER(D15),D15>0),100*B15/D15,"")
... A18: 03015 | B18: 14 | C18: 10 | D18: 7259.8475 | E18: =IF(AND(ISNUMBER(B18),ISNUMBER(C18),B18>0),C18/B18,"") | F18: =IF(AND(ISNUMBER(B18),ISNUMBER(D18),D18>0),100*B18/D18,"")
A19: 03016 | B19: 0 | E19: =IF(AND(ISNUMBER(B19),ISNUMBER(C19),B19>0),C19/B19,"") | F19: =IF(AND(ISNUMBER(B19),ISNUMBER(D19),D19>0),100*B19/D19,"")
A20: 03017 | B20: 0 | E20: =IF(AND(ISNUMBER(B20),ISNUMBER(C20),B20>0),C20/B20,"") | F20: =IF(AND(ISNUMBER(B20),ISNUMBER(D20),D20>0),100*B20/D20,"")
A21: 03018 | B21: 1002 | C21: 1570 | D21: 18309.001 | E21: =IF(AND(ISNUMBER(B21),ISNUMBER(C21),B21>0),C21/B21,"") | F21: =IF(AND(ISNUMBER(B21),ISNUMBER(D21),D21>0),100*B21/D21,"")
A22: 03019 | B22: 16 | C22: 4 | D22: 4113.7456 | E22: =IF(AND(ISNUMBER(B22),ISNUMBER(C22),B22>0),C22/B22,"") | F22: =IF(AND(ISNUMBER(B22),ISNUMBER(D22),D22>0),100*B22/D22,"")
A23: 03020 | B23: 0 | E23: =IF(AND(ISNUMBER(B23),ISNUMBER(C23),B23>0),C23/B23,"") | F23: =IF(AND(ISNUMBER(B23),ISNUMBER(D23),D23>0),100*B23/D23,"")
A24: 03021 | B24: 15 | C24: 17 | D24: 3843.1043 | E24: =IF(AND(ISNUMBER(B24),ISNUMBER(C24),B24>0),C24/B24,"") | F24: =IF(AND(ISNUMBER(B24),ISNUMBER(D24),D24>0),100*B24/D24,"")
A25: 03022 | B25: 1 | D25: 185.01388 | E25: =IF(AND(ISNUMBER(B25),ISNUMBER(C25),B25>0),C25/B25,"") | F25: =IF(AND(ISNUMBER(B25),ISNUMBER(D25),D25>0),100*B25/D25,"")
A26: 03023 | B26: 3 | C26: 2 | D26: 1356.2387 | E26: =IF(AND(ISNUMBER(B26),ISNUMBER(C26),B26>0),C26/B26,"") | F26: =IF(AND(ISNUMBER(B26),ISNUMBER(D26),D26>0),100*B26/D26,"")
A27: 03024 | B27: 0 | C27: 2 | E27: =IF(AND(ISNUMBER(B27),ISNUMBER(C27),B27>0),C27/B27,"") | F27: =IF(AND(ISNUMBER(B27),ISNUMBER(D27),D27>0),100*B27/D27,"")
A28: 03025 | B28: 3 | C28: 2 | D28: 1113.1725 | E28: =IF(AND(ISNUMBER(B28),ISNUMBER(C28),B28>0),C28/B28,"") | F28: =IF(AND(ISNUMBER(B28),ISNUMBER(D28),D28>0),100*B28/D28,"")
A29: 03026 | B29: 32 | C29: 39 | D29: 1371.9774 | E29: =IF(AND(ISNUMBER(B29),ISNUMBER(C29),B29>0),C29/B29,"") | F29: =IF(AND(ISNUMBER(B29),ISNUMBER(D29),D29>0),100*B29/D29,"")
A30: 03027 | B30: 2 | C30: 5 | D30: 232.99161 | E30: =IF(AND(ISNUMBER(B30),ISNUMBER(C30),B30>0),C30/B30,"") | F30: =IF(AND(ISNUMBER(B30),ISNUMBER(D30),D30>0),100*B30/D30,"")
A31: 03028 | B31: 0 | C31: 5 | E31: =IF(AND(ISNUMBER(B31),ISNUMBER(C31),B31>0),C31/B31,"") | F31: =IF(AND(ISNUMBER(B31),ISNUMBER(D31),D31>0),100*B31/D31,"")
A32: 03029 | B32: 8 | C32: 12 | D32: 501.002 | E32: =IF(AND(ISNUMBER(B32),ISNUMBER(C32),B32>0),C32/B32,"") | F32: =IF(AND(ISNUMBER(B32),ISNUMBER(D32),D32>0),100*B32/D32,"")
A33: 03030 | B33: 19 | C33: 40 | D33: 941.01332 | E33: =IF(AND(ISNUMBER(B33),ISNUMBER(C33),B33>0),C33/B33,"") | F33: =IF(AND(ISNUMBER(B33),ISNUMBER(D33),D33>0),100*B33/D33,"")
A34: 03031 | B34: 2564 | C34: 5642 | D34: 59118.181 | E34: =IF(AND(ISNUMBER(B34),ISNUMBER(C34),B34>0),C34/B34,"") | F34: =IF(AND(ISNUMBER(B34),ISNUMBER(D34),D34>0),100*B34/D34,"")
A35: 03032 | B35: 0 | E35: =IF(AND(ISNUMBER(B35),ISNUMBER(C35),B35>0),C35/B35,"") | F35: =IF(AND(ISNUMBER(B35),ISNUMBER(D35),D35>0),100*B35/D35,"")
A36: 03033 | B36: 1 | C36: 1 | D36: 186.0119 | E36: =IF(AND(ISNUMBER(B36),ISNUMBER(C36),B36>0),C36/B36,"") | F36: =IF(AND(ISNUMBER(B36),ISNUMBER(D36),D36>0),100*B36/D36,"")
A37: 03034 | B37: 24 | C37: 21 | D37: 2377.8857 | E37: =IF(AND(ISNUMBER(B37),ISNUMBER(C37),B37>0),C37/B37,"") | F37: =IF(AND(ISNUMBER(B37),ISNUMBER(D37),D37>0),100*B37/D37,"")
A38: 03035 | B38: 1 | C38: 1 | D38: 610.87355 | E38: =IF(AND(ISNUMBER(B38),ISNUMBER(C38),B38>0),C38/B38,"") | F38: =IF(AND(ISNUMBER(B38),ISNUMBER(D38),D38>0),100*B38/D38,"")
A39: 03036 | B39: 0 | E39: =IF(AND(ISNUMBER(B39),ISNUMBER(C39),B39>0),C39/B39,"") | F39: =IF(AND(ISNUMBER(B39),ISNUMBER(D39),D39>0),100*B39/D39,"")
A40: 03037 | B40: 25 | C40: 36 | D40: 496.99813 | E40: =IF(AND(ISNUMBER(B40),ISNUMBER(C40),B40>0),C40/B40,"") | F40: =IF(AND(ISNUMBER(B40),ISNUMBER(D40),D40>0),100*B40/D40,"")
A41: 03038 | B41: 0 | E41: =IF(AND(ISNUMBER(B41),ISNUMBER(C41),B41>0),C41/B41,"") | F41: =IF(AND(ISNUMBER(B41),ISNUMBER(D41),D41>0),100*B41/D41,"")
A42: 03039 | B42: 1 | D42: 108.00302 | E42: =IF(AND(ISNUMBER(B42),ISNUMBER(C42),B42>0),C42/B42,"") | F42: =IF(AND(ISNUMBER(B42),ISNUMBER(D42),D42>0),100*B42/D42,"")
...

Sheet Fuentes
A1: Fuentes y decisiones: docs/v12/decisiones.md; cifras publicables: output/v5/cifras_clave.csv (ids V12-).
